2021-12-02/24/21 00:12:12 connectionpool.py [lines:227] DEBUG: Starting new HTTP connection (1): 202.104.113.35:53281
2021-13-02/24/21 00:13:46 connectionpool.py [lines:227] DEBUG: Starting new HTTP connection (1): 202.104.113.35:53281
2021-15-02/24/21 00:15:51 connectionpool.py [lines:227] DEBUG: Starting new HTTP connection (1): 202.104.113.35:53281
2021-16-02/24/21 00:16:01 httpbin_validator.py [lines:80] ERROR: HTTPConnectionPool(host='202.104.113.35', port=53281): Read timed out. (read timeout=10)
Traceback (most recent call last):
  File "C:\Users\93057\PycharmProjects\pythonProject\venv\lib\site-packages\urllib3\connectionpool.py", line 445, in _make_request
    six.raise_from(e, None)
  File "<string>", line 3, in raise_from
  File "C:\Users\93057\PycharmProjects\pythonProject\venv\lib\site-packages\urllib3\connectionpool.py", line 440, in _make_request
    httplib_response = conn.getresponse()
  File "C:\Users\93057\AppData\Local\Programs\Python\Python39\lib\http\client.py", line 1347, in getresponse
    response.begin()
  File "C:\Users\93057\AppData\Local\Programs\Python\Python39\lib\http\client.py", line 307, in begin
    version, status, reason = self._read_status()
  File "C:\Users\93057\AppData\Local\Programs\Python\Python39\lib\http\client.py", line 268, in _read_status
    line = str(self.fp.readline(_MAXLINE + 1), "iso-8859-1")
  File "C:\Users\93057\AppData\Local\Programs\Python\Python39\lib\socket.py", line 704, in readinto
    return self._sock.recv_into(b)
socket.timeout: timed out

During handling of the above exception, another exception occurred:

Traceback (most recent call last):
  File "C:\Users\93057\PycharmProjects\pythonProject\venv\lib\site-packages\requests\adapters.py", line 439, in send
    resp = conn.urlopen(
  File "C:\Users\93057\PycharmProjects\pythonProject\venv\lib\site-packages\urllib3\connectionpool.py", line 755, in urlopen
    retries = retries.increment(
  File "C:\Users\93057\PycharmProjects\pythonProject\venv\lib\site-packages\urllib3\util\retry.py", line 531, in increment
    raise six.reraise(type(error), error, _stacktrace)
  File "C:\Users\93057\PycharmProjects\pythonProject\venv\lib\site-packages\urllib3\packages\six.py", line 735, in reraise
    raise value
  File "C:\Users\93057\PycharmProjects\pythonProject\venv\lib\site-packages\urllib3\connectionpool.py", line 699, in urlopen
    httplib_response = self._make_request(
  File "C:\Users\93057\PycharmProjects\pythonProject\venv\lib\site-packages\urllib3\connectionpool.py", line 447, in _make_request
    self._raise_timeout(err=e, url=url, timeout_value=read_timeout)
  File "C:\Users\93057\PycharmProjects\pythonProject\venv\lib\site-packages\urllib3\connectionpool.py", line 336, in _raise_timeout
    raise ReadTimeoutError(
urllib3.exceptions.ReadTimeoutError: HTTPConnectionPool(host='202.104.113.35', port=53281): Read timed out. (read timeout=10)

During handling of the above exception, another exception occurred:

Traceback (most recent call last):
  File "C:\Users\93057\PycharmProjects\IP_Proxy_Pool\core\proxy_validate\httpbin_validator.py", line 57, in __check_http_proxies
    response = requests.get(test_url, headers=get_request_headers(), proxies=proxies, timeout=TEST_TIMEOUT)
  File "C:\Users\93057\PycharmProjects\pythonProject\venv\lib\site-packages\requests\api.py", line 76, in get
    return request('get', url, params=params, **kwargs)
  File "C:\Users\93057\PycharmProjects\pythonProject\venv\lib\site-packages\requests\api.py", line 61, in request
    return session.request(method=method, url=url, **kwargs)
  File "C:\Users\93057\PycharmProjects\pythonProject\venv\lib\site-packages\requests\sessions.py", line 542, in request
    resp = self.send(prep, **send_kwargs)
  File "C:\Users\93057\PycharmProjects\pythonProject\venv\lib\site-packages\requests\sessions.py", line 655, in send
    r = adapter.send(request, **kwargs)
  File "C:\Users\93057\PycharmProjects\pythonProject\venv\lib\site-packages\requests\adapters.py", line 529, in send
    raise ReadTimeout(e, request=request)
requests.exceptions.ReadTimeout: HTTPConnectionPool(host='202.104.113.35', port=53281): Read timed out. (read timeout=10)
2021-16-02/24/21 00:16:01 connectionpool.py [lines:971] DEBUG: Starting new HTTPS connection (1): httpbin.org:443
2021-16-02/24/21 00:16:11 httpbin_validator.py [lines:80] ERROR: HTTPSConnectionPool(host='httpbin.org', port=443): Max retries exceeded with url: /get (Caused by ConnectTimeoutError(<urllib3.connection.HTTPSConnection object at 0x000002759AE251C0>, 'Connection to 202.104.113.35 timed out. (connect timeout=10)'))
Traceback (most recent call last):
  File "C:\Users\93057\PycharmProjects\pythonProject\venv\lib\site-packages\urllib3\connection.py", line 169, in _new_conn
    conn = connection.create_connection(
  File "C:\Users\93057\PycharmProjects\pythonProject\venv\lib\site-packages\urllib3\util\connection.py", line 96, in create_connection
    raise err
  File "C:\Users\93057\PycharmProjects\pythonProject\venv\lib\site-packages\urllib3\util\connection.py", line 86, in create_connection
    sock.connect(sa)
socket.timeout: timed out

During handling of the above exception, another exception occurred:

Traceback (most recent call last):
  File "C:\Users\93057\PycharmProjects\pythonProject\venv\lib\site-packages\urllib3\connectionpool.py", line 696, in urlopen
    self._prepare_proxy(conn)
  File "C:\Users\93057\PycharmProjects\pythonProject\venv\lib\site-packages\urllib3\connectionpool.py", line 964, in _prepare_proxy
    conn.connect()
  File "C:\Users\93057\PycharmProjects\pythonProject\venv\lib\site-packages\urllib3\connection.py", line 353, in connect
    conn = self._new_conn()
  File "C:\Users\93057\PycharmProjects\pythonProject\venv\lib\site-packages\urllib3\connection.py", line 174, in _new_conn
    raise ConnectTimeoutError(
urllib3.exceptions.ConnectTimeoutError: (<urllib3.connection.HTTPSConnection object at 0x000002759AE251C0>, 'Connection to 202.104.113.35 timed out. (connect timeout=10)')

During handling of the above exception, another exception occurred:

Traceback (most recent call last):
  File "C:\Users\93057\PycharmProjects\pythonProject\venv\lib\site-packages\requests\adapters.py", line 439, in send
    resp = conn.urlopen(
  File "C:\Users\93057\PycharmProjects\pythonProject\venv\lib\site-packages\urllib3\connectionpool.py", line 755, in urlopen
    retries = retries.increment(
  File "C:\Users\93057\PycharmProjects\pythonProject\venv\lib\site-packages\urllib3\util\retry.py", line 573, in increment
    raise MaxRetryError(_pool, url, error or ResponseError(cause))
urllib3.exceptions.MaxRetryError: HTTPSConnectionPool(host='httpbin.org', port=443): Max retries exceeded with url: /get (Caused by ConnectTimeoutError(<urllib3.connection.HTTPSConnection object at 0x000002759AE251C0>, 'Connection to 202.104.113.35 timed out. (connect timeout=10)'))

During handling of the above exception, another exception occurred:

Traceback (most recent call last):
  File "C:\Users\93057\PycharmProjects\IP_Proxy_Pool\core\proxy_validate\httpbin_validator.py", line 57, in __check_http_proxies
    response = requests.get(test_url, headers=get_request_headers(), proxies=proxies, timeout=TEST_TIMEOUT)
  File "C:\Users\93057\PycharmProjects\pythonProject\venv\lib\site-packages\requests\api.py", line 76, in get
    return request('get', url, params=params, **kwargs)
  File "C:\Users\93057\PycharmProjects\pythonProject\venv\lib\site-packages\requests\api.py", line 61, in request
    return session.request(method=method, url=url, **kwargs)
  File "C:\Users\93057\PycharmProjects\pythonProject\venv\lib\site-packages\requests\sessions.py", line 542, in request
    resp = self.send(prep, **send_kwargs)
  File "C:\Users\93057\PycharmProjects\pythonProject\venv\lib\site-packages\requests\sessions.py", line 655, in send
    r = adapter.send(request, **kwargs)
  File "C:\Users\93057\PycharmProjects\pythonProject\venv\lib\site-packages\requests\adapters.py", line 504, in send
    raise ConnectTimeout(e, request=request)
requests.exceptions.ConnectTimeout: HTTPSConnectionPool(host='httpbin.org', port=443): Max retries exceeded with url: /get (Caused by ConnectTimeoutError(<urllib3.connection.HTTPSConnection object at 0x000002759AE251C0>, 'Connection to 202.104.113.35 timed out. (connect timeout=10)'))
2021-16-02/24/21 00:16:55 connectionpool.py [lines:227] DEBUG: Starting new HTTP connection (1): 202.104.113.35:53281
2021-17-02/24/21 00:17:05 connectionpool.py [lines:971] DEBUG: Starting new HTTPS connection (1): httpbin.org:443
2021-18-02/24/21 00:18:51 connectionpool.py [lines:227] DEBUG: Starting new HTTP connection (1): 123.169.34.26:9999
2021-18-02/24/21 00:18:53 connectionpool.py [lines:971] DEBUG: Starting new HTTPS connection (1): httpbin.org:443
2021-19-02/24/21 00:19:16 connectionpool.py [lines:227] DEBUG: Starting new HTTP connection (1): 123.169.34.26:9999
2021-19-02/24/21 00:19:19 httpbin_validator.py [lines:80] ERROR: HTTPConnectionPool(host='123.169.34.26', port=9999): Max retries exceeded with url: http://httpbin.org/get (Caused by ProxyError('Cannot connect to proxy.', NewConnectionError('<urllib3.connection.HTTPConnection object at 0x000001AA8A6C8790>: Failed to establish a new connection: [WinError 10061] 由于目标计算机积极拒绝，无法连接。')))
Traceback (most recent call last):
  File "C:\Users\93057\PycharmProjects\pythonProject\venv\lib\site-packages\urllib3\connection.py", line 169, in _new_conn
    conn = connection.create_connection(
  File "C:\Users\93057\PycharmProjects\pythonProject\venv\lib\site-packages\urllib3\util\connection.py", line 96, in create_connection
    raise err
  File "C:\Users\93057\PycharmProjects\pythonProject\venv\lib\site-packages\urllib3\util\connection.py", line 86, in create_connection
    sock.connect(sa)
ConnectionRefusedError: [WinError 10061] 由于目标计算机积极拒绝，无法连接。

During handling of the above exception, another exception occurred:

Traceback (most recent call last):
  File "C:\Users\93057\PycharmProjects\pythonProject\venv\lib\site-packages\urllib3\connectionpool.py", line 699, in urlopen
    httplib_response = self._make_request(
  File "C:\Users\93057\PycharmProjects\pythonProject\venv\lib\site-packages\urllib3\connectionpool.py", line 394, in _make_request
    conn.request(method, url, **httplib_request_kw)
  File "C:\Users\93057\PycharmProjects\pythonProject\venv\lib\site-packages\urllib3\connection.py", line 234, in request
    super(HTTPConnection, self).request(method, url, body=body, headers=headers)
  File "C:\Users\93057\AppData\Local\Programs\Python\Python39\lib\http\client.py", line 1255, in request
    self._send_request(method, url, body, headers, encode_chunked)
  File "C:\Users\93057\AppData\Local\Programs\Python\Python39\lib\http\client.py", line 1301, in _send_request
    self.endheaders(body, encode_chunked=encode_chunked)
  File "C:\Users\93057\AppData\Local\Programs\Python\Python39\lib\http\client.py", line 1250, in endheaders
    self._send_output(message_body, encode_chunked=encode_chunked)
  File "C:\Users\93057\AppData\Local\Programs\Python\Python39\lib\http\client.py", line 1010, in _send_output
    self.send(msg)
  File "C:\Users\93057\AppData\Local\Programs\Python\Python39\lib\http\client.py", line 950, in send
    self.connect()
  File "C:\Users\93057\PycharmProjects\pythonProject\venv\lib\site-packages\urllib3\connection.py", line 200, in connect
    conn = self._new_conn()
  File "C:\Users\93057\PycharmProjects\pythonProject\venv\lib\site-packages\urllib3\connection.py", line 181, in _new_conn
    raise NewConnectionError(
urllib3.exceptions.NewConnectionError: <urllib3.connection.HTTPConnection object at 0x000001AA8A6C8790>: Failed to establish a new connection: [WinError 10061] 由于目标计算机积极拒绝，无法连接。

During handling of the above exception, another exception occurred:

Traceback (most recent call last):
  File "C:\Users\93057\PycharmProjects\pythonProject\venv\lib\site-packages\requests\adapters.py", line 439, in send
    resp = conn.urlopen(
  File "C:\Users\93057\PycharmProjects\pythonProject\venv\lib\site-packages\urllib3\connectionpool.py", line 755, in urlopen
    retries = retries.increment(
  File "C:\Users\93057\PycharmProjects\pythonProject\venv\lib\site-packages\urllib3\util\retry.py", line 573, in increment
    raise MaxRetryError(_pool, url, error or ResponseError(cause))
urllib3.exceptions.MaxRetryError: HTTPConnectionPool(host='123.169.34.26', port=9999): Max retries exceeded with url: http://httpbin.org/get (Caused by ProxyError('Cannot connect to proxy.', NewConnectionError('<urllib3.connection.HTTPConnection object at 0x000001AA8A6C8790>: Failed to establish a new connection: [WinError 10061] 由于目标计算机积极拒绝，无法连接。')))

During handling of the above exception, another exception occurred:

Traceback (most recent call last):
  File "C:\Users\93057\PycharmProjects\IP_Proxy_Pool\core\proxy_validate\httpbin_validator.py", line 57, in __check_http_proxies
    response = requests.get(test_url, headers=get_request_headers(), proxies=proxies, timeout=TEST_TIMEOUT)
  File "C:\Users\93057\PycharmProjects\pythonProject\venv\lib\site-packages\requests\api.py", line 76, in get
    return request('get', url, params=params, **kwargs)
  File "C:\Users\93057\PycharmProjects\pythonProject\venv\lib\site-packages\requests\api.py", line 61, in request
    return session.request(method=method, url=url, **kwargs)
  File "C:\Users\93057\PycharmProjects\pythonProject\venv\lib\site-packages\requests\sessions.py", line 542, in request
    resp = self.send(prep, **send_kwargs)
  File "C:\Users\93057\PycharmProjects\pythonProject\venv\lib\site-packages\requests\sessions.py", line 655, in send
    r = adapter.send(request, **kwargs)
  File "C:\Users\93057\PycharmProjects\pythonProject\venv\lib\site-packages\requests\adapters.py", line 510, in send
    raise ProxyError(e, request=request)
requests.exceptions.ProxyError: HTTPConnectionPool(host='123.169.34.26', port=9999): Max retries exceeded with url: http://httpbin.org/get (Caused by ProxyError('Cannot connect to proxy.', NewConnectionError('<urllib3.connection.HTTPConnection object at 0x000001AA8A6C8790>: Failed to establish a new connection: [WinError 10061] 由于目标计算机积极拒绝，无法连接。')))
2021-19-02/24/21 00:19:19 connectionpool.py [lines:971] DEBUG: Starting new HTTPS connection (1): httpbin.org:443
2021-19-02/24/21 00:19:21 httpbin_validator.py [lines:80] ERROR: HTTPSConnectionPool(host='httpbin.org', port=443): Max retries exceeded with url: /get (Caused by ProxyError('Cannot connect to proxy.', NewConnectionError('<urllib3.connection.HTTPSConnection object at 0x000001AA8A7691C0>: Failed to establish a new connection: [WinError 10061] 由于目标计算机积极拒绝，无法连接。')))
Traceback (most recent call last):
  File "C:\Users\93057\PycharmProjects\pythonProject\venv\lib\site-packages\urllib3\connection.py", line 169, in _new_conn
    conn = connection.create_connection(
  File "C:\Users\93057\PycharmProjects\pythonProject\venv\lib\site-packages\urllib3\util\connection.py", line 96, in create_connection
    raise err
  File "C:\Users\93057\PycharmProjects\pythonProject\venv\lib\site-packages\urllib3\util\connection.py", line 86, in create_connection
    sock.connect(sa)
ConnectionRefusedError: [WinError 10061] 由于目标计算机积极拒绝，无法连接。

During handling of the above exception, another exception occurred:

Traceback (most recent call last):
  File "C:\Users\93057\PycharmProjects\pythonProject\venv\lib\site-packages\urllib3\connectionpool.py", line 696, in urlopen
    self._prepare_proxy(conn)
  File "C:\Users\93057\PycharmProjects\pythonProject\venv\lib\site-packages\urllib3\connectionpool.py", line 964, in _prepare_proxy
    conn.connect()
  File "C:\Users\93057\PycharmProjects\pythonProject\venv\lib\site-packages\urllib3\connection.py", line 353, in connect
    conn = self._new_conn()
  File "C:\Users\93057\PycharmProjects\pythonProject\venv\lib\site-packages\urllib3\connection.py", line 181, in _new_conn
    raise NewConnectionError(
urllib3.exceptions.NewConnectionError: <urllib3.connection.HTTPSConnection object at 0x000001AA8A7691C0>: Failed to establish a new connection: [WinError 10061] 由于目标计算机积极拒绝，无法连接。

During handling of the above exception, another exception occurred:

Traceback (most recent call last):
  File "C:\Users\93057\PycharmProjects\pythonProject\venv\lib\site-packages\requests\adapters.py", line 439, in send
    resp = conn.urlopen(
  File "C:\Users\93057\PycharmProjects\pythonProject\venv\lib\site-packages\urllib3\connectionpool.py", line 755, in urlopen
    retries = retries.increment(
  File "C:\Users\93057\PycharmProjects\pythonProject\venv\lib\site-packages\urllib3\util\retry.py", line 573, in increment
    raise MaxRetryError(_pool, url, error or ResponseError(cause))
urllib3.exceptions.MaxRetryError: HTTPSConnectionPool(host='httpbin.org', port=443): Max retries exceeded with url: /get (Caused by ProxyError('Cannot connect to proxy.', NewConnectionError('<urllib3.connection.HTTPSConnection object at 0x000001AA8A7691C0>: Failed to establish a new connection: [WinError 10061] 由于目标计算机积极拒绝，无法连接。')))

During handling of the above exception, another exception occurred:

Traceback (most recent call last):
  File "C:\Users\93057\PycharmProjects\IP_Proxy_Pool\core\proxy_validate\httpbin_validator.py", line 57, in __check_http_proxies
    response = requests.get(test_url, headers=get_request_headers(), proxies=proxies, timeout=TEST_TIMEOUT)
  File "C:\Users\93057\PycharmProjects\pythonProject\venv\lib\site-packages\requests\api.py", line 76, in get
    return request('get', url, params=params, **kwargs)
  File "C:\Users\93057\PycharmProjects\pythonProject\venv\lib\site-packages\requests\api.py", line 61, in request
    return session.request(method=method, url=url, **kwargs)
  File "C:\Users\93057\PycharmProjects\pythonProject\venv\lib\site-packages\requests\sessions.py", line 542, in request
    resp = self.send(prep, **send_kwargs)
  File "C:\Users\93057\PycharmProjects\pythonProject\venv\lib\site-packages\requests\sessions.py", line 655, in send
    r = adapter.send(request, **kwargs)
  File "C:\Users\93057\PycharmProjects\pythonProject\venv\lib\site-packages\requests\adapters.py", line 510, in send
    raise ProxyError(e, request=request)
requests.exceptions.ProxyError: HTTPSConnectionPool(host='httpbin.org', port=443): Max retries exceeded with url: /get (Caused by ProxyError('Cannot connect to proxy.', NewConnectionError('<urllib3.connection.HTTPSConnection object at 0x000001AA8A7691C0>: Failed to establish a new connection: [WinError 10061] 由于目标计算机积极拒绝，无法连接。')))
2021-20-02/24/21 00:20:58 connectionpool.py [lines:227] DEBUG: Starting new HTTP connection (1): 123.169.34.26:9999
2021-21-02/24/21 00:21:07 connectionpool.py [lines:971] DEBUG: Starting new HTTPS connection (1): httpbin.org:443
2021-22-02/24/21 00:22:13 connectionpool.py [lines:227] DEBUG: Starting new HTTP connection (1): 123.169.34.26:9999
2021-22-02/24/21 00:22:16 connectionpool.py [lines:971] DEBUG: Starting new HTTPS connection (1): httpbin.org:443
2021-22-02/24/21 00:22:23 connectionpool.py [lines:227] DEBUG: Starting new HTTP connection (1): 123.169.34.26:9999
2021-22-02/24/21 00:22:26 connectionpool.py [lines:971] DEBUG: Starting new HTTPS connection (1): httpbin.org:443
2021-22-02/24/21 00:22:48 connectionpool.py [lines:227] DEBUG: Starting new HTTP connection (1): 123.169.34.26:9999
2021-22-02/24/21 00:22:50 connectionpool.py [lines:971] DEBUG: Starting new HTTPS connection (1): httpbin.org:443
2021-24-02/24/21 00:24:11 connectionpool.py [lines:227] DEBUG: Starting new HTTP connection (1): 123.169.34.26:9999
2021-24-02/24/21 00:24:13 connectionpool.py [lines:971] DEBUG: Starting new HTTPS connection (1): httpbin.org:443
2021-24-02/24/21 00:24:26 connectionpool.py [lines:227] DEBUG: Starting new HTTP connection (1): 123.169.34.26:9999
2021-24-02/24/21 00:24:46 connectionpool.py [lines:971] DEBUG: Starting new HTTPS connection (1): httpbin.org:443
2021-25-02/24/21 00:25:46 connectionpool.py [lines:227] DEBUG: Starting new HTTP connection (1): 49.89.103.159:9999
2021-25-02/24/21 00:25:48 connectionpool.py [lines:971] DEBUG: Starting new HTTPS connection (1): httpbin.org:443
2021-26-02/24/21 00:26:02 connectionpool.py [lines:227] DEBUG: Starting new HTTP connection (1): 49.89.103.159:9999
2021-26-02/24/21 00:26:04 connectionpool.py [lines:971] DEBUG: Starting new HTTPS connection (1): httpbin.org:443
2021-26-02/24/21 00:26:17 connectionpool.py [lines:227] DEBUG: Starting new HTTP connection (1): 49.89.103.159:9999
2021-26-02/24/21 00:26:19 httpbin_validator.py [lines:80] ERROR: HTTPConnectionPool(host='49.89.103.159', port=9999): Max retries exceeded with url: http://httpbin.org/get (Caused by ProxyError('Cannot connect to proxy.', NewConnectionError('<urllib3.connection.HTTPConnection object at 0x0000026FC3458790>: Failed to establish a new connection: [WinError 10061] 由于目标计算机积极拒绝，无法连接。')))
Traceback (most recent call last):
  File "C:\Users\93057\PycharmProjects\pythonProject\venv\lib\site-packages\urllib3\connection.py", line 169, in _new_conn
    conn = connection.create_connection(
  File "C:\Users\93057\PycharmProjects\pythonProject\venv\lib\site-packages\urllib3\util\connection.py", line 96, in create_connection
    raise err
  File "C:\Users\93057\PycharmProjects\pythonProject\venv\lib\site-packages\urllib3\util\connection.py", line 86, in create_connection
    sock.connect(sa)
ConnectionRefusedError: [WinError 10061] 由于目标计算机积极拒绝，无法连接。

During handling of the above exception, another exception occurred:

Traceback (most recent call last):
  File "C:\Users\93057\PycharmProjects\pythonProject\venv\lib\site-packages\urllib3\connectionpool.py", line 699, in urlopen
    httplib_response = self._make_request(
  File "C:\Users\93057\PycharmProjects\pythonProject\venv\lib\site-packages\urllib3\connectionpool.py", line 394, in _make_request
    conn.request(method, url, **httplib_request_kw)
  File "C:\Users\93057\PycharmProjects\pythonProject\venv\lib\site-packages\urllib3\connection.py", line 234, in request
    super(HTTPConnection, self).request(method, url, body=body, headers=headers)
  File "C:\Users\93057\AppData\Local\Programs\Python\Python39\lib\http\client.py", line 1255, in request
    self._send_request(method, url, body, headers, encode_chunked)
  File "C:\Users\93057\AppData\Local\Programs\Python\Python39\lib\http\client.py", line 1301, in _send_request
    self.endheaders(body, encode_chunked=encode_chunked)
  File "C:\Users\93057\AppData\Local\Programs\Python\Python39\lib\http\client.py", line 1250, in endheaders
    self._send_output(message_body, encode_chunked=encode_chunked)
  File "C:\Users\93057\AppData\Local\Programs\Python\Python39\lib\http\client.py", line 1010, in _send_output
    self.send(msg)
  File "C:\Users\93057\AppData\Local\Programs\Python\Python39\lib\http\client.py", line 950, in send
    self.connect()
  File "C:\Users\93057\PycharmProjects\pythonProject\venv\lib\site-packages\urllib3\connection.py", line 200, in connect
    conn = self._new_conn()
  File "C:\Users\93057\PycharmProjects\pythonProject\venv\lib\site-packages\urllib3\connection.py", line 181, in _new_conn
    raise NewConnectionError(
urllib3.exceptions.NewConnectionError: <urllib3.connection.HTTPConnection object at 0x0000026FC3458790>: Failed to establish a new connection: [WinError 10061] 由于目标计算机积极拒绝，无法连接。

During handling of the above exception, another exception occurred:

Traceback (most recent call last):
  File "C:\Users\93057\PycharmProjects\pythonProject\venv\lib\site-packages\requests\adapters.py", line 439, in send
    resp = conn.urlopen(
  File "C:\Users\93057\PycharmProjects\pythonProject\venv\lib\site-packages\urllib3\connectionpool.py", line 755, in urlopen
    retries = retries.increment(
  File "C:\Users\93057\PycharmProjects\pythonProject\venv\lib\site-packages\urllib3\util\retry.py", line 573, in increment
    raise MaxRetryError(_pool, url, error or ResponseError(cause))
urllib3.exceptions.MaxRetryError: HTTPConnectionPool(host='49.89.103.159', port=9999): Max retries exceeded with url: http://httpbin.org/get (Caused by ProxyError('Cannot connect to proxy.', NewConnectionError('<urllib3.connection.HTTPConnection object at 0x0000026FC3458790>: Failed to establish a new connection: [WinError 10061] 由于目标计算机积极拒绝，无法连接。')))

During handling of the above exception, another exception occurred:

Traceback (most recent call last):
  File "C:\Users\93057\PycharmProjects\IP_Proxy_Pool\core\proxy_validate\httpbin_validator.py", line 57, in __check_http_proxies
    response = requests.get(test_url, headers=get_request_headers(), proxies=proxies, timeout=TEST_TIMEOUT)
  File "C:\Users\93057\PycharmProjects\pythonProject\venv\lib\site-packages\requests\api.py", line 76, in get
    return request('get', url, params=params, **kwargs)
  File "C:\Users\93057\PycharmProjects\pythonProject\venv\lib\site-packages\requests\api.py", line 61, in request
    return session.request(method=method, url=url, **kwargs)
  File "C:\Users\93057\PycharmProjects\pythonProject\venv\lib\site-packages\requests\sessions.py", line 542, in request
    resp = self.send(prep, **send_kwargs)
  File "C:\Users\93057\PycharmProjects\pythonProject\venv\lib\site-packages\requests\sessions.py", line 655, in send
    r = adapter.send(request, **kwargs)
  File "C:\Users\93057\PycharmProjects\pythonProject\venv\lib\site-packages\requests\adapters.py", line 510, in send
    raise ProxyError(e, request=request)
requests.exceptions.ProxyError: HTTPConnectionPool(host='49.89.103.159', port=9999): Max retries exceeded with url: http://httpbin.org/get (Caused by ProxyError('Cannot connect to proxy.', NewConnectionError('<urllib3.connection.HTTPConnection object at 0x0000026FC3458790>: Failed to establish a new connection: [WinError 10061] 由于目标计算机积极拒绝，无法连接。')))
2021-26-02/24/21 00:26:19 connectionpool.py [lines:971] DEBUG: Starting new HTTPS connection (1): httpbin.org:443
2021-26-02/24/21 00:26:22 httpbin_validator.py [lines:80] ERROR: HTTPSConnectionPool(host='httpbin.org', port=443): Max retries exceeded with url: /get (Caused by ProxyError('Cannot connect to proxy.', NewConnectionError('<urllib3.connection.HTTPSConnection object at 0x0000026FC34F91C0>: Failed to establish a new connection: [WinError 10061] 由于目标计算机积极拒绝，无法连接。')))
Traceback (most recent call last):
  File "C:\Users\93057\PycharmProjects\pythonProject\venv\lib\site-packages\urllib3\connection.py", line 169, in _new_conn
    conn = connection.create_connection(
  File "C:\Users\93057\PycharmProjects\pythonProject\venv\lib\site-packages\urllib3\util\connection.py", line 96, in create_connection
    raise err
  File "C:\Users\93057\PycharmProjects\pythonProject\venv\lib\site-packages\urllib3\util\connection.py", line 86, in create_connection
    sock.connect(sa)
ConnectionRefusedError: [WinError 10061] 由于目标计算机积极拒绝，无法连接。

During handling of the above exception, another exception occurred:

Traceback (most recent call last):
  File "C:\Users\93057\PycharmProjects\pythonProject\venv\lib\site-packages\urllib3\connectionpool.py", line 696, in urlopen
    self._prepare_proxy(conn)
  File "C:\Users\93057\PycharmProjects\pythonProject\venv\lib\site-packages\urllib3\connectionpool.py", line 964, in _prepare_proxy
    conn.connect()
  File "C:\Users\93057\PycharmProjects\pythonProject\venv\lib\site-packages\urllib3\connection.py", line 353, in connect
    conn = self._new_conn()
  File "C:\Users\93057\PycharmProjects\pythonProject\venv\lib\site-packages\urllib3\connection.py", line 181, in _new_conn
    raise NewConnectionError(
urllib3.exceptions.NewConnectionError: <urllib3.connection.HTTPSConnection object at 0x0000026FC34F91C0>: Failed to establish a new connection: [WinError 10061] 由于目标计算机积极拒绝，无法连接。

During handling of the above exception, another exception occurred:

Traceback (most recent call last):
  File "C:\Users\93057\PycharmProjects\pythonProject\venv\lib\site-packages\requests\adapters.py", line 439, in send
    resp = conn.urlopen(
  File "C:\Users\93057\PycharmProjects\pythonProject\venv\lib\site-packages\urllib3\connectionpool.py", line 755, in urlopen
    retries = retries.increment(
  File "C:\Users\93057\PycharmProjects\pythonProject\venv\lib\site-packages\urllib3\util\retry.py", line 573, in increment
    raise MaxRetryError(_pool, url, error or ResponseError(cause))
urllib3.exceptions.MaxRetryError: HTTPSConnectionPool(host='httpbin.org', port=443): Max retries exceeded with url: /get (Caused by ProxyError('Cannot connect to proxy.', NewConnectionError('<urllib3.connection.HTTPSConnection object at 0x0000026FC34F91C0>: Failed to establish a new connection: [WinError 10061] 由于目标计算机积极拒绝，无法连接。')))

During handling of the above exception, another exception occurred:

Traceback (most recent call last):
  File "C:\Users\93057\PycharmProjects\IP_Proxy_Pool\core\proxy_validate\httpbin_validator.py", line 57, in __check_http_proxies
    response = requests.get(test_url, headers=get_request_headers(), proxies=proxies, timeout=TEST_TIMEOUT)
  File "C:\Users\93057\PycharmProjects\pythonProject\venv\lib\site-packages\requests\api.py", line 76, in get
    return request('get', url, params=params, **kwargs)
  File "C:\Users\93057\PycharmProjects\pythonProject\venv\lib\site-packages\requests\api.py", line 61, in request
    return session.request(method=method, url=url, **kwargs)
  File "C:\Users\93057\PycharmProjects\pythonProject\venv\lib\site-packages\requests\sessions.py", line 542, in request
    resp = self.send(prep, **send_kwargs)
  File "C:\Users\93057\PycharmProjects\pythonProject\venv\lib\site-packages\requests\sessions.py", line 655, in send
    r = adapter.send(request, **kwargs)
  File "C:\Users\93057\PycharmProjects\pythonProject\venv\lib\site-packages\requests\adapters.py", line 510, in send
    raise ProxyError(e, request=request)
requests.exceptions.ProxyError: HTTPSConnectionPool(host='httpbin.org', port=443): Max retries exceeded with url: /get (Caused by ProxyError('Cannot connect to proxy.', NewConnectionError('<urllib3.connection.HTTPSConnection object at 0x0000026FC34F91C0>: Failed to establish a new connection: [WinError 10061] 由于目标计算机积极拒绝，无法连接。')))
2021-27-02/24/21 00:27:15 connectionpool.py [lines:227] DEBUG: Starting new HTTP connection (1): 61.220.204.25:3128
2021-27-02/24/21 00:27:20 httpbin_validator.py [lines:80] ERROR: HTTPConnectionPool(host='61.220.204.25', port=3128): Max retries exceeded with url: http://httpbin.org/get (Caused by ConnectTimeoutError(<urllib3.connection.HTTPConnection object at 0x000001FB16078790>, 'Connection to 61.220.204.25 timed out. (connect timeout=5)'))
Traceback (most recent call last):
  File "C:\Users\93057\PycharmProjects\pythonProject\venv\lib\site-packages\urllib3\connection.py", line 169, in _new_conn
    conn = connection.create_connection(
  File "C:\Users\93057\PycharmProjects\pythonProject\venv\lib\site-packages\urllib3\util\connection.py", line 96, in create_connection
    raise err
  File "C:\Users\93057\PycharmProjects\pythonProject\venv\lib\site-packages\urllib3\util\connection.py", line 86, in create_connection
    sock.connect(sa)
socket.timeout: timed out

During handling of the above exception, another exception occurred:

Traceback (most recent call last):
  File "C:\Users\93057\PycharmProjects\pythonProject\venv\lib\site-packages\urllib3\connectionpool.py", line 699, in urlopen
    httplib_response = self._make_request(
  File "C:\Users\93057\PycharmProjects\pythonProject\venv\lib\site-packages\urllib3\connectionpool.py", line 394, in _make_request
    conn.request(method, url, **httplib_request_kw)
  File "C:\Users\93057\PycharmProjects\pythonProject\venv\lib\site-packages\urllib3\connection.py", line 234, in request
    super(HTTPConnection, self).request(method, url, body=body, headers=headers)
  File "C:\Users\93057\AppData\Local\Programs\Python\Python39\lib\http\client.py", line 1255, in request
    self._send_request(method, url, body, headers, encode_chunked)
  File "C:\Users\93057\AppData\Local\Programs\Python\Python39\lib\http\client.py", line 1301, in _send_request
    self.endheaders(body, encode_chunked=encode_chunked)
  File "C:\Users\93057\AppData\Local\Programs\Python\Python39\lib\http\client.py", line 1250, in endheaders
    self._send_output(message_body, encode_chunked=encode_chunked)
  File "C:\Users\93057\AppData\Local\Programs\Python\Python39\lib\http\client.py", line 1010, in _send_output
    self.send(msg)
  File "C:\Users\93057\AppData\Local\Programs\Python\Python39\lib\http\client.py", line 950, in send
    self.connect()
  File "C:\Users\93057\PycharmProjects\pythonProject\venv\lib\site-packages\urllib3\connection.py", line 200, in connect
    conn = self._new_conn()
  File "C:\Users\93057\PycharmProjects\pythonProject\venv\lib\site-packages\urllib3\connection.py", line 174, in _new_conn
    raise ConnectTimeoutError(
urllib3.exceptions.ConnectTimeoutError: (<urllib3.connection.HTTPConnection object at 0x000001FB16078790>, 'Connection to 61.220.204.25 timed out. (connect timeout=5)')

During handling of the above exception, another exception occurred:

Traceback (most recent call last):
  File "C:\Users\93057\PycharmProjects\pythonProject\venv\lib\site-packages\requests\adapters.py", line 439, in send
    resp = conn.urlopen(
  File "C:\Users\93057\PycharmProjects\pythonProject\venv\lib\site-packages\urllib3\connectionpool.py", line 755, in urlopen
    retries = retries.increment(
  File "C:\Users\93057\PycharmProjects\pythonProject\venv\lib\site-packages\urllib3\util\retry.py", line 573, in increment
    raise MaxRetryError(_pool, url, error or ResponseError(cause))
urllib3.exceptions.MaxRetryError: HTTPConnectionPool(host='61.220.204.25', port=3128): Max retries exceeded with url: http://httpbin.org/get (Caused by ConnectTimeoutError(<urllib3.connection.HTTPConnection object at 0x000001FB16078790>, 'Connection to 61.220.204.25 timed out. (connect timeout=5)'))

During handling of the above exception, another exception occurred:

Traceback (most recent call last):
  File "C:\Users\93057\PycharmProjects\IP_Proxy_Pool\core\proxy_validate\httpbin_validator.py", line 57, in __check_http_proxies
    response = requests.get(test_url, headers=get_request_headers(), proxies=proxies, timeout=TEST_TIMEOUT)
  File "C:\Users\93057\PycharmProjects\pythonProject\venv\lib\site-packages\requests\api.py", line 76, in get
    return request('get', url, params=params, **kwargs)
  File "C:\Users\93057\PycharmProjects\pythonProject\venv\lib\site-packages\requests\api.py", line 61, in request
    return session.request(method=method, url=url, **kwargs)
  File "C:\Users\93057\PycharmProjects\pythonProject\venv\lib\site-packages\requests\sessions.py", line 542, in request
    resp = self.send(prep, **send_kwargs)
  File "C:\Users\93057\PycharmProjects\pythonProject\venv\lib\site-packages\requests\sessions.py", line 655, in send
    r = adapter.send(request, **kwargs)
  File "C:\Users\93057\PycharmProjects\pythonProject\venv\lib\site-packages\requests\adapters.py", line 504, in send
    raise ConnectTimeout(e, request=request)
requests.exceptions.ConnectTimeout: HTTPConnectionPool(host='61.220.204.25', port=3128): Max retries exceeded with url: http://httpbin.org/get (Caused by ConnectTimeoutError(<urllib3.connection.HTTPConnection object at 0x000001FB16078790>, 'Connection to 61.220.204.25 timed out. (connect timeout=5)'))
2021-27-02/24/21 00:27:20 connectionpool.py [lines:971] DEBUG: Starting new HTTPS connection (1): httpbin.org:443
2021-27-02/24/21 00:27:25 httpbin_validator.py [lines:80] ERROR: HTTPSConnectionPool(host='httpbin.org', port=443): Max retries exceeded with url: /get (Caused by ConnectTimeoutError(<urllib3.connection.HTTPSConnection object at 0x000001FB161191C0>, 'Connection to 61.220.204.25 timed out. (connect timeout=5)'))
Traceback (most recent call last):
  File "C:\Users\93057\PycharmProjects\pythonProject\venv\lib\site-packages\urllib3\connection.py", line 169, in _new_conn
    conn = connection.create_connection(
  File "C:\Users\93057\PycharmProjects\pythonProject\venv\lib\site-packages\urllib3\util\connection.py", line 96, in create_connection
    raise err
  File "C:\Users\93057\PycharmProjects\pythonProject\venv\lib\site-packages\urllib3\util\connection.py", line 86, in create_connection
    sock.connect(sa)
socket.timeout: timed out

During handling of the above exception, another exception occurred:

Traceback (most recent call last):
  File "C:\Users\93057\PycharmProjects\pythonProject\venv\lib\site-packages\urllib3\connectionpool.py", line 696, in urlopen
    self._prepare_proxy(conn)
  File "C:\Users\93057\PycharmProjects\pythonProject\venv\lib\site-packages\urllib3\connectionpool.py", line 964, in _prepare_proxy
    conn.connect()
  File "C:\Users\93057\PycharmProjects\pythonProject\venv\lib\site-packages\urllib3\connection.py", line 353, in connect
    conn = self._new_conn()
  File "C:\Users\93057\PycharmProjects\pythonProject\venv\lib\site-packages\urllib3\connection.py", line 174, in _new_conn
    raise ConnectTimeoutError(
urllib3.exceptions.ConnectTimeoutError: (<urllib3.connection.HTTPSConnection object at 0x000001FB161191C0>, 'Connection to 61.220.204.25 timed out. (connect timeout=5)')

During handling of the above exception, another exception occurred:

Traceback (most recent call last):
  File "C:\Users\93057\PycharmProjects\pythonProject\venv\lib\site-packages\requests\adapters.py", line 439, in send
    resp = conn.urlopen(
  File "C:\Users\93057\PycharmProjects\pythonProject\venv\lib\site-packages\urllib3\connectionpool.py", line 755, in urlopen
    retries = retries.increment(
  File "C:\Users\93057\PycharmProjects\pythonProject\venv\lib\site-packages\urllib3\util\retry.py", line 573, in increment
    raise MaxRetryError(_pool, url, error or ResponseError(cause))
urllib3.exceptions.MaxRetryError: HTTPSConnectionPool(host='httpbin.org', port=443): Max retries exceeded with url: /get (Caused by ConnectTimeoutError(<urllib3.connection.HTTPSConnection object at 0x000001FB161191C0>, 'Connection to 61.220.204.25 timed out. (connect timeout=5)'))

During handling of the above exception, another exception occurred:

Traceback (most recent call last):
  File "C:\Users\93057\PycharmProjects\IP_Proxy_Pool\core\proxy_validate\httpbin_validator.py", line 57, in __check_http_proxies
    response = requests.get(test_url, headers=get_request_headers(), proxies=proxies, timeout=TEST_TIMEOUT)
  File "C:\Users\93057\PycharmProjects\pythonProject\venv\lib\site-packages\requests\api.py", line 76, in get
    return request('get', url, params=params, **kwargs)
  File "C:\Users\93057\PycharmProjects\pythonProject\venv\lib\site-packages\requests\api.py", line 61, in request
    return session.request(method=method, url=url, **kwargs)
  File "C:\Users\93057\PycharmProjects\pythonProject\venv\lib\site-packages\requests\sessions.py", line 542, in request
    resp = self.send(prep, **send_kwargs)
  File "C:\Users\93057\PycharmProjects\pythonProject\venv\lib\site-packages\requests\sessions.py", line 655, in send
    r = adapter.send(request, **kwargs)
  File "C:\Users\93057\PycharmProjects\pythonProject\venv\lib\site-packages\requests\adapters.py", line 504, in send
    raise ConnectTimeout(e, request=request)
requests.exceptions.ConnectTimeout: HTTPSConnectionPool(host='httpbin.org', port=443): Max retries exceeded with url: /get (Caused by ConnectTimeoutError(<urllib3.connection.HTTPSConnection object at 0x000001FB161191C0>, 'Connection to 61.220.204.25 timed out. (connect timeout=5)'))
2021-27-02/24/21 00:27:54 connectionpool.py [lines:227] DEBUG: Starting new HTTP connection (1): 124.205.155.152:9090
2021-27-02/24/21 00:27:59 httpbin_validator.py [lines:80] ERROR: HTTPConnectionPool(host='124.205.155.152', port=9090): Max retries exceeded with url: http://httpbin.org/get (Caused by ConnectTimeoutError(<urllib3.connection.HTTPConnection object at 0x000001E461218760>, 'Connection to 124.205.155.152 timed out. (connect timeout=5)'))
Traceback (most recent call last):
  File "C:\Users\93057\PycharmProjects\pythonProject\venv\lib\site-packages\urllib3\connection.py", line 169, in _new_conn
    conn = connection.create_connection(
  File "C:\Users\93057\PycharmProjects\pythonProject\venv\lib\site-packages\urllib3\util\connection.py", line 96, in create_connection
    raise err
  File "C:\Users\93057\PycharmProjects\pythonProject\venv\lib\site-packages\urllib3\util\connection.py", line 86, in create_connection
    sock.connect(sa)
socket.timeout: timed out

During handling of the above exception, another exception occurred:

Traceback (most recent call last):
  File "C:\Users\93057\PycharmProjects\pythonProject\venv\lib\site-packages\urllib3\connectionpool.py", line 699, in urlopen
    httplib_response = self._make_request(
  File "C:\Users\93057\PycharmProjects\pythonProject\venv\lib\site-packages\urllib3\connectionpool.py", line 394, in _make_request
    conn.request(method, url, **httplib_request_kw)
  File "C:\Users\93057\PycharmProjects\pythonProject\venv\lib\site-packages\urllib3\connection.py", line 234, in request
    super(HTTPConnection, self).request(method, url, body=body, headers=headers)
  File "C:\Users\93057\AppData\Local\Programs\Python\Python39\lib\http\client.py", line 1255, in request
    self._send_request(method, url, body, headers, encode_chunked)
  File "C:\Users\93057\AppData\Local\Programs\Python\Python39\lib\http\client.py", line 1301, in _send_request
    self.endheaders(body, encode_chunked=encode_chunked)
  File "C:\Users\93057\AppData\Local\Programs\Python\Python39\lib\http\client.py", line 1250, in endheaders
    self._send_output(message_body, encode_chunked=encode_chunked)
  File "C:\Users\93057\AppData\Local\Programs\Python\Python39\lib\http\client.py", line 1010, in _send_output
    self.send(msg)
  File "C:\Users\93057\AppData\Local\Programs\Python\Python39\lib\http\client.py", line 950, in send
    self.connect()
  File "C:\Users\93057\PycharmProjects\pythonProject\venv\lib\site-packages\urllib3\connection.py", line 200, in connect
    conn = self._new_conn()
  File "C:\Users\93057\PycharmProjects\pythonProject\venv\lib\site-packages\urllib3\connection.py", line 174, in _new_conn
    raise ConnectTimeoutError(
urllib3.exceptions.ConnectTimeoutError: (<urllib3.connection.HTTPConnection object at 0x000001E461218760>, 'Connection to 124.205.155.152 timed out. (connect timeout=5)')

During handling of the above exception, another exception occurred:

Traceback (most recent call last):
  File "C:\Users\93057\PycharmProjects\pythonProject\venv\lib\site-packages\requests\adapters.py", line 439, in send
    resp = conn.urlopen(
  File "C:\Users\93057\PycharmProjects\pythonProject\venv\lib\site-packages\urllib3\connectionpool.py", line 755, in urlopen
    retries = retries.increment(
  File "C:\Users\93057\PycharmProjects\pythonProject\venv\lib\site-packages\urllib3\util\retry.py", line 573, in increment
    raise MaxRetryError(_pool, url, error or ResponseError(cause))
urllib3.exceptions.MaxRetryError: HTTPConnectionPool(host='124.205.155.152', port=9090): Max retries exceeded with url: http://httpbin.org/get (Caused by ConnectTimeoutError(<urllib3.connection.HTTPConnection object at 0x000001E461218760>, 'Connection to 124.205.155.152 timed out. (connect timeout=5)'))

During handling of the above exception, another exception occurred:

Traceback (most recent call last):
  File "C:\Users\93057\PycharmProjects\IP_Proxy_Pool\core\proxy_validate\httpbin_validator.py", line 57, in __check_http_proxies
    response = requests.get(test_url, headers=get_request_headers(), proxies=proxies, timeout=TEST_TIMEOUT)
  File "C:\Users\93057\PycharmProjects\pythonProject\venv\lib\site-packages\requests\api.py", line 76, in get
    return request('get', url, params=params, **kwargs)
  File "C:\Users\93057\PycharmProjects\pythonProject\venv\lib\site-packages\requests\api.py", line 61, in request
    return session.request(method=method, url=url, **kwargs)
  File "C:\Users\93057\PycharmProjects\pythonProject\venv\lib\site-packages\requests\sessions.py", line 542, in request
    resp = self.send(prep, **send_kwargs)
  File "C:\Users\93057\PycharmProjects\pythonProject\venv\lib\site-packages\requests\sessions.py", line 655, in send
    r = adapter.send(request, **kwargs)
  File "C:\Users\93057\PycharmProjects\pythonProject\venv\lib\site-packages\requests\adapters.py", line 504, in send
    raise ConnectTimeout(e, request=request)
requests.exceptions.ConnectTimeout: HTTPConnectionPool(host='124.205.155.152', port=9090): Max retries exceeded with url: http://httpbin.org/get (Caused by ConnectTimeoutError(<urllib3.connection.HTTPConnection object at 0x000001E461218760>, 'Connection to 124.205.155.152 timed out. (connect timeout=5)'))
2021-27-02/24/21 00:27:59 connectionpool.py [lines:971] DEBUG: Starting new HTTPS connection (1): httpbin.org:443
2021-28-02/24/21 00:28:04 httpbin_validator.py [lines:80] ERROR: HTTPSConnectionPool(host='httpbin.org', port=443): Max retries exceeded with url: /get (Caused by ConnectTimeoutError(<urllib3.connection.HTTPSConnection object at 0x000001E4612B9190>, 'Connection to 124.205.155.152 timed out. (connect timeout=5)'))
Traceback (most recent call last):
  File "C:\Users\93057\PycharmProjects\pythonProject\venv\lib\site-packages\urllib3\connection.py", line 169, in _new_conn
    conn = connection.create_connection(
  File "C:\Users\93057\PycharmProjects\pythonProject\venv\lib\site-packages\urllib3\util\connection.py", line 96, in create_connection
    raise err
  File "C:\Users\93057\PycharmProjects\pythonProject\venv\lib\site-packages\urllib3\util\connection.py", line 86, in create_connection
    sock.connect(sa)
socket.timeout: timed out

During handling of the above exception, another exception occurred:

Traceback (most recent call last):
  File "C:\Users\93057\PycharmProjects\pythonProject\venv\lib\site-packages\urllib3\connectionpool.py", line 696, in urlopen
    self._prepare_proxy(conn)
  File "C:\Users\93057\PycharmProjects\pythonProject\venv\lib\site-packages\urllib3\connectionpool.py", line 964, in _prepare_proxy
    conn.connect()
  File "C:\Users\93057\PycharmProjects\pythonProject\venv\lib\site-packages\urllib3\connection.py", line 353, in connect
    conn = self._new_conn()
  File "C:\Users\93057\PycharmProjects\pythonProject\venv\lib\site-packages\urllib3\connection.py", line 174, in _new_conn
    raise ConnectTimeoutError(
urllib3.exceptions.ConnectTimeoutError: (<urllib3.connection.HTTPSConnection object at 0x000001E4612B9190>, 'Connection to 124.205.155.152 timed out. (connect timeout=5)')

During handling of the above exception, another exception occurred:

Traceback (most recent call last):
  File "C:\Users\93057\PycharmProjects\pythonProject\venv\lib\site-packages\requests\adapters.py", line 439, in send
    resp = conn.urlopen(
  File "C:\Users\93057\PycharmProjects\pythonProject\venv\lib\site-packages\urllib3\connectionpool.py", line 755, in urlopen
    retries = retries.increment(
  File "C:\Users\93057\PycharmProjects\pythonProject\venv\lib\site-packages\urllib3\util\retry.py", line 573, in increment
    raise MaxRetryError(_pool, url, error or ResponseError(cause))
urllib3.exceptions.MaxRetryError: HTTPSConnectionPool(host='httpbin.org', port=443): Max retries exceeded with url: /get (Caused by ConnectTimeoutError(<urllib3.connection.HTTPSConnection object at 0x000001E4612B9190>, 'Connection to 124.205.155.152 timed out. (connect timeout=5)'))

During handling of the above exception, another exception occurred:

Traceback (most recent call last):
  File "C:\Users\93057\PycharmProjects\IP_Proxy_Pool\core\proxy_validate\httpbin_validator.py", line 57, in __check_http_proxies
    response = requests.get(test_url, headers=get_request_headers(), proxies=proxies, timeout=TEST_TIMEOUT)
  File "C:\Users\93057\PycharmProjects\pythonProject\venv\lib\site-packages\requests\api.py", line 76, in get
    return request('get', url, params=params, **kwargs)
  File "C:\Users\93057\PycharmProjects\pythonProject\venv\lib\site-packages\requests\api.py", line 61, in request
    return session.request(method=method, url=url, **kwargs)
  File "C:\Users\93057\PycharmProjects\pythonProject\venv\lib\site-packages\requests\sessions.py", line 542, in request
    resp = self.send(prep, **send_kwargs)
  File "C:\Users\93057\PycharmProjects\pythonProject\venv\lib\site-packages\requests\sessions.py", line 655, in send
    r = adapter.send(request, **kwargs)
  File "C:\Users\93057\PycharmProjects\pythonProject\venv\lib\site-packages\requests\adapters.py", line 504, in send
    raise ConnectTimeout(e, request=request)
requests.exceptions.ConnectTimeout: HTTPSConnectionPool(host='httpbin.org', port=443): Max retries exceeded with url: /get (Caused by ConnectTimeoutError(<urllib3.connection.HTTPSConnection object at 0x000001E4612B9190>, 'Connection to 124.205.155.152 timed out. (connect timeout=5)'))
2021-30-02/24/21 00:30:56 connectionpool.py [lines:227] DEBUG: Starting new HTTP connection (1): 1.198.41.178:9999
2021-31-02/24/21 00:31:01 httpbin_validator.py [lines:80] ERROR: HTTPConnectionPool(host='1.198.41.178', port=9999): Max retries exceeded with url: http://httpbin.org/get (Caused by ConnectTimeoutError(<urllib3.connection.HTTPConnection object at 0x000002AEC5598790>, 'Connection to 1.198.41.178 timed out. (connect timeout=5)'))
Traceback (most recent call last):
  File "C:\Users\93057\PycharmProjects\pythonProject\venv\lib\site-packages\urllib3\connection.py", line 169, in _new_conn
    conn = connection.create_connection(
  File "C:\Users\93057\PycharmProjects\pythonProject\venv\lib\site-packages\urllib3\util\connection.py", line 96, in create_connection
    raise err
  File "C:\Users\93057\PycharmProjects\pythonProject\venv\lib\site-packages\urllib3\util\connection.py", line 86, in create_connection
    sock.connect(sa)
socket.timeout: timed out

During handling of the above exception, another exception occurred:

Traceback (most recent call last):
  File "C:\Users\93057\PycharmProjects\pythonProject\venv\lib\site-packages\urllib3\connectionpool.py", line 699, in urlopen
    httplib_response = self._make_request(
  File "C:\Users\93057\PycharmProjects\pythonProject\venv\lib\site-packages\urllib3\connectionpool.py", line 394, in _make_request
    conn.request(method, url, **httplib_request_kw)
  File "C:\Users\93057\PycharmProjects\pythonProject\venv\lib\site-packages\urllib3\connection.py", line 234, in request
    super(HTTPConnection, self).request(method, url, body=body, headers=headers)
  File "C:\Users\93057\AppData\Local\Programs\Python\Python39\lib\http\client.py", line 1255, in request
    self._send_request(method, url, body, headers, encode_chunked)
  File "C:\Users\93057\AppData\Local\Programs\Python\Python39\lib\http\client.py", line 1301, in _send_request
    self.endheaders(body, encode_chunked=encode_chunked)
  File "C:\Users\93057\AppData\Local\Programs\Python\Python39\lib\http\client.py", line 1250, in endheaders
    self._send_output(message_body, encode_chunked=encode_chunked)
  File "C:\Users\93057\AppData\Local\Programs\Python\Python39\lib\http\client.py", line 1010, in _send_output
    self.send(msg)
  File "C:\Users\93057\AppData\Local\Programs\Python\Python39\lib\http\client.py", line 950, in send
    self.connect()
  File "C:\Users\93057\PycharmProjects\pythonProject\venv\lib\site-packages\urllib3\connection.py", line 200, in connect
    conn = self._new_conn()
  File "C:\Users\93057\PycharmProjects\pythonProject\venv\lib\site-packages\urllib3\connection.py", line 174, in _new_conn
    raise ConnectTimeoutError(
urllib3.exceptions.ConnectTimeoutError: (<urllib3.connection.HTTPConnection object at 0x000002AEC5598790>, 'Connection to 1.198.41.178 timed out. (connect timeout=5)')

During handling of the above exception, another exception occurred:

Traceback (most recent call last):
  File "C:\Users\93057\PycharmProjects\pythonProject\venv\lib\site-packages\requests\adapters.py", line 439, in send
    resp = conn.urlopen(
  File "C:\Users\93057\PycharmProjects\pythonProject\venv\lib\site-packages\urllib3\connectionpool.py", line 755, in urlopen
    retries = retries.increment(
  File "C:\Users\93057\PycharmProjects\pythonProject\venv\lib\site-packages\urllib3\util\retry.py", line 573, in increment
    raise MaxRetryError(_pool, url, error or ResponseError(cause))
urllib3.exceptions.MaxRetryError: HTTPConnectionPool(host='1.198.41.178', port=9999): Max retries exceeded with url: http://httpbin.org/get (Caused by ConnectTimeoutError(<urllib3.connection.HTTPConnection object at 0x000002AEC5598790>, 'Connection to 1.198.41.178 timed out. (connect timeout=5)'))

During handling of the above exception, another exception occurred:

Traceback (most recent call last):
  File "C:\Users\93057\PycharmProjects\IP_Proxy_Pool\core\proxy_validate\httpbin_validator.py", line 57, in __check_http_proxies
    response = requests.get(test_url, headers=get_request_headers(), proxies=proxies, timeout=TEST_TIMEOUT)
  File "C:\Users\93057\PycharmProjects\pythonProject\venv\lib\site-packages\requests\api.py", line 76, in get
    return request('get', url, params=params, **kwargs)
  File "C:\Users\93057\PycharmProjects\pythonProject\venv\lib\site-packages\requests\api.py", line 61, in request
    return session.request(method=method, url=url, **kwargs)
  File "C:\Users\93057\PycharmProjects\pythonProject\venv\lib\site-packages\requests\sessions.py", line 542, in request
    resp = self.send(prep, **send_kwargs)
  File "C:\Users\93057\PycharmProjects\pythonProject\venv\lib\site-packages\requests\sessions.py", line 655, in send
    r = adapter.send(request, **kwargs)
  File "C:\Users\93057\PycharmProjects\pythonProject\venv\lib\site-packages\requests\adapters.py", line 504, in send
    raise ConnectTimeout(e, request=request)
requests.exceptions.ConnectTimeout: HTTPConnectionPool(host='1.198.41.178', port=9999): Max retries exceeded with url: http://httpbin.org/get (Caused by ConnectTimeoutError(<urllib3.connection.HTTPConnection object at 0x000002AEC5598790>, 'Connection to 1.198.41.178 timed out. (connect timeout=5)'))
2021-31-02/24/21 00:31:01 connectionpool.py [lines:971] DEBUG: Starting new HTTPS connection (1): httpbin.org:443
2021-31-02/24/21 00:31:06 httpbin_validator.py [lines:80] ERROR: HTTPSConnectionPool(host='httpbin.org', port=443): Max retries exceeded with url: /get (Caused by ConnectTimeoutError(<urllib3.connection.HTTPSConnection object at 0x000002AEC56391C0>, 'Connection to 1.198.41.178 timed out. (connect timeout=5)'))
Traceback (most recent call last):
  File "C:\Users\93057\PycharmProjects\pythonProject\venv\lib\site-packages\urllib3\connection.py", line 169, in _new_conn
    conn = connection.create_connection(
  File "C:\Users\93057\PycharmProjects\pythonProject\venv\lib\site-packages\urllib3\util\connection.py", line 96, in create_connection
    raise err
  File "C:\Users\93057\PycharmProjects\pythonProject\venv\lib\site-packages\urllib3\util\connection.py", line 86, in create_connection
    sock.connect(sa)
socket.timeout: timed out

During handling of the above exception, another exception occurred:

Traceback (most recent call last):
  File "C:\Users\93057\PycharmProjects\pythonProject\venv\lib\site-packages\urllib3\connectionpool.py", line 696, in urlopen
    self._prepare_proxy(conn)
  File "C:\Users\93057\PycharmProjects\pythonProject\venv\lib\site-packages\urllib3\connectionpool.py", line 964, in _prepare_proxy
    conn.connect()
  File "C:\Users\93057\PycharmProjects\pythonProject\venv\lib\site-packages\urllib3\connection.py", line 353, in connect
    conn = self._new_conn()
  File "C:\Users\93057\PycharmProjects\pythonProject\venv\lib\site-packages\urllib3\connection.py", line 174, in _new_conn
    raise ConnectTimeoutError(
urllib3.exceptions.ConnectTimeoutError: (<urllib3.connection.HTTPSConnection object at 0x000002AEC56391C0>, 'Connection to 1.198.41.178 timed out. (connect timeout=5)')

During handling of the above exception, another exception occurred:

Traceback (most recent call last):
  File "C:\Users\93057\PycharmProjects\pythonProject\venv\lib\site-packages\requests\adapters.py", line 439, in send
    resp = conn.urlopen(
  File "C:\Users\93057\PycharmProjects\pythonProject\venv\lib\site-packages\urllib3\connectionpool.py", line 755, in urlopen
    retries = retries.increment(
  File "C:\Users\93057\PycharmProjects\pythonProject\venv\lib\site-packages\urllib3\util\retry.py", line 573, in increment
    raise MaxRetryError(_pool, url, error or ResponseError(cause))
urllib3.exceptions.MaxRetryError: HTTPSConnectionPool(host='httpbin.org', port=443): Max retries exceeded with url: /get (Caused by ConnectTimeoutError(<urllib3.connection.HTTPSConnection object at 0x000002AEC56391C0>, 'Connection to 1.198.41.178 timed out. (connect timeout=5)'))

During handling of the above exception, another exception occurred:

Traceback (most recent call last):
  File "C:\Users\93057\PycharmProjects\IP_Proxy_Pool\core\proxy_validate\httpbin_validator.py", line 57, in __check_http_proxies
    response = requests.get(test_url, headers=get_request_headers(), proxies=proxies, timeout=TEST_TIMEOUT)
  File "C:\Users\93057\PycharmProjects\pythonProject\venv\lib\site-packages\requests\api.py", line 76, in get
    return request('get', url, params=params, **kwargs)
  File "C:\Users\93057\PycharmProjects\pythonProject\venv\lib\site-packages\requests\api.py", line 61, in request
    return session.request(method=method, url=url, **kwargs)
  File "C:\Users\93057\PycharmProjects\pythonProject\venv\lib\site-packages\requests\sessions.py", line 542, in request
    resp = self.send(prep, **send_kwargs)
  File "C:\Users\93057\PycharmProjects\pythonProject\venv\lib\site-packages\requests\sessions.py", line 655, in send
    r = adapter.send(request, **kwargs)
  File "C:\Users\93057\PycharmProjects\pythonProject\venv\lib\site-packages\requests\adapters.py", line 504, in send
    raise ConnectTimeout(e, request=request)
requests.exceptions.ConnectTimeout: HTTPSConnectionPool(host='httpbin.org', port=443): Max retries exceeded with url: /get (Caused by ConnectTimeoutError(<urllib3.connection.HTTPSConnection object at 0x000002AEC56391C0>, 'Connection to 1.198.41.178 timed out. (connect timeout=5)'))
2021-32-02/24/21 00:32:29 connectionpool.py [lines:227] DEBUG: Starting new HTTP connection (1): 117.114.149.66:53281
2021-32-02/24/21 00:32:31 httpbin_validator.py [lines:80] ERROR: HTTPConnectionPool(host='117.114.149.66', port=53281): Max retries exceeded with url: http://httpbin.org/get (Caused by ProxyError('Cannot connect to proxy.', NewConnectionError('<urllib3.connection.HTTPConnection object at 0x0000027F1D168760>: Failed to establish a new connection: [WinError 10061] 由于目标计算机积极拒绝，无法连接。')))
Traceback (most recent call last):
  File "C:\Users\93057\PycharmProjects\pythonProject\venv\lib\site-packages\urllib3\connection.py", line 169, in _new_conn
    conn = connection.create_connection(
  File "C:\Users\93057\PycharmProjects\pythonProject\venv\lib\site-packages\urllib3\util\connection.py", line 96, in create_connection
    raise err
  File "C:\Users\93057\PycharmProjects\pythonProject\venv\lib\site-packages\urllib3\util\connection.py", line 86, in create_connection
    sock.connect(sa)
ConnectionRefusedError: [WinError 10061] 由于目标计算机积极拒绝，无法连接。

During handling of the above exception, another exception occurred:

Traceback (most recent call last):
  File "C:\Users\93057\PycharmProjects\pythonProject\venv\lib\site-packages\urllib3\connectionpool.py", line 699, in urlopen
    httplib_response = self._make_request(
  File "C:\Users\93057\PycharmProjects\pythonProject\venv\lib\site-packages\urllib3\connectionpool.py", line 394, in _make_request
    conn.request(method, url, **httplib_request_kw)
  File "C:\Users\93057\PycharmProjects\pythonProject\venv\lib\site-packages\urllib3\connection.py", line 234, in request
    super(HTTPConnection, self).request(method, url, body=body, headers=headers)
  File "C:\Users\93057\AppData\Local\Programs\Python\Python39\lib\http\client.py", line 1255, in request
    self._send_request(method, url, body, headers, encode_chunked)
  File "C:\Users\93057\AppData\Local\Programs\Python\Python39\lib\http\client.py", line 1301, in _send_request
    self.endheaders(body, encode_chunked=encode_chunked)
  File "C:\Users\93057\AppData\Local\Programs\Python\Python39\lib\http\client.py", line 1250, in endheaders
    self._send_output(message_body, encode_chunked=encode_chunked)
  File "C:\Users\93057\AppData\Local\Programs\Python\Python39\lib\http\client.py", line 1010, in _send_output
    self.send(msg)
  File "C:\Users\93057\AppData\Local\Programs\Python\Python39\lib\http\client.py", line 950, in send
    self.connect()
  File "C:\Users\93057\PycharmProjects\pythonProject\venv\lib\site-packages\urllib3\connection.py", line 200, in connect
    conn = self._new_conn()
  File "C:\Users\93057\PycharmProjects\pythonProject\venv\lib\site-packages\urllib3\connection.py", line 181, in _new_conn
    raise NewConnectionError(
urllib3.exceptions.NewConnectionError: <urllib3.connection.HTTPConnection object at 0x0000027F1D168760>: Failed to establish a new connection: [WinError 10061] 由于目标计算机积极拒绝，无法连接。

During handling of the above exception, another exception occurred:

Traceback (most recent call last):
  File "C:\Users\93057\PycharmProjects\pythonProject\venv\lib\site-packages\requests\adapters.py", line 439, in send
    resp = conn.urlopen(
  File "C:\Users\93057\PycharmProjects\pythonProject\venv\lib\site-packages\urllib3\connectionpool.py", line 755, in urlopen
    retries = retries.increment(
  File "C:\Users\93057\PycharmProjects\pythonProject\venv\lib\site-packages\urllib3\util\retry.py", line 573, in increment
    raise MaxRetryError(_pool, url, error or ResponseError(cause))
urllib3.exceptions.MaxRetryError: HTTPConnectionPool(host='117.114.149.66', port=53281): Max retries exceeded with url: http://httpbin.org/get (Caused by ProxyError('Cannot connect to proxy.', NewConnectionError('<urllib3.connection.HTTPConnection object at 0x0000027F1D168760>: Failed to establish a new connection: [WinError 10061] 由于目标计算机积极拒绝，无法连接。')))

During handling of the above exception, another exception occurred:

Traceback (most recent call last):
  File "C:\Users\93057\PycharmProjects\IP_Proxy_Pool\core\proxy_validate\httpbin_validator.py", line 57, in __check_http_proxies
    response = requests.get(test_url, headers=get_request_headers(), proxies=proxies, timeout=TEST_TIMEOUT)
  File "C:\Users\93057\PycharmProjects\pythonProject\venv\lib\site-packages\requests\api.py", line 76, in get
    return request('get', url, params=params, **kwargs)
  File "C:\Users\93057\PycharmProjects\pythonProject\venv\lib\site-packages\requests\api.py", line 61, in request
    return session.request(method=method, url=url, **kwargs)
  File "C:\Users\93057\PycharmProjects\pythonProject\venv\lib\site-packages\requests\sessions.py", line 542, in request
    resp = self.send(prep, **send_kwargs)
  File "C:\Users\93057\PycharmProjects\pythonProject\venv\lib\site-packages\requests\sessions.py", line 655, in send
    r = adapter.send(request, **kwargs)
  File "C:\Users\93057\PycharmProjects\pythonProject\venv\lib\site-packages\requests\adapters.py", line 510, in send
    raise ProxyError(e, request=request)
requests.exceptions.ProxyError: HTTPConnectionPool(host='117.114.149.66', port=53281): Max retries exceeded with url: http://httpbin.org/get (Caused by ProxyError('Cannot connect to proxy.', NewConnectionError('<urllib3.connection.HTTPConnection object at 0x0000027F1D168760>: Failed to establish a new connection: [WinError 10061] 由于目标计算机积极拒绝，无法连接。')))
2021-32-02/24/21 00:32:31 connectionpool.py [lines:971] DEBUG: Starting new HTTPS connection (1): httpbin.org:443
2021-32-02/24/21 00:32:33 httpbin_validator.py [lines:80] ERROR: HTTPSConnectionPool(host='httpbin.org', port=443): Max retries exceeded with url: /get (Caused by ProxyError('Cannot connect to proxy.', NewConnectionError('<urllib3.connection.HTTPSConnection object at 0x0000027F1D209190>: Failed to establish a new connection: [WinError 10061] 由于目标计算机积极拒绝，无法连接。')))
Traceback (most recent call last):
  File "C:\Users\93057\PycharmProjects\pythonProject\venv\lib\site-packages\urllib3\connection.py", line 169, in _new_conn
    conn = connection.create_connection(
  File "C:\Users\93057\PycharmProjects\pythonProject\venv\lib\site-packages\urllib3\util\connection.py", line 96, in create_connection
    raise err
  File "C:\Users\93057\PycharmProjects\pythonProject\venv\lib\site-packages\urllib3\util\connection.py", line 86, in create_connection
    sock.connect(sa)
ConnectionRefusedError: [WinError 10061] 由于目标计算机积极拒绝，无法连接。

During handling of the above exception, another exception occurred:

Traceback (most recent call last):
  File "C:\Users\93057\PycharmProjects\pythonProject\venv\lib\site-packages\urllib3\connectionpool.py", line 696, in urlopen
    self._prepare_proxy(conn)
  File "C:\Users\93057\PycharmProjects\pythonProject\venv\lib\site-packages\urllib3\connectionpool.py", line 964, in _prepare_proxy
    conn.connect()
  File "C:\Users\93057\PycharmProjects\pythonProject\venv\lib\site-packages\urllib3\connection.py", line 353, in connect
    conn = self._new_conn()
  File "C:\Users\93057\PycharmProjects\pythonProject\venv\lib\site-packages\urllib3\connection.py", line 181, in _new_conn
    raise NewConnectionError(
urllib3.exceptions.NewConnectionError: <urllib3.connection.HTTPSConnection object at 0x0000027F1D209190>: Failed to establish a new connection: [WinError 10061] 由于目标计算机积极拒绝，无法连接。

During handling of the above exception, another exception occurred:

Traceback (most recent call last):
  File "C:\Users\93057\PycharmProjects\pythonProject\venv\lib\site-packages\requests\adapters.py", line 439, in send
    resp = conn.urlopen(
  File "C:\Users\93057\PycharmProjects\pythonProject\venv\lib\site-packages\urllib3\connectionpool.py", line 755, in urlopen
    retries = retries.increment(
  File "C:\Users\93057\PycharmProjects\pythonProject\venv\lib\site-packages\urllib3\util\retry.py", line 573, in increment
    raise MaxRetryError(_pool, url, error or ResponseError(cause))
urllib3.exceptions.MaxRetryError: HTTPSConnectionPool(host='httpbin.org', port=443): Max retries exceeded with url: /get (Caused by ProxyError('Cannot connect to proxy.', NewConnectionError('<urllib3.connection.HTTPSConnection object at 0x0000027F1D209190>: Failed to establish a new connection: [WinError 10061] 由于目标计算机积极拒绝，无法连接。')))

During handling of the above exception, another exception occurred:

Traceback (most recent call last):
  File "C:\Users\93057\PycharmProjects\IP_Proxy_Pool\core\proxy_validate\httpbin_validator.py", line 57, in __check_http_proxies
    response = requests.get(test_url, headers=get_request_headers(), proxies=proxies, timeout=TEST_TIMEOUT)
  File "C:\Users\93057\PycharmProjects\pythonProject\venv\lib\site-packages\requests\api.py", line 76, in get
    return request('get', url, params=params, **kwargs)
  File "C:\Users\93057\PycharmProjects\pythonProject\venv\lib\site-packages\requests\api.py", line 61, in request
    return session.request(method=method, url=url, **kwargs)
  File "C:\Users\93057\PycharmProjects\pythonProject\venv\lib\site-packages\requests\sessions.py", line 542, in request
    resp = self.send(prep, **send_kwargs)
  File "C:\Users\93057\PycharmProjects\pythonProject\venv\lib\site-packages\requests\sessions.py", line 655, in send
    r = adapter.send(request, **kwargs)
  File "C:\Users\93057\PycharmProjects\pythonProject\venv\lib\site-packages\requests\adapters.py", line 510, in send
    raise ProxyError(e, request=request)
requests.exceptions.ProxyError: HTTPSConnectionPool(host='httpbin.org', port=443): Max retries exceeded with url: /get (Caused by ProxyError('Cannot connect to proxy.', NewConnectionError('<urllib3.connection.HTTPSConnection object at 0x0000027F1D209190>: Failed to establish a new connection: [WinError 10061] 由于目标计算机积极拒绝，无法连接。')))
2021-32-02/24/21 00:32:45 connectionpool.py [lines:227] DEBUG: Starting new HTTP connection (1): 117.114.149.66:53281
2021-32-02/24/21 00:32:47 connectionpool.py [lines:971] DEBUG: Starting new HTTPS connection (1): httpbin.org:443
2021-38-02/24/21 00:38:07 connectionpool.py [lines:227] DEBUG: Starting new HTTP connection (1): 213.6.66.66:48687
2021-38-02/24/21 00:38:12 connectionpool.py [lines:971] DEBUG: Starting new HTTPS connection (1): httpbin.org:443
2021-38-02/24/21 00:38:45 connectionpool.py [lines:227] DEBUG: Starting new HTTP connection (1): 88.255.102.2:8080
2021-38-02/24/21 00:38:50 connectionpool.py [lines:971] DEBUG: Starting new HTTPS connection (1): httpbin.org:443
2021-40-02/24/21 00:40:31 connectionpool.py [lines:227] DEBUG: Starting new HTTP connection (1): 88.255.102.2:8080
2021-40-02/24/21 00:40:37 connectionpool.py [lines:971] DEBUG: Starting new HTTPS connection (1): httpbin.org:443
2021-41-02/24/21 00:41:06 connectionpool.py [lines:227] DEBUG: Starting new HTTP connection (1): 96.113.165.182:3128
2021-41-02/24/21 00:41:07 connectionpool.py [lines:452] DEBUG: http://96.113.165.182:3128 "GET http://httpbin.org/get HTTP/1.1" 200 566
2021-41-02/24/21 00:41:07 connectionpool.py [lines:971] DEBUG: Starting new HTTPS connection (1): httpbin.org:443
2021-41-02/24/21 00:41:21 connectionpool.py [lines:227] DEBUG: Starting new HTTP connection (1): 96.113.165.182:3128
2021-41-02/24/21 00:41:26 connectionpool.py [lines:971] DEBUG: Starting new HTTPS connection (1): httpbin.org:443
2021-41-02/24/21 00:41:38 connectionpool.py [lines:227] DEBUG: Starting new HTTP connection (1): 96.113.165.182:3128
2021-41-02/24/21 00:41:43 httpbin_validator.py [lines:80] ERROR: HTTPConnectionPool(host='96.113.165.182', port=3128): Max retries exceeded with url: http://httpbin.org/get (Caused by ConnectTimeoutError(<urllib3.connection.HTTPConnection object at 0x0000018B70BD8760>, 'Connection to 96.113.165.182 timed out. (connect timeout=5)'))
Traceback (most recent call last):
  File "C:\Users\93057\PycharmProjects\pythonProject\venv\lib\site-packages\urllib3\connection.py", line 169, in _new_conn
    conn = connection.create_connection(
  File "C:\Users\93057\PycharmProjects\pythonProject\venv\lib\site-packages\urllib3\util\connection.py", line 96, in create_connection
    raise err
  File "C:\Users\93057\PycharmProjects\pythonProject\venv\lib\site-packages\urllib3\util\connection.py", line 86, in create_connection
    sock.connect(sa)
socket.timeout: timed out

During handling of the above exception, another exception occurred:

Traceback (most recent call last):
  File "C:\Users\93057\PycharmProjects\pythonProject\venv\lib\site-packages\urllib3\connectionpool.py", line 699, in urlopen
    httplib_response = self._make_request(
  File "C:\Users\93057\PycharmProjects\pythonProject\venv\lib\site-packages\urllib3\connectionpool.py", line 394, in _make_request
    conn.request(method, url, **httplib_request_kw)
  File "C:\Users\93057\PycharmProjects\pythonProject\venv\lib\site-packages\urllib3\connection.py", line 234, in request
    super(HTTPConnection, self).request(method, url, body=body, headers=headers)
  File "C:\Users\93057\AppData\Local\Programs\Python\Python39\lib\http\client.py", line 1255, in request
    self._send_request(method, url, body, headers, encode_chunked)
  File "C:\Users\93057\AppData\Local\Programs\Python\Python39\lib\http\client.py", line 1301, in _send_request
    self.endheaders(body, encode_chunked=encode_chunked)
  File "C:\Users\93057\AppData\Local\Programs\Python\Python39\lib\http\client.py", line 1250, in endheaders
    self._send_output(message_body, encode_chunked=encode_chunked)
  File "C:\Users\93057\AppData\Local\Programs\Python\Python39\lib\http\client.py", line 1010, in _send_output
    self.send(msg)
  File "C:\Users\93057\AppData\Local\Programs\Python\Python39\lib\http\client.py", line 950, in send
    self.connect()
  File "C:\Users\93057\PycharmProjects\pythonProject\venv\lib\site-packages\urllib3\connection.py", line 200, in connect
    conn = self._new_conn()
  File "C:\Users\93057\PycharmProjects\pythonProject\venv\lib\site-packages\urllib3\connection.py", line 174, in _new_conn
    raise ConnectTimeoutError(
urllib3.exceptions.ConnectTimeoutError: (<urllib3.connection.HTTPConnection object at 0x0000018B70BD8760>, 'Connection to 96.113.165.182 timed out. (connect timeout=5)')

During handling of the above exception, another exception occurred:

Traceback (most recent call last):
  File "C:\Users\93057\PycharmProjects\pythonProject\venv\lib\site-packages\requests\adapters.py", line 439, in send
    resp = conn.urlopen(
  File "C:\Users\93057\PycharmProjects\pythonProject\venv\lib\site-packages\urllib3\connectionpool.py", line 755, in urlopen
    retries = retries.increment(
  File "C:\Users\93057\PycharmProjects\pythonProject\venv\lib\site-packages\urllib3\util\retry.py", line 573, in increment
    raise MaxRetryError(_pool, url, error or ResponseError(cause))
urllib3.exceptions.MaxRetryError: HTTPConnectionPool(host='96.113.165.182', port=3128): Max retries exceeded with url: http://httpbin.org/get (Caused by ConnectTimeoutError(<urllib3.connection.HTTPConnection object at 0x0000018B70BD8760>, 'Connection to 96.113.165.182 timed out. (connect timeout=5)'))

During handling of the above exception, another exception occurred:

Traceback (most recent call last):
  File "C:\Users\93057\PycharmProjects\IP_Proxy_Pool\core\proxy_validate\httpbin_validator.py", line 57, in __check_http_proxies
    response = requests.get(test_url, headers=get_request_headers(), proxies=proxies, timeout=TEST_TIMEOUT)
  File "C:\Users\93057\PycharmProjects\pythonProject\venv\lib\site-packages\requests\api.py", line 76, in get
    return request('get', url, params=params, **kwargs)
  File "C:\Users\93057\PycharmProjects\pythonProject\venv\lib\site-packages\requests\api.py", line 61, in request
    return session.request(method=method, url=url, **kwargs)
  File "C:\Users\93057\PycharmProjects\pythonProject\venv\lib\site-packages\requests\sessions.py", line 542, in request
    resp = self.send(prep, **send_kwargs)
  File "C:\Users\93057\PycharmProjects\pythonProject\venv\lib\site-packages\requests\sessions.py", line 655, in send
    r = adapter.send(request, **kwargs)
  File "C:\Users\93057\PycharmProjects\pythonProject\venv\lib\site-packages\requests\adapters.py", line 504, in send
    raise ConnectTimeout(e, request=request)
requests.exceptions.ConnectTimeout: HTTPConnectionPool(host='96.113.165.182', port=3128): Max retries exceeded with url: http://httpbin.org/get (Caused by ConnectTimeoutError(<urllib3.connection.HTTPConnection object at 0x0000018B70BD8760>, 'Connection to 96.113.165.182 timed out. (connect timeout=5)'))
2021-41-02/24/21 00:41:43 connectionpool.py [lines:971] DEBUG: Starting new HTTPS connection (1): httpbin.org:443
2021-41-02/24/21 00:41:48 httpbin_validator.py [lines:80] ERROR: HTTPSConnectionPool(host='httpbin.org', port=443): Max retries exceeded with url: /get (Caused by ConnectTimeoutError(<urllib3.connection.HTTPSConnection object at 0x0000018B70C79190>, 'Connection to 96.113.165.182 timed out. (connect timeout=5)'))
Traceback (most recent call last):
  File "C:\Users\93057\PycharmProjects\pythonProject\venv\lib\site-packages\urllib3\connection.py", line 169, in _new_conn
    conn = connection.create_connection(
  File "C:\Users\93057\PycharmProjects\pythonProject\venv\lib\site-packages\urllib3\util\connection.py", line 96, in create_connection
    raise err
  File "C:\Users\93057\PycharmProjects\pythonProject\venv\lib\site-packages\urllib3\util\connection.py", line 86, in create_connection
    sock.connect(sa)
socket.timeout: timed out

During handling of the above exception, another exception occurred:

Traceback (most recent call last):
  File "C:\Users\93057\PycharmProjects\pythonProject\venv\lib\site-packages\urllib3\connectionpool.py", line 696, in urlopen
    self._prepare_proxy(conn)
  File "C:\Users\93057\PycharmProjects\pythonProject\venv\lib\site-packages\urllib3\connectionpool.py", line 964, in _prepare_proxy
    conn.connect()
  File "C:\Users\93057\PycharmProjects\pythonProject\venv\lib\site-packages\urllib3\connection.py", line 353, in connect
    conn = self._new_conn()
  File "C:\Users\93057\PycharmProjects\pythonProject\venv\lib\site-packages\urllib3\connection.py", line 174, in _new_conn
    raise ConnectTimeoutError(
urllib3.exceptions.ConnectTimeoutError: (<urllib3.connection.HTTPSConnection object at 0x0000018B70C79190>, 'Connection to 96.113.165.182 timed out. (connect timeout=5)')

During handling of the above exception, another exception occurred:

Traceback (most recent call last):
  File "C:\Users\93057\PycharmProjects\pythonProject\venv\lib\site-packages\requests\adapters.py", line 439, in send
    resp = conn.urlopen(
  File "C:\Users\93057\PycharmProjects\pythonProject\venv\lib\site-packages\urllib3\connectionpool.py", line 755, in urlopen
    retries = retries.increment(
  File "C:\Users\93057\PycharmProjects\pythonProject\venv\lib\site-packages\urllib3\util\retry.py", line 573, in increment
    raise MaxRetryError(_pool, url, error or ResponseError(cause))
urllib3.exceptions.MaxRetryError: HTTPSConnectionPool(host='httpbin.org', port=443): Max retries exceeded with url: /get (Caused by ConnectTimeoutError(<urllib3.connection.HTTPSConnection object at 0x0000018B70C79190>, 'Connection to 96.113.165.182 timed out. (connect timeout=5)'))

During handling of the above exception, another exception occurred:

Traceback (most recent call last):
  File "C:\Users\93057\PycharmProjects\IP_Proxy_Pool\core\proxy_validate\httpbin_validator.py", line 57, in __check_http_proxies
    response = requests.get(test_url, headers=get_request_headers(), proxies=proxies, timeout=TEST_TIMEOUT)
  File "C:\Users\93057\PycharmProjects\pythonProject\venv\lib\site-packages\requests\api.py", line 76, in get
    return request('get', url, params=params, **kwargs)
  File "C:\Users\93057\PycharmProjects\pythonProject\venv\lib\site-packages\requests\api.py", line 61, in request
    return session.request(method=method, url=url, **kwargs)
  File "C:\Users\93057\PycharmProjects\pythonProject\venv\lib\site-packages\requests\sessions.py", line 542, in request
    resp = self.send(prep, **send_kwargs)
  File "C:\Users\93057\PycharmProjects\pythonProject\venv\lib\site-packages\requests\sessions.py", line 655, in send
    r = adapter.send(request, **kwargs)
  File "C:\Users\93057\PycharmProjects\pythonProject\venv\lib\site-packages\requests\adapters.py", line 504, in send
    raise ConnectTimeout(e, request=request)
requests.exceptions.ConnectTimeout: HTTPSConnectionPool(host='httpbin.org', port=443): Max retries exceeded with url: /get (Caused by ConnectTimeoutError(<urllib3.connection.HTTPSConnection object at 0x0000018B70C79190>, 'Connection to 96.113.165.182 timed out. (connect timeout=5)'))
2021-42-02/24/21 00:42:28 connectionpool.py [lines:227] DEBUG: Starting new HTTP connection (1): 150.239.66.249:3128
2021-42-02/24/21 00:42:33 httpbin_validator.py [lines:80] ERROR: HTTPConnectionPool(host='150.239.66.249', port=3128): Max retries exceeded with url: http://httpbin.org/get (Caused by ConnectTimeoutError(<urllib3.connection.HTTPConnection object at 0x000001ED56EC9760>, 'Connection to 150.239.66.249 timed out. (connect timeout=5)'))
Traceback (most recent call last):
  File "C:\Users\93057\PycharmProjects\pythonProject\venv\lib\site-packages\urllib3\connection.py", line 169, in _new_conn
    conn = connection.create_connection(
  File "C:\Users\93057\PycharmProjects\pythonProject\venv\lib\site-packages\urllib3\util\connection.py", line 96, in create_connection
    raise err
  File "C:\Users\93057\PycharmProjects\pythonProject\venv\lib\site-packages\urllib3\util\connection.py", line 86, in create_connection
    sock.connect(sa)
socket.timeout: timed out

During handling of the above exception, another exception occurred:

Traceback (most recent call last):
  File "C:\Users\93057\PycharmProjects\pythonProject\venv\lib\site-packages\urllib3\connectionpool.py", line 699, in urlopen
    httplib_response = self._make_request(
  File "C:\Users\93057\PycharmProjects\pythonProject\venv\lib\site-packages\urllib3\connectionpool.py", line 394, in _make_request
    conn.request(method, url, **httplib_request_kw)
  File "C:\Users\93057\PycharmProjects\pythonProject\venv\lib\site-packages\urllib3\connection.py", line 234, in request
    super(HTTPConnection, self).request(method, url, body=body, headers=headers)
  File "C:\Users\93057\AppData\Local\Programs\Python\Python39\lib\http\client.py", line 1255, in request
    self._send_request(method, url, body, headers, encode_chunked)
  File "C:\Users\93057\AppData\Local\Programs\Python\Python39\lib\http\client.py", line 1301, in _send_request
    self.endheaders(body, encode_chunked=encode_chunked)
  File "C:\Users\93057\AppData\Local\Programs\Python\Python39\lib\http\client.py", line 1250, in endheaders
    self._send_output(message_body, encode_chunked=encode_chunked)
  File "C:\Users\93057\AppData\Local\Programs\Python\Python39\lib\http\client.py", line 1010, in _send_output
    self.send(msg)
  File "C:\Users\93057\AppData\Local\Programs\Python\Python39\lib\http\client.py", line 950, in send
    self.connect()
  File "C:\Users\93057\PycharmProjects\pythonProject\venv\lib\site-packages\urllib3\connection.py", line 200, in connect
    conn = self._new_conn()
  File "C:\Users\93057\PycharmProjects\pythonProject\venv\lib\site-packages\urllib3\connection.py", line 174, in _new_conn
    raise ConnectTimeoutError(
urllib3.exceptions.ConnectTimeoutError: (<urllib3.connection.HTTPConnection object at 0x000001ED56EC9760>, 'Connection to 150.239.66.249 timed out. (connect timeout=5)')

During handling of the above exception, another exception occurred:

Traceback (most recent call last):
  File "C:\Users\93057\PycharmProjects\pythonProject\venv\lib\site-packages\requests\adapters.py", line 439, in send
    resp = conn.urlopen(
  File "C:\Users\93057\PycharmProjects\pythonProject\venv\lib\site-packages\urllib3\connectionpool.py", line 755, in urlopen
    retries = retries.increment(
  File "C:\Users\93057\PycharmProjects\pythonProject\venv\lib\site-packages\urllib3\util\retry.py", line 573, in increment
    raise MaxRetryError(_pool, url, error or ResponseError(cause))
urllib3.exceptions.MaxRetryError: HTTPConnectionPool(host='150.239.66.249', port=3128): Max retries exceeded with url: http://httpbin.org/get (Caused by ConnectTimeoutError(<urllib3.connection.HTTPConnection object at 0x000001ED56EC9760>, 'Connection to 150.239.66.249 timed out. (connect timeout=5)'))

During handling of the above exception, another exception occurred:

Traceback (most recent call last):
  File "C:\Users\93057\PycharmProjects\IP_Proxy_Pool\core\proxy_validate\httpbin_validator.py", line 57, in __check_http_proxies
    response = requests.get(test_url, headers=get_request_headers(), proxies=proxies, timeout=TEST_TIMEOUT)
  File "C:\Users\93057\PycharmProjects\pythonProject\venv\lib\site-packages\requests\api.py", line 76, in get
    return request('get', url, params=params, **kwargs)
  File "C:\Users\93057\PycharmProjects\pythonProject\venv\lib\site-packages\requests\api.py", line 61, in request
    return session.request(method=method, url=url, **kwargs)
  File "C:\Users\93057\PycharmProjects\pythonProject\venv\lib\site-packages\requests\sessions.py", line 542, in request
    resp = self.send(prep, **send_kwargs)
  File "C:\Users\93057\PycharmProjects\pythonProject\venv\lib\site-packages\requests\sessions.py", line 655, in send
    r = adapter.send(request, **kwargs)
  File "C:\Users\93057\PycharmProjects\pythonProject\venv\lib\site-packages\requests\adapters.py", line 504, in send
    raise ConnectTimeout(e, request=request)
requests.exceptions.ConnectTimeout: HTTPConnectionPool(host='150.239.66.249', port=3128): Max retries exceeded with url: http://httpbin.org/get (Caused by ConnectTimeoutError(<urllib3.connection.HTTPConnection object at 0x000001ED56EC9760>, 'Connection to 150.239.66.249 timed out. (connect timeout=5)'))
2021-42-02/24/21 00:42:33 connectionpool.py [lines:971] DEBUG: Starting new HTTPS connection (1): httpbin.org:443
2021-42-02/24/21 00:42:38 httpbin_validator.py [lines:80] ERROR: HTTPSConnectionPool(host='httpbin.org', port=443): Max retries exceeded with url: /get (Caused by ConnectTimeoutError(<urllib3.connection.HTTPSConnection object at 0x000001ED56F69190>, 'Connection to 150.239.66.249 timed out. (connect timeout=5)'))
Traceback (most recent call last):
  File "C:\Users\93057\PycharmProjects\pythonProject\venv\lib\site-packages\urllib3\connection.py", line 169, in _new_conn
    conn = connection.create_connection(
  File "C:\Users\93057\PycharmProjects\pythonProject\venv\lib\site-packages\urllib3\util\connection.py", line 96, in create_connection
    raise err
  File "C:\Users\93057\PycharmProjects\pythonProject\venv\lib\site-packages\urllib3\util\connection.py", line 86, in create_connection
    sock.connect(sa)
socket.timeout: timed out

During handling of the above exception, another exception occurred:

Traceback (most recent call last):
  File "C:\Users\93057\PycharmProjects\pythonProject\venv\lib\site-packages\urllib3\connectionpool.py", line 696, in urlopen
    self._prepare_proxy(conn)
  File "C:\Users\93057\PycharmProjects\pythonProject\venv\lib\site-packages\urllib3\connectionpool.py", line 964, in _prepare_proxy
    conn.connect()
  File "C:\Users\93057\PycharmProjects\pythonProject\venv\lib\site-packages\urllib3\connection.py", line 353, in connect
    conn = self._new_conn()
  File "C:\Users\93057\PycharmProjects\pythonProject\venv\lib\site-packages\urllib3\connection.py", line 174, in _new_conn
    raise ConnectTimeoutError(
urllib3.exceptions.ConnectTimeoutError: (<urllib3.connection.HTTPSConnection object at 0x000001ED56F69190>, 'Connection to 150.239.66.249 timed out. (connect timeout=5)')

During handling of the above exception, another exception occurred:

Traceback (most recent call last):
  File "C:\Users\93057\PycharmProjects\pythonProject\venv\lib\site-packages\requests\adapters.py", line 439, in send
    resp = conn.urlopen(
  File "C:\Users\93057\PycharmProjects\pythonProject\venv\lib\site-packages\urllib3\connectionpool.py", line 755, in urlopen
    retries = retries.increment(
  File "C:\Users\93057\PycharmProjects\pythonProject\venv\lib\site-packages\urllib3\util\retry.py", line 573, in increment
    raise MaxRetryError(_pool, url, error or ResponseError(cause))
urllib3.exceptions.MaxRetryError: HTTPSConnectionPool(host='httpbin.org', port=443): Max retries exceeded with url: /get (Caused by ConnectTimeoutError(<urllib3.connection.HTTPSConnection object at 0x000001ED56F69190>, 'Connection to 150.239.66.249 timed out. (connect timeout=5)'))

During handling of the above exception, another exception occurred:

Traceback (most recent call last):
  File "C:\Users\93057\PycharmProjects\IP_Proxy_Pool\core\proxy_validate\httpbin_validator.py", line 57, in __check_http_proxies
    response = requests.get(test_url, headers=get_request_headers(), proxies=proxies, timeout=TEST_TIMEOUT)
  File "C:\Users\93057\PycharmProjects\pythonProject\venv\lib\site-packages\requests\api.py", line 76, in get
    return request('get', url, params=params, **kwargs)
  File "C:\Users\93057\PycharmProjects\pythonProject\venv\lib\site-packages\requests\api.py", line 61, in request
    return session.request(method=method, url=url, **kwargs)
  File "C:\Users\93057\PycharmProjects\pythonProject\venv\lib\site-packages\requests\sessions.py", line 542, in request
    resp = self.send(prep, **send_kwargs)
  File "C:\Users\93057\PycharmProjects\pythonProject\venv\lib\site-packages\requests\sessions.py", line 655, in send
    r = adapter.send(request, **kwargs)
  File "C:\Users\93057\PycharmProjects\pythonProject\venv\lib\site-packages\requests\adapters.py", line 504, in send
    raise ConnectTimeout(e, request=request)
requests.exceptions.ConnectTimeout: HTTPSConnectionPool(host='httpbin.org', port=443): Max retries exceeded with url: /get (Caused by ConnectTimeoutError(<urllib3.connection.HTTPSConnection object at 0x000001ED56F69190>, 'Connection to 150.239.66.249 timed out. (connect timeout=5)'))
2021-42-02/24/21 00:42:41 connectionpool.py [lines:227] DEBUG: Starting new HTTP connection (1): 150.239.66.249:3128
2021-42-02/24/21 00:42:46 connectionpool.py [lines:971] DEBUG: Starting new HTTPS connection (1): httpbin.org:443
2021-43-02/24/21 00:43:33 connectionpool.py [lines:227] DEBUG: Starting new HTTP connection (1): 62.33.207.202:3128
2021-43-02/24/21 00:43:38 connectionpool.py [lines:971] DEBUG: Starting new HTTPS connection (1): httpbin.org:443
2021-58-02/24/21 00:58:04 connectionpool.py [lines:227] DEBUG: Starting new HTTP connection (1): 62.33.207.202:3128
2021-58-02/24/21 00:58:09 httpbin_validator.py [lines:80] DEBUG: HTTPConnectionPool(host='62.33.207.202', port=3128): Max retries exceeded with url: http://httpbin.org/get (Caused by ConnectTimeoutError(<urllib3.connection.HTTPConnection object at 0x00000260B75797C0>, 'Connection to 62.33.207.202 timed out. (connect timeout=5)'))
2021-58-02/24/21 00:58:09 connectionpool.py [lines:971] DEBUG: Starting new HTTPS connection (1): httpbin.org:443
2021-58-02/24/21 00:58:14 httpbin_validator.py [lines:80] DEBUG: HTTPSConnectionPool(host='httpbin.org', port=443): Max retries exceeded with url: /get (Caused by ConnectTimeoutError(<urllib3.connection.HTTPSConnection object at 0x00000260B75A5040>, 'Connection to 62.33.207.202 timed out. (connect timeout=5)'))
2021-49-02/28/21 15:49:58 connectionpool.py [lines:227] DEBUG: Starting new HTTP connection (1): 138.117.85.113:999
2021-50-02/28/21 15:50:03 httpbin_validator.py [lines:80] DEBUG: HTTPConnectionPool(host='138.117.85.113', port=999): Max retries exceeded with url: http://httpbin.org/get (Caused by ConnectTimeoutError(<urllib3.connection.HTTPConnection object at 0x000001637D75A760>, 'Connection to 138.117.85.113 timed out. (connect timeout=5)'))
2021-50-02/28/21 15:50:03 connectionpool.py [lines:971] DEBUG: Starting new HTTPS connection (1): httpbin.org:443
2021-50-02/28/21 15:50:10 httpbin_validator.py [lines:80] DEBUG: HTTPSConnectionPool(host='httpbin.org', port=443): Max retries exceeded with url: /get (Caused by ProxyError('Cannot connect to proxy.', timeout('_ssl.c:1106: The handshake operation timed out')))
2021-50-02/28/21 15:50:37 connectionpool.py [lines:227] DEBUG: Starting new HTTP connection (1): 138.117.85.113:999
2021-50-02/28/21 15:50:41 connectionpool.py [lines:452] DEBUG: http://138.117.85.113:999 "GET http://httpbin.org/get HTTP/1.1" 200 581
2021-50-02/28/21 15:50:41 connectionpool.py [lines:971] DEBUG: Starting new HTTPS connection (1): httpbin.org:443
2021-50-02/28/21 15:50:46 httpbin_validator.py [lines:80] DEBUG: HTTPSConnectionPool(host='httpbin.org', port=443): Max retries exceeded with url: /get (Caused by ConnectTimeoutError(<urllib3.connection.HTTPSConnection object at 0x0000021A8CDDA7C0>, 'Connection to 138.117.85.113 timed out. (connect timeout=5)'))
2021-51-02/28/21 15:51:06 connectionpool.py [lines:227] DEBUG: Starting new HTTP connection (1): 138.117.85.113:999
2021-51-02/28/21 15:51:11 httpbin_validator.py [lines:80] DEBUG: HTTPConnectionPool(host='138.117.85.113', port=999): Max retries exceeded with url: http://httpbin.org/get (Caused by ConnectTimeoutError(<urllib3.connection.HTTPConnection object at 0x00000154A001A760>, 'Connection to 138.117.85.113 timed out. (connect timeout=5)'))
2021-51-02/28/21 15:51:11 connectionpool.py [lines:971] DEBUG: Starting new HTTPS connection (1): httpbin.org:443
2021-51-02/28/21 15:51:16 httpbin_validator.py [lines:80] DEBUG: HTTPSConnectionPool(host='httpbin.org', port=443): Max retries exceeded with url: /get (Caused by ConnectTimeoutError(<urllib3.connection.HTTPSConnection object at 0x00000154A0048040>, 'Connection to 138.117.85.113 timed out. (connect timeout=5)'))
2021-51-02/28/21 15:51:19 connectionpool.py [lines:227] DEBUG: Starting new HTTP connection (1): 138.117.85.113:999
2021-51-02/28/21 15:51:24 httpbin_validator.py [lines:80] DEBUG: HTTPConnectionPool(host='138.117.85.113', port=999): Max retries exceeded with url: http://httpbin.org/get (Caused by ConnectTimeoutError(<urllib3.connection.HTTPConnection object at 0x0000019A92EBA760>, 'Connection to 138.117.85.113 timed out. (connect timeout=5)'))
2021-51-02/28/21 15:51:24 connectionpool.py [lines:971] DEBUG: Starting new HTTPS connection (1): httpbin.org:443
2021-51-02/28/21 15:51:29 httpbin_validator.py [lines:80] DEBUG: HTTPSConnectionPool(host='httpbin.org', port=443): Max retries exceeded with url: /get (Caused by ConnectTimeoutError(<urllib3.connection.HTTPSConnection object at 0x0000019A92EE9040>, 'Connection to 138.117.85.113 timed out. (connect timeout=5)'))
2021-52-02/28/21 15:52:00 connectionpool.py [lines:227] DEBUG: Starting new HTTP connection (1): 138.117.85.113:999
2021-52-02/28/21 15:52:02 httpbin_validator.py [lines:80] DEBUG: HTTPConnectionPool(host='138.117.85.113', port=999): Max retries exceeded with url: http://httpbin.org/get (Caused by ConnectTimeoutError(<urllib3.connection.HTTPConnection object at 0x00000189A1EFA760>, 'Connection to 138.117.85.113 timed out. (connect timeout=2)'))
2021-52-02/28/21 15:52:02 connectionpool.py [lines:971] DEBUG: Starting new HTTPS connection (1): httpbin.org:443
2021-52-02/28/21 15:52:04 httpbin_validator.py [lines:80] DEBUG: HTTPSConnectionPool(host='httpbin.org', port=443): Max retries exceeded with url: /get (Caused by ConnectTimeoutError(<urllib3.connection.HTTPSConnection object at 0x00000189A1F28040>, 'Connection to 138.117.85.113 timed out. (connect timeout=2)'))
2021-52-02/28/21 15:52:06 connectionpool.py [lines:227] DEBUG: Starting new HTTP connection (1): 138.117.85.113:999
2021-52-02/28/21 15:52:08 httpbin_validator.py [lines:80] DEBUG: HTTPConnectionPool(host='138.117.85.113', port=999): Max retries exceeded with url: http://httpbin.org/get (Caused by ConnectTimeoutError(<urllib3.connection.HTTPConnection object at 0x000001C64A1AA760>, 'Connection to 138.117.85.113 timed out. (connect timeout=2)'))
2021-52-02/28/21 15:52:08 connectionpool.py [lines:971] DEBUG: Starting new HTTPS connection (1): httpbin.org:443
2021-52-02/28/21 15:52:11 httpbin_validator.py [lines:80] DEBUG: HTTPSConnectionPool(host='httpbin.org', port=443): Max retries exceeded with url: /get (Caused by ConnectTimeoutError(<urllib3.connection.HTTPSConnection object at 0x000001C64A1D8040>, 'Connection to 138.117.85.113 timed out. (connect timeout=2)'))
2021-52-02/28/21 15:52:14 connectionpool.py [lines:227] DEBUG: Starting new HTTP connection (1): 138.117.85.113:999
2021-52-02/28/21 15:52:24 httpbin_validator.py [lines:80] DEBUG: HTTPConnectionPool(host='138.117.85.113', port=999): Max retries exceeded with url: http://httpbin.org/get (Caused by ConnectTimeoutError(<urllib3.connection.HTTPConnection object at 0x000001CC0B25A760>, 'Connection to 138.117.85.113 timed out. (connect timeout=10)'))
2021-52-02/28/21 15:52:24 connectionpool.py [lines:971] DEBUG: Starting new HTTPS connection (1): httpbin.org:443
2021-52-02/28/21 15:52:36 httpbin_validator.py [lines:80] DEBUG: HTTPSConnectionPool(host='httpbin.org', port=443): Max retries exceeded with url: /get (Caused by ProxyError('Cannot connect to proxy.', timeout('_ssl.c:1106: The handshake operation timed out')))
2021-53-02/28/21 15:53:00 connectionpool.py [lines:227] DEBUG: Starting new HTTP connection (1): 138.117.85.113:999
2021-53-02/28/21 15:53:03 connectionpool.py [lines:452] DEBUG: http://138.117.85.113:999 "GET http://httpbin.org/get HTTP/1.1" 200 570
2021-53-02/28/21 15:53:03 connectionpool.py [lines:971] DEBUG: Starting new HTTPS connection (1): httpbin.org:443
2021-53-02/28/21 15:53:08 httpbin_validator.py [lines:80] DEBUG: HTTPSConnectionPool(host='httpbin.org', port=443): Max retries exceeded with url: /get (Caused by ConnectTimeoutError(<urllib3.connection.HTTPSConnection object at 0x000002AA2EFEA7F0>, 'Connection to 138.117.85.113 timed out. (connect timeout=5)'))
2021-53-02/28/21 15:53:15 connectionpool.py [lines:227] DEBUG: Starting new HTTP connection (1): 138.117.85.113:999
2021-53-02/28/21 15:53:20 httpbin_validator.py [lines:80] DEBUG: HTTPConnectionPool(host='138.117.85.113', port=999): Max retries exceeded with url: http://httpbin.org/get (Caused by ConnectTimeoutError(<urllib3.connection.HTTPConnection object at 0x000001EEB313A760>, 'Connection to 138.117.85.113 timed out. (connect timeout=5)'))
2021-53-02/28/21 15:53:20 connectionpool.py [lines:971] DEBUG: Starting new HTTPS connection (1): httpbin.org:443
2021-53-02/28/21 15:53:25 httpbin_validator.py [lines:80] DEBUG: HTTPSConnectionPool(host='httpbin.org', port=443): Max retries exceeded with url: /get (Caused by ConnectTimeoutError(<urllib3.connection.HTTPSConnection object at 0x000001EEB3169040>, 'Connection to 138.117.85.113 timed out. (connect timeout=5)'))
