2021-42-03/07/21 22:42:34 connectionpool.py [lines:227] DEBUG: Starting new HTTP connection (1): 103.156.16.62:8080
2021-42-03/07/21 22:42:34 connectionpool.py [lines:227] DEBUG: Starting new HTTP connection (1): 84.214.150.146:8080
2021-42-03/07/21 22:42:34 connectionpool.py [lines:227] DEBUG: Starting new HTTP connection (1): 122.55.250.90:8080
2021-42-03/07/21 22:42:34 connectionpool.py [lines:227] DEBUG: Starting new HTTP connection (1): 103.153.66.34:8080
2021-42-03/07/21 22:42:34 connectionpool.py [lines:227] DEBUG: Starting new HTTP connection (1): 103.152.5.80:8080
2021-42-03/07/21 22:42:34 connectionpool.py [lines:227] DEBUG: Starting new HTTP connection (1): 106.104.148.208:80
2021-42-03/07/21 22:42:38 connectionpool.py [lines:452] DEBUG: http://103.152.5.80:8080 "GET http://httpbin.org/get HTTP/1.1" 200 544
2021-42-03/07/21 22:42:38 connectionpool.py [lines:971] DEBUG: Starting new HTTPS connection (1): httpbin.org:443
2021-42-03/07/21 22:42:39 httpbin_validator.py [lines:80] DEBUG: HTTPSConnectionPool(host='httpbin.org', port=443): Max retries exceeded with url: /get (Caused by SSLError(SSLError(1, '[SSL: WRONG_VERSION_NUMBER] wrong version number (_ssl.c:1123)')))
2021-42-03/07/21 22:42:39 httpbin_validator.py [lines:80] DEBUG: HTTPConnectionPool(host='122.55.250.90', port=8080): Max retries exceeded with url: http://httpbin.org/get (Caused by ConnectTimeoutError(<urllib3.connection.HTTPConnection object at 0x0000027896FE57F0>, 'Connection to 122.55.250.90 timed out. (connect timeout=5)'))
2021-42-03/07/21 22:42:39 httpbin_validator.py [lines:80] DEBUG: HTTPConnectionPool(host='106.104.148.208', port=80): Max retries exceeded with url: http://httpbin.org/get (Caused by ConnectTimeoutError(<urllib3.connection.HTTPConnection object at 0x0000027896FF3BB0>, 'Connection to 106.104.148.208 timed out. (connect timeout=5)'))
2021-42-03/07/21 22:42:39 connectionpool.py [lines:971] DEBUG: Starting new HTTPS connection (1): httpbin.org:443
2021-42-03/07/21 22:42:39 connectionpool.py [lines:971] DEBUG: Starting new HTTPS connection (1): httpbin.org:443
2021-42-03/07/21 22:42:40 httpbin_validator.py [lines:80] DEBUG: HTTPConnectionPool(host='103.153.66.34', port=8080): Read timed out. (read timeout=5)
2021-42-03/07/21 22:42:40 connectionpool.py [lines:971] DEBUG: Starting new HTTPS connection (1): httpbin.org:443
2021-42-03/07/21 22:42:40 httpbin_validator.py [lines:80] DEBUG: HTTPConnectionPool(host='84.214.150.146', port=8080): Read timed out. (read timeout=5)
2021-42-03/07/21 22:42:40 connectionpool.py [lines:971] DEBUG: Starting new HTTPS connection (1): httpbin.org:443
2021-42-03/07/21 22:42:40 httpbin_validator.py [lines:80] DEBUG: HTTPConnectionPool(host='103.156.16.62', port=8080): Read timed out. (read timeout=5)
2021-42-03/07/21 22:42:40 connectionpool.py [lines:971] DEBUG: Starting new HTTPS connection (1): httpbin.org:443
2021-42-03/07/21 22:42:44 httpbin_validator.py [lines:80] DEBUG: HTTPSConnectionPool(host='httpbin.org', port=443): Max retries exceeded with url: /get (Caused by ConnectTimeoutError(<urllib3.connection.HTTPSConnection object at 0x0000027897013820>, 'Connection to 122.55.250.90 timed out. (connect timeout=5)'))
2021-42-03/07/21 22:42:44 httpbin_validator.py [lines:80] DEBUG: HTTPSConnectionPool(host='httpbin.org', port=443): Max retries exceeded with url: /get (Caused by ConnectTimeoutError(<urllib3.connection.HTTPSConnection object at 0x00000278970137F0>, 'Connection to 106.104.148.208 timed out. (connect timeout=5)'))
2021-42-03/07/21 22:42:45 httpbin_validator.py [lines:80] DEBUG: HTTPSConnectionPool(host='httpbin.org', port=443): Max retries exceeded with url: /get (Caused by ConnectTimeoutError(<urllib3.connection.HTTPSConnection object at 0x0000027896FBBC70>, 'Connection to 84.214.150.146 timed out. (connect timeout=5)'))
2021-42-03/07/21 22:42:45 httpbin_validator.py [lines:80] DEBUG: HTTPSConnectionPool(host='httpbin.org', port=443): Max retries exceeded with url: /get (Caused by ProxyError('Cannot connect to proxy.', timeout('The handshake operation timed out')))
2021-42-03/07/21 22:42:48 httpbin_validator.py [lines:80] DEBUG: HTTPSConnectionPool(host='httpbin.org', port=443): Max retries exceeded with url: /get (Caused by ProxyError('Cannot connect to proxy.', timeout('The handshake operation timed out')))
2021-45-03/07/21 22:45:15 connectionpool.py [lines:227] DEBUG: Starting new HTTP connection (1): 103.156.16.62:8080
2021-45-03/07/21 22:45:15 connectionpool.py [lines:227] DEBUG: Starting new HTTP connection (1): 84.214.150.146:8080
2021-45-03/07/21 22:45:15 connectionpool.py [lines:227] DEBUG: Starting new HTTP connection (1): 122.55.250.90:8080
2021-45-03/07/21 22:45:15 connectionpool.py [lines:227] DEBUG: Starting new HTTP connection (1): 103.153.66.34:8080
2021-45-03/07/21 22:45:15 connectionpool.py [lines:227] DEBUG: Starting new HTTP connection (1): 103.152.5.80:8080
2021-45-03/07/21 22:45:15 connectionpool.py [lines:227] DEBUG: Starting new HTTP connection (1): 106.104.148.208:80
2021-45-03/07/21 22:45:20 httpbin_validator.py [lines:80] DEBUG: HTTPConnectionPool(host='103.156.16.62', port=8080): Max retries exceeded with url: http://httpbin.org/get (Caused by ConnectTimeoutError(<urllib3.connection.HTTPConnection object at 0x000001447D3C1DC0>, 'Connection to 103.156.16.62 timed out. (connect timeout=5)'))
2021-45-03/07/21 22:45:20 httpbin_validator.py [lines:80] DEBUG: HTTPConnectionPool(host='84.214.150.146', port=8080): Max retries exceeded with url: http://httpbin.org/get (Caused by ConnectTimeoutError(<urllib3.connection.HTTPConnection object at 0x000001447D3C1E50>, 'Connection to 84.214.150.146 timed out. (connect timeout=5)'))
2021-45-03/07/21 22:45:20 httpbin_validator.py [lines:80] DEBUG: HTTPConnectionPool(host='122.55.250.90', port=8080): Max retries exceeded with url: http://httpbin.org/get (Caused by ConnectTimeoutError(<urllib3.connection.HTTPConnection object at 0x000001447D4239A0>, 'Connection to 122.55.250.90 timed out. (connect timeout=5)'))
2021-45-03/07/21 22:45:20 httpbin_validator.py [lines:80] DEBUG: HTTPConnectionPool(host='103.153.66.34', port=8080): Max retries exceeded with url: http://httpbin.org/get (Caused by ConnectTimeoutError(<urllib3.connection.HTTPConnection object at 0x000001447D441130>, 'Connection to 103.153.66.34 timed out. (connect timeout=5)'))
2021-45-03/07/21 22:45:20 httpbin_validator.py [lines:80] DEBUG: HTTPConnectionPool(host='103.152.5.80', port=8080): Max retries exceeded with url: http://httpbin.org/get (Caused by ConnectTimeoutError(<urllib3.connection.HTTPConnection object at 0x000001447D42EE50>, 'Connection to 103.152.5.80 timed out. (connect timeout=5)'))
2021-45-03/07/21 22:45:20 httpbin_validator.py [lines:80] DEBUG: HTTPConnectionPool(host='106.104.148.208', port=80): Max retries exceeded with url: http://httpbin.org/get (Caused by ConnectTimeoutError(<urllib3.connection.HTTPConnection object at 0x000001447D42ED60>, 'Connection to 106.104.148.208 timed out. (connect timeout=5)'))
2021-45-03/07/21 22:45:20 connectionpool.py [lines:971] DEBUG: Starting new HTTPS connection (1): httpbin.org:443
2021-45-03/07/21 22:45:20 connectionpool.py [lines:971] DEBUG: Starting new HTTPS connection (1): httpbin.org:443
2021-45-03/07/21 22:45:20 connectionpool.py [lines:971] DEBUG: Starting new HTTPS connection (1): httpbin.org:443
2021-45-03/07/21 22:45:20 connectionpool.py [lines:971] DEBUG: Starting new HTTPS connection (1): httpbin.org:443
2021-45-03/07/21 22:45:20 connectionpool.py [lines:971] DEBUG: Starting new HTTPS connection (1): httpbin.org:443
2021-45-03/07/21 22:45:20 connectionpool.py [lines:971] DEBUG: Starting new HTTPS connection (1): httpbin.org:443
2021-45-03/07/21 22:45:21 httpbin_validator.py [lines:80] DEBUG: HTTPSConnectionPool(host='httpbin.org', port=443): Max retries exceeded with url: /get (Caused by SSLError(SSLError(1, '[SSL: WRONG_VERSION_NUMBER] wrong version number (_ssl.c:1123)')))
2021-45-03/07/21 22:45:25 httpbin_validator.py [lines:80] DEBUG: HTTPSConnectionPool(host='httpbin.org', port=443): Max retries exceeded with url: /get (Caused by ConnectTimeoutError(<urllib3.connection.HTTPSConnection object at 0x000001447D474220>, 'Connection to 84.214.150.146 timed out. (connect timeout=5)'))
2021-45-03/07/21 22:45:25 httpbin_validator.py [lines:80] DEBUG: HTTPSConnectionPool(host='httpbin.org', port=443): Max retries exceeded with url: /get (Caused by ConnectTimeoutError(<urllib3.connection.HTTPSConnection object at 0x000001447D474C70>, 'Connection to 106.104.148.208 timed out. (connect timeout=5)'))
2021-45-03/07/21 22:45:25 httpbin_validator.py [lines:80] DEBUG: HTTPSConnectionPool(host='httpbin.org', port=443): Max retries exceeded with url: /get (Caused by ConnectTimeoutError(<urllib3.connection.HTTPSConnection object at 0x000001447D474AF0>, 'Connection to 103.153.66.34 timed out. (connect timeout=5)'))
2021-45-03/07/21 22:45:25 httpbin_validator.py [lines:80] DEBUG: HTTPSConnectionPool(host='httpbin.org', port=443): Max retries exceeded with url: /get (Caused by ProxyError('Cannot connect to proxy.', timeout('The handshake operation timed out')))
2021-45-03/07/21 22:45:28 httpbin_validator.py [lines:80] DEBUG: HTTPSConnectionPool(host='httpbin.org', port=443): Max retries exceeded with url: /get (Caused by ProxyError('Cannot connect to proxy.', timeout('The handshake operation timed out')))
2021-46-03/07/21 22:46:13 connectionpool.py [lines:227] DEBUG: Starting new HTTP connection (1): 103.156.16.62:8080
2021-46-03/07/21 22:46:13 connectionpool.py [lines:227] DEBUG: Starting new HTTP connection (1): 84.214.150.146:8080
2021-46-03/07/21 22:46:13 connectionpool.py [lines:227] DEBUG: Starting new HTTP connection (1): 122.55.250.90:8080
2021-46-03/07/21 22:46:13 connectionpool.py [lines:227] DEBUG: Starting new HTTP connection (1): 103.153.66.34:8080
2021-46-03/07/21 22:46:13 connectionpool.py [lines:227] DEBUG: Starting new HTTP connection (1): 103.152.5.80:8080
2021-46-03/07/21 22:46:13 connectionpool.py [lines:227] DEBUG: Starting new HTTP connection (1): 106.104.148.208:80
2021-46-03/07/21 22:46:15 connectionpool.py [lines:452] DEBUG: http://103.153.66.34:8080 "GET http://httpbin.org/get HTTP/1.1" 200 552
2021-46-03/07/21 22:46:15 connectionpool.py [lines:971] DEBUG: Starting new HTTPS connection (1): httpbin.org:443
2021-46-03/07/21 22:46:17 connectionpool.py [lines:452] DEBUG: http://103.152.5.80:8080 "GET http://httpbin.org/get HTTP/1.1" 200 652
2021-46-03/07/21 22:46:17 connectionpool.py [lines:971] DEBUG: Starting new HTTPS connection (1): httpbin.org:443
2021-46-03/07/21 22:46:18 httpbin_validator.py [lines:80] DEBUG: HTTPConnectionPool(host='103.156.16.62', port=8080): Max retries exceeded with url: http://httpbin.org/get (Caused by ConnectTimeoutError(<urllib3.connection.HTTPConnection object at 0x0000023FD3B3A7F0>, 'Connection to 103.156.16.62 timed out. (connect timeout=5)'))
2021-46-03/07/21 22:46:18 httpbin_validator.py [lines:80] DEBUG: HTTPConnectionPool(host='84.214.150.146', port=8080): Max retries exceeded with url: http://httpbin.org/get (Caused by ConnectTimeoutError(<urllib3.connection.HTTPConnection object at 0x0000023FD3B3AF70>, 'Connection to 84.214.150.146 timed out. (connect timeout=5)'))
2021-46-03/07/21 22:46:18 httpbin_validator.py [lines:80] DEBUG: HTTPConnectionPool(host='122.55.250.90', port=8080): Max retries exceeded with url: http://httpbin.org/get (Caused by ConnectTimeoutError(<urllib3.connection.HTTPConnection object at 0x0000023FD3B9ED90>, 'Connection to 122.55.250.90 timed out. (connect timeout=5)'))
2021-46-03/07/21 22:46:18 httpbin_validator.py [lines:80] DEBUG: HTTPConnectionPool(host='106.104.148.208', port=80): Max retries exceeded with url: http://httpbin.org/get (Caused by ConnectTimeoutError(<urllib3.connection.HTTPConnection object at 0x0000023FD3BB8DC0>, 'Connection to 106.104.148.208 timed out. (connect timeout=5)'))
2021-46-03/07/21 22:46:18 connectionpool.py [lines:971] DEBUG: Starting new HTTPS connection (1): httpbin.org:443
2021-46-03/07/21 22:46:18 connectionpool.py [lines:971] DEBUG: Starting new HTTPS connection (1): httpbin.org:443
2021-46-03/07/21 22:46:18 connectionpool.py [lines:971] DEBUG: Starting new HTTPS connection (1): httpbin.org:443
2021-46-03/07/21 22:46:18 connectionpool.py [lines:971] DEBUG: Starting new HTTPS connection (1): httpbin.org:443
2021-46-03/07/21 22:46:19 httpbin_validator.py [lines:80] DEBUG: HTTPSConnectionPool(host='httpbin.org', port=443): Max retries exceeded with url: /get (Caused by SSLError(SSLError(1, '[SSL: WRONG_VERSION_NUMBER] wrong version number (_ssl.c:1123)')))
2021-46-03/07/21 22:46:20 httpbin_validator.py [lines:80] DEBUG: HTTPSConnectionPool(host='httpbin.org', port=443): Max retries exceeded with url: /get (Caused by ConnectTimeoutError(<urllib3.connection.HTTPSConnection object at 0x0000023FD3B3A9A0>, 'Connection to 103.153.66.34 timed out. (connect timeout=5)'))
2021-46-03/07/21 22:46:23 httpbin_validator.py [lines:80] DEBUG: HTTPSConnectionPool(host='httpbin.org', port=443): Max retries exceeded with url: /get (Caused by ConnectTimeoutError(<urllib3.connection.HTTPSConnection object at 0x0000023FD3BADA30>, 'Connection to 122.55.250.90 timed out. (connect timeout=5)'))
2021-46-03/07/21 22:46:23 httpbin_validator.py [lines:80] DEBUG: HTTPSConnectionPool(host='httpbin.org', port=443): Max retries exceeded with url: /get (Caused by ConnectTimeoutError(<urllib3.connection.HTTPSConnection object at 0x0000023FD3BADF40>, 'Connection to 106.104.148.208 timed out. (connect timeout=5)'))
2021-46-03/07/21 22:46:23 httpbin_validator.py [lines:80] DEBUG: HTTPSConnectionPool(host='httpbin.org', port=443): Max retries exceeded with url: /get (Caused by ConnectTimeoutError(<urllib3.connection.HTTPSConnection object at 0x0000023FD3BADE50>, 'Connection to 103.156.16.62 timed out. (connect timeout=5)'))
2021-46-03/07/21 22:46:25 httpbin_validator.py [lines:80] DEBUG: HTTPSConnectionPool(host='httpbin.org', port=443): Max retries exceeded with url: /get (Caused by ProxyError('Cannot connect to proxy.', timeout('The handshake operation timed out')))
2021-47-03/07/21 22:47:35 connectionpool.py [lines:227] DEBUG: Starting new HTTP connection (1): 103.156.16.62:8080
2021-47-03/07/21 22:47:35 connectionpool.py [lines:227] DEBUG: Starting new HTTP connection (1): 84.214.150.146:8080
2021-47-03/07/21 22:47:35 connectionpool.py [lines:227] DEBUG: Starting new HTTP connection (1): 122.55.250.90:8080
2021-47-03/07/21 22:47:35 connectionpool.py [lines:227] DEBUG: Starting new HTTP connection (1): 103.153.66.34:8080
2021-47-03/07/21 22:47:35 connectionpool.py [lines:227] DEBUG: Starting new HTTP connection (1): 103.152.5.80:8080
2021-47-03/07/21 22:47:35 connectionpool.py [lines:227] DEBUG: Starting new HTTP connection (1): 106.104.148.208:80
2021-47-03/07/21 22:47:36 connectionpool.py [lines:452] DEBUG: http://103.152.5.80:8080 "GET http://httpbin.org/get HTTP/1.1" 200 525
2021-47-03/07/21 22:47:36 connectionpool.py [lines:971] DEBUG: Starting new HTTPS connection (1): httpbin.org:443
2021-47-03/07/21 22:47:37 httpbin_validator.py [lines:80] DEBUG: HTTPSConnectionPool(host='httpbin.org', port=443): Max retries exceeded with url: /get (Caused by SSLError(SSLError(1, '[SSL: WRONG_VERSION_NUMBER] wrong version number (_ssl.c:1123)')))
2021-47-03/07/21 22:47:40 httpbin_validator.py [lines:80] DEBUG: HTTPConnectionPool(host='103.156.16.62', port=8080): Max retries exceeded with url: http://httpbin.org/get (Caused by ConnectTimeoutError(<urllib3.connection.HTTPConnection object at 0x000001FE4FDBBF40>, 'Connection to 103.156.16.62 timed out. (connect timeout=5)'))
2021-47-03/07/21 22:47:40 httpbin_validator.py [lines:80] DEBUG: HTTPConnectionPool(host='84.214.150.146', port=8080): Max retries exceeded with url: http://httpbin.org/get (Caused by ConnectTimeoutError(<urllib3.connection.HTTPConnection object at 0x000001FE4FDBBF70>, 'Connection to 84.214.150.146 timed out. (connect timeout=5)'))
2021-47-03/07/21 22:47:40 connectionpool.py [lines:971] DEBUG: Starting new HTTPS connection (1): httpbin.org:443
2021-47-03/07/21 22:47:40 connectionpool.py [lines:971] DEBUG: Starting new HTTPS connection (1): httpbin.org:443
2021-47-03/07/21 22:47:42 httpbin_validator.py [lines:80] DEBUG: HTTPConnectionPool(host='122.55.250.90', port=8080): Read timed out. (read timeout=5)
2021-47-03/07/21 22:47:42 connectionpool.py [lines:971] DEBUG: Starting new HTTPS connection (1): httpbin.org:443
2021-47-03/07/21 22:47:42 httpbin_validator.py [lines:80] DEBUG: HTTPConnectionPool(host='106.104.148.208', port=80): Read timed out. (read timeout=5)
2021-47-03/07/21 22:47:42 connectionpool.py [lines:971] DEBUG: Starting new HTTPS connection (1): httpbin.org:443
2021-47-03/07/21 22:47:44 httpbin_validator.py [lines:80] DEBUG: HTTPConnectionPool(host='103.153.66.34', port=8080): Read timed out. (read timeout=5)
2021-47-03/07/21 22:47:44 connectionpool.py [lines:971] DEBUG: Starting new HTTPS connection (1): httpbin.org:443
2021-47-03/07/21 22:47:45 httpbin_validator.py [lines:80] DEBUG: HTTPSConnectionPool(host='httpbin.org', port=443): Max retries exceeded with url: /get (Caused by ConnectTimeoutError(<urllib3.connection.HTTPSConnection object at 0x000001FE4FE4CA60>, 'Connection to 103.156.16.62 timed out. (connect timeout=5)'))
2021-47-03/07/21 22:47:46 httpbin_validator.py [lines:80] DEBUG: HTTPSConnectionPool(host='httpbin.org', port=443): Max retries exceeded with url: /get (Caused by ProxyError('Cannot connect to proxy.', timeout('The handshake operation timed out')))
2021-47-03/07/21 22:47:47 httpbin_validator.py [lines:80] DEBUG: HTTPSConnectionPool(host='httpbin.org', port=443): Max retries exceeded with url: /get (Caused by ConnectTimeoutError(<urllib3.connection.HTTPSConnection object at 0x000001FE4FE4C9D0>, 'Connection to 122.55.250.90 timed out. (connect timeout=5)'))
2021-47-03/07/21 22:47:47 httpbin_validator.py [lines:80] DEBUG: HTTPSConnectionPool(host='httpbin.org', port=443): Max retries exceeded with url: /get (Caused by ConnectTimeoutError(<urllib3.connection.HTTPSConnection object at 0x000001FE4FE2DDF0>, 'Connection to 106.104.148.208 timed out. (connect timeout=5)'))
2021-47-03/07/21 22:47:50 httpbin_validator.py [lines:80] DEBUG: HTTPSConnectionPool(host='httpbin.org', port=443): Max retries exceeded with url: /get (Caused by ProxyError('Cannot connect to proxy.', timeout('The handshake operation timed out')))
2021-53-03/07/21 22:53:33 connectionpool.py [lines:227] DEBUG: Starting new HTTP connection (1): 103.156.16.62:8080
2021-53-03/07/21 22:53:33 connectionpool.py [lines:227] DEBUG: Starting new HTTP connection (1): 84.214.150.146:8080
2021-53-03/07/21 22:53:33 connectionpool.py [lines:227] DEBUG: Starting new HTTP connection (1): 122.55.250.90:8080
2021-53-03/07/21 22:53:33 connectionpool.py [lines:227] DEBUG: Starting new HTTP connection (1): 103.153.66.34:8080
2021-53-03/07/21 22:53:33 connectionpool.py [lines:227] DEBUG: Starting new HTTP connection (1): 103.152.5.80:8080
2021-53-03/07/21 22:53:33 connectionpool.py [lines:227] DEBUG: Starting new HTTP connection (1): 106.104.148.208:80
2021-53-03/07/21 22:53:33 connectionpool.py [lines:227] DEBUG: Starting new HTTP connection (1): 103.132.221.178:8080
2021-53-03/07/21 22:53:33 connectionpool.py [lines:227] DEBUG: Starting new HTTP connection (1): 103.154.160.58:8080
2021-53-03/07/21 22:53:34 connectionpool.py [lines:452] DEBUG: http://103.152.5.80:8080 "GET http://httpbin.org/get HTTP/1.1" 200 559
2021-53-03/07/21 22:53:34 connectionpool.py [lines:971] DEBUG: Starting new HTTPS connection (1): httpbin.org:443
2021-53-03/07/21 22:53:35 httpbin_validator.py [lines:80] DEBUG: HTTPSConnectionPool(host='httpbin.org', port=443): Max retries exceeded with url: /get (Caused by SSLError(SSLError(1, '[SSL: WRONG_VERSION_NUMBER] wrong version number (_ssl.c:1123)')))
2021-53-03/07/21 22:53:38 httpbin_validator.py [lines:80] DEBUG: HTTPConnectionPool(host='84.214.150.146', port=8080): Max retries exceeded with url: http://httpbin.org/get (Caused by ConnectTimeoutError(<urllib3.connection.HTTPConnection object at 0x0000015A58E82F70>, 'Connection to 84.214.150.146 timed out. (connect timeout=5)'))
2021-53-03/07/21 22:53:38 httpbin_validator.py [lines:80] DEBUG: HTTPConnectionPool(host='103.153.66.34', port=8080): Max retries exceeded with url: http://httpbin.org/get (Caused by ConnectTimeoutError(<urllib3.connection.HTTPConnection object at 0x0000015A58EF24C0>, 'Connection to 103.153.66.34 timed out. (connect timeout=5)'))
2021-53-03/07/21 22:53:38 httpbin_validator.py [lines:80] DEBUG: HTTPConnectionPool(host='106.104.148.208', port=80): Max retries exceeded with url: http://httpbin.org/get (Caused by ConnectTimeoutError(<urllib3.connection.HTTPConnection object at 0x0000015A58F15760>, 'Connection to 106.104.148.208 timed out. (connect timeout=5)'))
2021-53-03/07/21 22:53:38 httpbin_validator.py [lines:80] DEBUG: HTTPConnectionPool(host='103.132.221.178', port=8080): Max retries exceeded with url: http://httpbin.org/get (Caused by ConnectTimeoutError(<urllib3.connection.HTTPConnection object at 0x0000015A58F1F0D0>, 'Connection to 103.132.221.178 timed out. (connect timeout=5)'))
2021-53-03/07/21 22:53:38 connectionpool.py [lines:971] DEBUG: Starting new HTTPS connection (1): httpbin.org:443
2021-53-03/07/21 22:53:38 connectionpool.py [lines:971] DEBUG: Starting new HTTPS connection (1): httpbin.org:443
2021-53-03/07/21 22:53:38 connectionpool.py [lines:971] DEBUG: Starting new HTTPS connection (1): httpbin.org:443
2021-53-03/07/21 22:53:38 connectionpool.py [lines:971] DEBUG: Starting new HTTPS connection (1): httpbin.org:443
2021-53-03/07/21 22:53:39 httpbin_validator.py [lines:80] DEBUG: HTTPConnectionPool(host='122.55.250.90', port=8080): Read timed out. (read timeout=5)
2021-53-03/07/21 22:53:39 connectionpool.py [lines:971] DEBUG: Starting new HTTPS connection (1): httpbin.org:443
2021-53-03/07/21 22:53:42 httpbin_validator.py [lines:80] DEBUG: HTTPConnectionPool(host='103.154.160.58', port=8080): Read timed out. (read timeout=5)
2021-53-03/07/21 22:53:42 connectionpool.py [lines:971] DEBUG: Starting new HTTPS connection (1): httpbin.org:443
2021-53-03/07/21 22:53:42 httpbin_validator.py [lines:80] DEBUG: HTTPConnectionPool(host='103.156.16.62', port=8080): Read timed out. (read timeout=5)
2021-53-03/07/21 22:53:42 connectionpool.py [lines:971] DEBUG: Starting new HTTPS connection (1): httpbin.org:443
2021-53-03/07/21 22:53:43 httpbin_validator.py [lines:80] DEBUG: HTTPSConnectionPool(host='httpbin.org', port=443): Max retries exceeded with url: /get (Caused by ConnectTimeoutError(<urllib3.connection.HTTPSConnection object at 0x0000015A58EF2190>, 'Connection to 84.214.150.146 timed out. (connect timeout=5)'))
2021-53-03/07/21 22:53:43 httpbin_validator.py [lines:80] DEBUG: HTTPSConnectionPool(host='httpbin.org', port=443): Max retries exceeded with url: /get (Caused by ConnectTimeoutError(<urllib3.connection.HTTPSConnection object at 0x0000015A58F3B670>, 'Connection to 103.153.66.34 timed out. (connect timeout=5)'))
2021-53-03/07/21 22:53:43 httpbin_validator.py [lines:80] DEBUG: HTTPSConnectionPool(host='httpbin.org', port=443): Max retries exceeded with url: /get (Caused by ConnectTimeoutError(<urllib3.connection.HTTPSConnection object at 0x0000015A58F3B730>, 'Connection to 106.104.148.208 timed out. (connect timeout=5)'))
2021-53-03/07/21 22:53:43 httpbin_validator.py [lines:80] DEBUG: HTTPSConnectionPool(host='httpbin.org', port=443): Max retries exceeded with url: /get (Caused by ConnectTimeoutError(<urllib3.connection.HTTPSConnection object at 0x0000015A58F3B7F0>, 'Connection to 103.132.221.178 timed out. (connect timeout=5)'))
2021-53-03/07/21 22:53:44 httpbin_validator.py [lines:80] DEBUG: HTTPSConnectionPool(host='httpbin.org', port=443): Max retries exceeded with url: /get (Caused by ConnectTimeoutError(<urllib3.connection.HTTPSConnection object at 0x0000015A58F1FF10>, 'Connection to 122.55.250.90 timed out. (connect timeout=5)'))
2021-53-03/07/21 22:53:47 httpbin_validator.py [lines:80] DEBUG: HTTPSConnectionPool(host='httpbin.org', port=443): Max retries exceeded with url: /get (Caused by ProxyError('Cannot connect to proxy.', timeout('The handshake operation timed out')))
2021-53-03/07/21 22:53:50 httpbin_validator.py [lines:80] DEBUG: HTTPSConnectionPool(host='httpbin.org', port=443): Max retries exceeded with url: /get (Caused by ProxyError('Cannot connect to proxy.', timeout('The handshake operation timed out')))
