2021-42-03/07/21 22:42:34 connectionpool.py [lines:227] DEBUG: Starting new HTTP connection (1): 103.156.16.62:8080
2021-42-03/07/21 22:42:34 connectionpool.py [lines:227] DEBUG: Starting new HTTP connection (1): 84.214.150.146:8080
2021-42-03/07/21 22:42:34 connectionpool.py [lines:227] DEBUG: Starting new HTTP connection (1): 122.55.250.90:8080
2021-42-03/07/21 22:42:34 connectionpool.py [lines:227] DEBUG: Starting new HTTP connection (1): 103.153.66.34:8080
2021-42-03/07/21 22:42:34 connectionpool.py [lines:227] DEBUG: Starting new HTTP connection (1): 103.152.5.80:8080
2021-42-03/07/21 22:42:34 connectionpool.py [lines:227] DEBUG: Starting new HTTP connection (1): 106.104.148.208:80
2021-42-03/07/21 22:42:38 connectionpool.py [lines:452] DEBUG: http://103.152.5.80:8080 "GET http://httpbin.org/get HTTP/1.1" 200 544
2021-42-03/07/21 22:42:38 connectionpool.py [lines:971] DEBUG: Starting new HTTPS connection (1): httpbin.org:443
2021-42-03/07/21 22:42:39 httpbin_validator.py [lines:80] DEBUG: HTTPSConnectionPool(host='httpbin.org', port=443): Max retries exceeded with url: /get (Caused by SSLError(SSLError(1, '[SSL: WRONG_VERSION_NUMBER] wrong version number (_ssl.c:1123)')))
2021-42-03/07/21 22:42:39 httpbin_validator.py [lines:80] DEBUG: HTTPConnectionPool(host='122.55.250.90', port=8080): Max retries exceeded with url: http://httpbin.org/get (Caused by ConnectTimeoutError(<urllib3.connection.HTTPConnection object at 0x0000027896FE57F0>, 'Connection to 122.55.250.90 timed out. (connect timeout=5)'))
2021-42-03/07/21 22:42:39 httpbin_validator.py [lines:80] DEBUG: HTTPConnectionPool(host='106.104.148.208', port=80): Max retries exceeded with url: http://httpbin.org/get (Caused by ConnectTimeoutError(<urllib3.connection.HTTPConnection object at 0x0000027896FF3BB0>, 'Connection to 106.104.148.208 timed out. (connect timeout=5)'))
2021-42-03/07/21 22:42:39 connectionpool.py [lines:971] DEBUG: Starting new HTTPS connection (1): httpbin.org:443
2021-42-03/07/21 22:42:39 connectionpool.py [lines:971] DEBUG: Starting new HTTPS connection (1): httpbin.org:443
2021-42-03/07/21 22:42:40 httpbin_validator.py [lines:80] DEBUG: HTTPConnectionPool(host='103.153.66.34', port=8080): Read timed out. (read timeout=5)
2021-42-03/07/21 22:42:40 connectionpool.py [lines:971] DEBUG: Starting new HTTPS connection (1): httpbin.org:443
2021-42-03/07/21 22:42:40 httpbin_validator.py [lines:80] DEBUG: HTTPConnectionPool(host='84.214.150.146', port=8080): Read timed out. (read timeout=5)
2021-42-03/07/21 22:42:40 connectionpool.py [lines:971] DEBUG: Starting new HTTPS connection (1): httpbin.org:443
2021-42-03/07/21 22:42:40 httpbin_validator.py [lines:80] DEBUG: HTTPConnectionPool(host='103.156.16.62', port=8080): Read timed out. (read timeout=5)
2021-42-03/07/21 22:42:40 connectionpool.py [lines:971] DEBUG: Starting new HTTPS connection (1): httpbin.org:443
2021-42-03/07/21 22:42:44 httpbin_validator.py [lines:80] DEBUG: HTTPSConnectionPool(host='httpbin.org', port=443): Max retries exceeded with url: /get (Caused by ConnectTimeoutError(<urllib3.connection.HTTPSConnection object at 0x0000027897013820>, 'Connection to 122.55.250.90 timed out. (connect timeout=5)'))
2021-42-03/07/21 22:42:44 httpbin_validator.py [lines:80] DEBUG: HTTPSConnectionPool(host='httpbin.org', port=443): Max retries exceeded with url: /get (Caused by ConnectTimeoutError(<urllib3.connection.HTTPSConnection object at 0x00000278970137F0>, 'Connection to 106.104.148.208 timed out. (connect timeout=5)'))
2021-42-03/07/21 22:42:45 httpbin_validator.py [lines:80] DEBUG: HTTPSConnectionPool(host='httpbin.org', port=443): Max retries exceeded with url: /get (Caused by ConnectTimeoutError(<urllib3.connection.HTTPSConnection object at 0x0000027896FBBC70>, 'Connection to 84.214.150.146 timed out. (connect timeout=5)'))
2021-42-03/07/21 22:42:45 httpbin_validator.py [lines:80] DEBUG: HTTPSConnectionPool(host='httpbin.org', port=443): Max retries exceeded with url: /get (Caused by ProxyError('Cannot connect to proxy.', timeout('The handshake operation timed out')))
2021-42-03/07/21 22:42:48 httpbin_validator.py [lines:80] DEBUG: HTTPSConnectionPool(host='httpbin.org', port=443): Max retries exceeded with url: /get (Caused by ProxyError('Cannot connect to proxy.', timeout('The handshake operation timed out')))
2021-45-03/07/21 22:45:15 connectionpool.py [lines:227] DEBUG: Starting new HTTP connection (1): 103.156.16.62:8080
2021-45-03/07/21 22:45:15 connectionpool.py [lines:227] DEBUG: Starting new HTTP connection (1): 84.214.150.146:8080
2021-45-03/07/21 22:45:15 connectionpool.py [lines:227] DEBUG: Starting new HTTP connection (1): 122.55.250.90:8080
2021-45-03/07/21 22:45:15 connectionpool.py [lines:227] DEBUG: Starting new HTTP connection (1): 103.153.66.34:8080
2021-45-03/07/21 22:45:15 connectionpool.py [lines:227] DEBUG: Starting new HTTP connection (1): 103.152.5.80:8080
2021-45-03/07/21 22:45:15 connectionpool.py [lines:227] DEBUG: Starting new HTTP connection (1): 106.104.148.208:80
2021-45-03/07/21 22:45:20 httpbin_validator.py [lines:80] DEBUG: HTTPConnectionPool(host='103.156.16.62', port=8080): Max retries exceeded with url: http://httpbin.org/get (Caused by ConnectTimeoutError(<urllib3.connection.HTTPConnection object at 0x000001447D3C1DC0>, 'Connection to 103.156.16.62 timed out. (connect timeout=5)'))
2021-45-03/07/21 22:45:20 httpbin_validator.py [lines:80] DEBUG: HTTPConnectionPool(host='84.214.150.146', port=8080): Max retries exceeded with url: http://httpbin.org/get (Caused by ConnectTimeoutError(<urllib3.connection.HTTPConnection object at 0x000001447D3C1E50>, 'Connection to 84.214.150.146 timed out. (connect timeout=5)'))
2021-45-03/07/21 22:45:20 httpbin_validator.py [lines:80] DEBUG: HTTPConnectionPool(host='122.55.250.90', port=8080): Max retries exceeded with url: http://httpbin.org/get (Caused by ConnectTimeoutError(<urllib3.connection.HTTPConnection object at 0x000001447D4239A0>, 'Connection to 122.55.250.90 timed out. (connect timeout=5)'))
2021-45-03/07/21 22:45:20 httpbin_validator.py [lines:80] DEBUG: HTTPConnectionPool(host='103.153.66.34', port=8080): Max retries exceeded with url: http://httpbin.org/get (Caused by ConnectTimeoutError(<urllib3.connection.HTTPConnection object at 0x000001447D441130>, 'Connection to 103.153.66.34 timed out. (connect timeout=5)'))
2021-45-03/07/21 22:45:20 httpbin_validator.py [lines:80] DEBUG: HTTPConnectionPool(host='103.152.5.80', port=8080): Max retries exceeded with url: http://httpbin.org/get (Caused by ConnectTimeoutError(<urllib3.connection.HTTPConnection object at 0x000001447D42EE50>, 'Connection to 103.152.5.80 timed out. (connect timeout=5)'))
2021-45-03/07/21 22:45:20 httpbin_validator.py [lines:80] DEBUG: HTTPConnectionPool(host='106.104.148.208', port=80): Max retries exceeded with url: http://httpbin.org/get (Caused by ConnectTimeoutError(<urllib3.connection.HTTPConnection object at 0x000001447D42ED60>, 'Connection to 106.104.148.208 timed out. (connect timeout=5)'))
2021-45-03/07/21 22:45:20 connectionpool.py [lines:971] DEBUG: Starting new HTTPS connection (1): httpbin.org:443
2021-45-03/07/21 22:45:20 connectionpool.py [lines:971] DEBUG: Starting new HTTPS connection (1): httpbin.org:443
2021-45-03/07/21 22:45:20 connectionpool.py [lines:971] DEBUG: Starting new HTTPS connection (1): httpbin.org:443
2021-45-03/07/21 22:45:20 connectionpool.py [lines:971] DEBUG: Starting new HTTPS connection (1): httpbin.org:443
2021-45-03/07/21 22:45:20 connectionpool.py [lines:971] DEBUG: Starting new HTTPS connection (1): httpbin.org:443
2021-45-03/07/21 22:45:20 connectionpool.py [lines:971] DEBUG: Starting new HTTPS connection (1): httpbin.org:443
2021-45-03/07/21 22:45:21 httpbin_validator.py [lines:80] DEBUG: HTTPSConnectionPool(host='httpbin.org', port=443): Max retries exceeded with url: /get (Caused by SSLError(SSLError(1, '[SSL: WRONG_VERSION_NUMBER] wrong version number (_ssl.c:1123)')))
2021-45-03/07/21 22:45:25 httpbin_validator.py [lines:80] DEBUG: HTTPSConnectionPool(host='httpbin.org', port=443): Max retries exceeded with url: /get (Caused by ConnectTimeoutError(<urllib3.connection.HTTPSConnection object at 0x000001447D474220>, 'Connection to 84.214.150.146 timed out. (connect timeout=5)'))
2021-45-03/07/21 22:45:25 httpbin_validator.py [lines:80] DEBUG: HTTPSConnectionPool(host='httpbin.org', port=443): Max retries exceeded with url: /get (Caused by ConnectTimeoutError(<urllib3.connection.HTTPSConnection object at 0x000001447D474C70>, 'Connection to 106.104.148.208 timed out. (connect timeout=5)'))
2021-45-03/07/21 22:45:25 httpbin_validator.py [lines:80] DEBUG: HTTPSConnectionPool(host='httpbin.org', port=443): Max retries exceeded with url: /get (Caused by ConnectTimeoutError(<urllib3.connection.HTTPSConnection object at 0x000001447D474AF0>, 'Connection to 103.153.66.34 timed out. (connect timeout=5)'))
2021-45-03/07/21 22:45:25 httpbin_validator.py [lines:80] DEBUG: HTTPSConnectionPool(host='httpbin.org', port=443): Max retries exceeded with url: /get (Caused by ProxyError('Cannot connect to proxy.', timeout('The handshake operation timed out')))
2021-45-03/07/21 22:45:28 httpbin_validator.py [lines:80] DEBUG: HTTPSConnectionPool(host='httpbin.org', port=443): Max retries exceeded with url: /get (Caused by ProxyError('Cannot connect to proxy.', timeout('The handshake operation timed out')))
2021-46-03/07/21 22:46:13 connectionpool.py [lines:227] DEBUG: Starting new HTTP connection (1): 103.156.16.62:8080
2021-46-03/07/21 22:46:13 connectionpool.py [lines:227] DEBUG: Starting new HTTP connection (1): 84.214.150.146:8080
2021-46-03/07/21 22:46:13 connectionpool.py [lines:227] DEBUG: Starting new HTTP connection (1): 122.55.250.90:8080
2021-46-03/07/21 22:46:13 connectionpool.py [lines:227] DEBUG: Starting new HTTP connection (1): 103.153.66.34:8080
2021-46-03/07/21 22:46:13 connectionpool.py [lines:227] DEBUG: Starting new HTTP connection (1): 103.152.5.80:8080
2021-46-03/07/21 22:46:13 connectionpool.py [lines:227] DEBUG: Starting new HTTP connection (1): 106.104.148.208:80
2021-46-03/07/21 22:46:15 connectionpool.py [lines:452] DEBUG: http://103.153.66.34:8080 "GET http://httpbin.org/get HTTP/1.1" 200 552
2021-46-03/07/21 22:46:15 connectionpool.py [lines:971] DEBUG: Starting new HTTPS connection (1): httpbin.org:443
2021-46-03/07/21 22:46:17 connectionpool.py [lines:452] DEBUG: http://103.152.5.80:8080 "GET http://httpbin.org/get HTTP/1.1" 200 652
2021-46-03/07/21 22:46:17 connectionpool.py [lines:971] DEBUG: Starting new HTTPS connection (1): httpbin.org:443
2021-46-03/07/21 22:46:18 httpbin_validator.py [lines:80] DEBUG: HTTPConnectionPool(host='103.156.16.62', port=8080): Max retries exceeded with url: http://httpbin.org/get (Caused by ConnectTimeoutError(<urllib3.connection.HTTPConnection object at 0x0000023FD3B3A7F0>, 'Connection to 103.156.16.62 timed out. (connect timeout=5)'))
2021-46-03/07/21 22:46:18 httpbin_validator.py [lines:80] DEBUG: HTTPConnectionPool(host='84.214.150.146', port=8080): Max retries exceeded with url: http://httpbin.org/get (Caused by ConnectTimeoutError(<urllib3.connection.HTTPConnection object at 0x0000023FD3B3AF70>, 'Connection to 84.214.150.146 timed out. (connect timeout=5)'))
2021-46-03/07/21 22:46:18 httpbin_validator.py [lines:80] DEBUG: HTTPConnectionPool(host='122.55.250.90', port=8080): Max retries exceeded with url: http://httpbin.org/get (Caused by ConnectTimeoutError(<urllib3.connection.HTTPConnection object at 0x0000023FD3B9ED90>, 'Connection to 122.55.250.90 timed out. (connect timeout=5)'))
2021-46-03/07/21 22:46:18 httpbin_validator.py [lines:80] DEBUG: HTTPConnectionPool(host='106.104.148.208', port=80): Max retries exceeded with url: http://httpbin.org/get (Caused by ConnectTimeoutError(<urllib3.connection.HTTPConnection object at 0x0000023FD3BB8DC0>, 'Connection to 106.104.148.208 timed out. (connect timeout=5)'))
2021-46-03/07/21 22:46:18 connectionpool.py [lines:971] DEBUG: Starting new HTTPS connection (1): httpbin.org:443
2021-46-03/07/21 22:46:18 connectionpool.py [lines:971] DEBUG: Starting new HTTPS connection (1): httpbin.org:443
2021-46-03/07/21 22:46:18 connectionpool.py [lines:971] DEBUG: Starting new HTTPS connection (1): httpbin.org:443
2021-46-03/07/21 22:46:18 connectionpool.py [lines:971] DEBUG: Starting new HTTPS connection (1): httpbin.org:443
2021-46-03/07/21 22:46:19 httpbin_validator.py [lines:80] DEBUG: HTTPSConnectionPool(host='httpbin.org', port=443): Max retries exceeded with url: /get (Caused by SSLError(SSLError(1, '[SSL: WRONG_VERSION_NUMBER] wrong version number (_ssl.c:1123)')))
2021-46-03/07/21 22:46:20 httpbin_validator.py [lines:80] DEBUG: HTTPSConnectionPool(host='httpbin.org', port=443): Max retries exceeded with url: /get (Caused by ConnectTimeoutError(<urllib3.connection.HTTPSConnection object at 0x0000023FD3B3A9A0>, 'Connection to 103.153.66.34 timed out. (connect timeout=5)'))
2021-46-03/07/21 22:46:23 httpbin_validator.py [lines:80] DEBUG: HTTPSConnectionPool(host='httpbin.org', port=443): Max retries exceeded with url: /get (Caused by ConnectTimeoutError(<urllib3.connection.HTTPSConnection object at 0x0000023FD3BADA30>, 'Connection to 122.55.250.90 timed out. (connect timeout=5)'))
2021-46-03/07/21 22:46:23 httpbin_validator.py [lines:80] DEBUG: HTTPSConnectionPool(host='httpbin.org', port=443): Max retries exceeded with url: /get (Caused by ConnectTimeoutError(<urllib3.connection.HTTPSConnection object at 0x0000023FD3BADF40>, 'Connection to 106.104.148.208 timed out. (connect timeout=5)'))
2021-46-03/07/21 22:46:23 httpbin_validator.py [lines:80] DEBUG: HTTPSConnectionPool(host='httpbin.org', port=443): Max retries exceeded with url: /get (Caused by ConnectTimeoutError(<urllib3.connection.HTTPSConnection object at 0x0000023FD3BADE50>, 'Connection to 103.156.16.62 timed out. (connect timeout=5)'))
2021-46-03/07/21 22:46:25 httpbin_validator.py [lines:80] DEBUG: HTTPSConnectionPool(host='httpbin.org', port=443): Max retries exceeded with url: /get (Caused by ProxyError('Cannot connect to proxy.', timeout('The handshake operation timed out')))
2021-47-03/07/21 22:47:35 connectionpool.py [lines:227] DEBUG: Starting new HTTP connection (1): 103.156.16.62:8080
2021-47-03/07/21 22:47:35 connectionpool.py [lines:227] DEBUG: Starting new HTTP connection (1): 84.214.150.146:8080
2021-47-03/07/21 22:47:35 connectionpool.py [lines:227] DEBUG: Starting new HTTP connection (1): 122.55.250.90:8080
2021-47-03/07/21 22:47:35 connectionpool.py [lines:227] DEBUG: Starting new HTTP connection (1): 103.153.66.34:8080
2021-47-03/07/21 22:47:35 connectionpool.py [lines:227] DEBUG: Starting new HTTP connection (1): 103.152.5.80:8080
2021-47-03/07/21 22:47:35 connectionpool.py [lines:227] DEBUG: Starting new HTTP connection (1): 106.104.148.208:80
2021-47-03/07/21 22:47:36 connectionpool.py [lines:452] DEBUG: http://103.152.5.80:8080 "GET http://httpbin.org/get HTTP/1.1" 200 525
2021-47-03/07/21 22:47:36 connectionpool.py [lines:971] DEBUG: Starting new HTTPS connection (1): httpbin.org:443
2021-47-03/07/21 22:47:37 httpbin_validator.py [lines:80] DEBUG: HTTPSConnectionPool(host='httpbin.org', port=443): Max retries exceeded with url: /get (Caused by SSLError(SSLError(1, '[SSL: WRONG_VERSION_NUMBER] wrong version number (_ssl.c:1123)')))
2021-47-03/07/21 22:47:40 httpbin_validator.py [lines:80] DEBUG: HTTPConnectionPool(host='103.156.16.62', port=8080): Max retries exceeded with url: http://httpbin.org/get (Caused by ConnectTimeoutError(<urllib3.connection.HTTPConnection object at 0x000001FE4FDBBF40>, 'Connection to 103.156.16.62 timed out. (connect timeout=5)'))
2021-47-03/07/21 22:47:40 httpbin_validator.py [lines:80] DEBUG: HTTPConnectionPool(host='84.214.150.146', port=8080): Max retries exceeded with url: http://httpbin.org/get (Caused by ConnectTimeoutError(<urllib3.connection.HTTPConnection object at 0x000001FE4FDBBF70>, 'Connection to 84.214.150.146 timed out. (connect timeout=5)'))
2021-47-03/07/21 22:47:40 connectionpool.py [lines:971] DEBUG: Starting new HTTPS connection (1): httpbin.org:443
2021-47-03/07/21 22:47:40 connectionpool.py [lines:971] DEBUG: Starting new HTTPS connection (1): httpbin.org:443
2021-47-03/07/21 22:47:42 httpbin_validator.py [lines:80] DEBUG: HTTPConnectionPool(host='122.55.250.90', port=8080): Read timed out. (read timeout=5)
2021-47-03/07/21 22:47:42 connectionpool.py [lines:971] DEBUG: Starting new HTTPS connection (1): httpbin.org:443
2021-47-03/07/21 22:47:42 httpbin_validator.py [lines:80] DEBUG: HTTPConnectionPool(host='106.104.148.208', port=80): Read timed out. (read timeout=5)
2021-47-03/07/21 22:47:42 connectionpool.py [lines:971] DEBUG: Starting new HTTPS connection (1): httpbin.org:443
2021-47-03/07/21 22:47:44 httpbin_validator.py [lines:80] DEBUG: HTTPConnectionPool(host='103.153.66.34', port=8080): Read timed out. (read timeout=5)
2021-47-03/07/21 22:47:44 connectionpool.py [lines:971] DEBUG: Starting new HTTPS connection (1): httpbin.org:443
2021-47-03/07/21 22:47:45 httpbin_validator.py [lines:80] DEBUG: HTTPSConnectionPool(host='httpbin.org', port=443): Max retries exceeded with url: /get (Caused by ConnectTimeoutError(<urllib3.connection.HTTPSConnection object at 0x000001FE4FE4CA60>, 'Connection to 103.156.16.62 timed out. (connect timeout=5)'))
2021-47-03/07/21 22:47:46 httpbin_validator.py [lines:80] DEBUG: HTTPSConnectionPool(host='httpbin.org', port=443): Max retries exceeded with url: /get (Caused by ProxyError('Cannot connect to proxy.', timeout('The handshake operation timed out')))
2021-47-03/07/21 22:47:47 httpbin_validator.py [lines:80] DEBUG: HTTPSConnectionPool(host='httpbin.org', port=443): Max retries exceeded with url: /get (Caused by ConnectTimeoutError(<urllib3.connection.HTTPSConnection object at 0x000001FE4FE4C9D0>, 'Connection to 122.55.250.90 timed out. (connect timeout=5)'))
2021-47-03/07/21 22:47:47 httpbin_validator.py [lines:80] DEBUG: HTTPSConnectionPool(host='httpbin.org', port=443): Max retries exceeded with url: /get (Caused by ConnectTimeoutError(<urllib3.connection.HTTPSConnection object at 0x000001FE4FE2DDF0>, 'Connection to 106.104.148.208 timed out. (connect timeout=5)'))
2021-47-03/07/21 22:47:50 httpbin_validator.py [lines:80] DEBUG: HTTPSConnectionPool(host='httpbin.org', port=443): Max retries exceeded with url: /get (Caused by ProxyError('Cannot connect to proxy.', timeout('The handshake operation timed out')))
2021-53-03/07/21 22:53:33 connectionpool.py [lines:227] DEBUG: Starting new HTTP connection (1): 103.156.16.62:8080
2021-53-03/07/21 22:53:33 connectionpool.py [lines:227] DEBUG: Starting new HTTP connection (1): 84.214.150.146:8080
2021-53-03/07/21 22:53:33 connectionpool.py [lines:227] DEBUG: Starting new HTTP connection (1): 122.55.250.90:8080
2021-53-03/07/21 22:53:33 connectionpool.py [lines:227] DEBUG: Starting new HTTP connection (1): 103.153.66.34:8080
2021-53-03/07/21 22:53:33 connectionpool.py [lines:227] DEBUG: Starting new HTTP connection (1): 103.152.5.80:8080
2021-53-03/07/21 22:53:33 connectionpool.py [lines:227] DEBUG: Starting new HTTP connection (1): 106.104.148.208:80
2021-53-03/07/21 22:53:33 connectionpool.py [lines:227] DEBUG: Starting new HTTP connection (1): 103.132.221.178:8080
2021-53-03/07/21 22:53:33 connectionpool.py [lines:227] DEBUG: Starting new HTTP connection (1): 103.154.160.58:8080
2021-53-03/07/21 22:53:34 connectionpool.py [lines:452] DEBUG: http://103.152.5.80:8080 "GET http://httpbin.org/get HTTP/1.1" 200 559
2021-53-03/07/21 22:53:34 connectionpool.py [lines:971] DEBUG: Starting new HTTPS connection (1): httpbin.org:443
2021-53-03/07/21 22:53:35 httpbin_validator.py [lines:80] DEBUG: HTTPSConnectionPool(host='httpbin.org', port=443): Max retries exceeded with url: /get (Caused by SSLError(SSLError(1, '[SSL: WRONG_VERSION_NUMBER] wrong version number (_ssl.c:1123)')))
2021-53-03/07/21 22:53:38 httpbin_validator.py [lines:80] DEBUG: HTTPConnectionPool(host='84.214.150.146', port=8080): Max retries exceeded with url: http://httpbin.org/get (Caused by ConnectTimeoutError(<urllib3.connection.HTTPConnection object at 0x0000015A58E82F70>, 'Connection to 84.214.150.146 timed out. (connect timeout=5)'))
2021-53-03/07/21 22:53:38 httpbin_validator.py [lines:80] DEBUG: HTTPConnectionPool(host='103.153.66.34', port=8080): Max retries exceeded with url: http://httpbin.org/get (Caused by ConnectTimeoutError(<urllib3.connection.HTTPConnection object at 0x0000015A58EF24C0>, 'Connection to 103.153.66.34 timed out. (connect timeout=5)'))
2021-53-03/07/21 22:53:38 httpbin_validator.py [lines:80] DEBUG: HTTPConnectionPool(host='106.104.148.208', port=80): Max retries exceeded with url: http://httpbin.org/get (Caused by ConnectTimeoutError(<urllib3.connection.HTTPConnection object at 0x0000015A58F15760>, 'Connection to 106.104.148.208 timed out. (connect timeout=5)'))
2021-53-03/07/21 22:53:38 httpbin_validator.py [lines:80] DEBUG: HTTPConnectionPool(host='103.132.221.178', port=8080): Max retries exceeded with url: http://httpbin.org/get (Caused by ConnectTimeoutError(<urllib3.connection.HTTPConnection object at 0x0000015A58F1F0D0>, 'Connection to 103.132.221.178 timed out. (connect timeout=5)'))
2021-53-03/07/21 22:53:38 connectionpool.py [lines:971] DEBUG: Starting new HTTPS connection (1): httpbin.org:443
2021-53-03/07/21 22:53:38 connectionpool.py [lines:971] DEBUG: Starting new HTTPS connection (1): httpbin.org:443
2021-53-03/07/21 22:53:38 connectionpool.py [lines:971] DEBUG: Starting new HTTPS connection (1): httpbin.org:443
2021-53-03/07/21 22:53:38 connectionpool.py [lines:971] DEBUG: Starting new HTTPS connection (1): httpbin.org:443
2021-53-03/07/21 22:53:39 httpbin_validator.py [lines:80] DEBUG: HTTPConnectionPool(host='122.55.250.90', port=8080): Read timed out. (read timeout=5)
2021-53-03/07/21 22:53:39 connectionpool.py [lines:971] DEBUG: Starting new HTTPS connection (1): httpbin.org:443
2021-53-03/07/21 22:53:42 httpbin_validator.py [lines:80] DEBUG: HTTPConnectionPool(host='103.154.160.58', port=8080): Read timed out. (read timeout=5)
2021-53-03/07/21 22:53:42 connectionpool.py [lines:971] DEBUG: Starting new HTTPS connection (1): httpbin.org:443
2021-53-03/07/21 22:53:42 httpbin_validator.py [lines:80] DEBUG: HTTPConnectionPool(host='103.156.16.62', port=8080): Read timed out. (read timeout=5)
2021-53-03/07/21 22:53:42 connectionpool.py [lines:971] DEBUG: Starting new HTTPS connection (1): httpbin.org:443
2021-53-03/07/21 22:53:43 httpbin_validator.py [lines:80] DEBUG: HTTPSConnectionPool(host='httpbin.org', port=443): Max retries exceeded with url: /get (Caused by ConnectTimeoutError(<urllib3.connection.HTTPSConnection object at 0x0000015A58EF2190>, 'Connection to 84.214.150.146 timed out. (connect timeout=5)'))
2021-53-03/07/21 22:53:43 httpbin_validator.py [lines:80] DEBUG: HTTPSConnectionPool(host='httpbin.org', port=443): Max retries exceeded with url: /get (Caused by ConnectTimeoutError(<urllib3.connection.HTTPSConnection object at 0x0000015A58F3B670>, 'Connection to 103.153.66.34 timed out. (connect timeout=5)'))
2021-53-03/07/21 22:53:43 httpbin_validator.py [lines:80] DEBUG: HTTPSConnectionPool(host='httpbin.org', port=443): Max retries exceeded with url: /get (Caused by ConnectTimeoutError(<urllib3.connection.HTTPSConnection object at 0x0000015A58F3B730>, 'Connection to 106.104.148.208 timed out. (connect timeout=5)'))
2021-53-03/07/21 22:53:43 httpbin_validator.py [lines:80] DEBUG: HTTPSConnectionPool(host='httpbin.org', port=443): Max retries exceeded with url: /get (Caused by ConnectTimeoutError(<urllib3.connection.HTTPSConnection object at 0x0000015A58F3B7F0>, 'Connection to 103.132.221.178 timed out. (connect timeout=5)'))
2021-53-03/07/21 22:53:44 httpbin_validator.py [lines:80] DEBUG: HTTPSConnectionPool(host='httpbin.org', port=443): Max retries exceeded with url: /get (Caused by ConnectTimeoutError(<urllib3.connection.HTTPSConnection object at 0x0000015A58F1FF10>, 'Connection to 122.55.250.90 timed out. (connect timeout=5)'))
2021-53-03/07/21 22:53:47 httpbin_validator.py [lines:80] DEBUG: HTTPSConnectionPool(host='httpbin.org', port=443): Max retries exceeded with url: /get (Caused by ProxyError('Cannot connect to proxy.', timeout('The handshake operation timed out')))
2021-53-03/07/21 22:53:50 httpbin_validator.py [lines:80] DEBUG: HTTPSConnectionPool(host='httpbin.org', port=443): Max retries exceeded with url: /get (Caused by ProxyError('Cannot connect to proxy.', timeout('The handshake operation timed out')))
2021-09-03/07/21 23:09:08 connectionpool.py [lines:227] DEBUG: Starting new HTTP connection (1): 103.156.16.62:8080
2021-09-03/07/21 23:09:08 connectionpool.py [lines:227] DEBUG: Starting new HTTP connection (1): 84.214.150.146:8080
2021-09-03/07/21 23:09:08 connectionpool.py [lines:227] DEBUG: Starting new HTTP connection (1): 122.55.250.90:8080
2021-09-03/07/21 23:09:08 connectionpool.py [lines:227] DEBUG: Starting new HTTP connection (1): 103.153.66.34:8080
2021-09-03/07/21 23:09:08 connectionpool.py [lines:227] DEBUG: Starting new HTTP connection (1): 103.152.5.80:8080
2021-09-03/07/21 23:09:08 connectionpool.py [lines:227] DEBUG: Starting new HTTP connection (1): 106.104.148.208:80
2021-09-03/07/21 23:09:08 connectionpool.py [lines:227] DEBUG: Starting new HTTP connection (1): 103.132.221.178:8080
2021-09-03/07/21 23:09:08 connectionpool.py [lines:227] DEBUG: Starting new HTTP connection (1): 103.154.160.58:8080
2021-09-03/07/21 23:09:11 connectionpool.py [lines:452] DEBUG: http://103.153.66.34:8080 "GET http://httpbin.org/get HTTP/1.1" 200 507
2021-09-03/07/21 23:09:11 connectionpool.py [lines:971] DEBUG: Starting new HTTPS connection (1): httpbin.org:443
2021-09-03/07/21 23:09:13 httpbin_validator.py [lines:80] DEBUG: HTTPConnectionPool(host='103.156.16.62', port=8080): Max retries exceeded with url: http://httpbin.org/get (Caused by ConnectTimeoutError(<urllib3.connection.HTTPConnection object at 0x0000013C26C2DEE0>, 'Connection to 103.156.16.62 timed out. (connect timeout=5)'))
2021-09-03/07/21 23:09:13 httpbin_validator.py [lines:80] DEBUG: HTTPConnectionPool(host='84.214.150.146', port=8080): Max retries exceeded with url: http://httpbin.org/get (Caused by ConnectTimeoutError(<urllib3.connection.HTTPConnection object at 0x0000013C26C2DF70>, 'Connection to 84.214.150.146 timed out. (connect timeout=5)'))
2021-09-03/07/21 23:09:13 httpbin_validator.py [lines:80] DEBUG: HTTPConnectionPool(host='122.55.250.90', port=8080): Max retries exceeded with url: http://httpbin.org/get (Caused by ConnectTimeoutError(<urllib3.connection.HTTPConnection object at 0x0000013C26C91AC0>, 'Connection to 122.55.250.90 timed out. (connect timeout=5)'))
2021-09-03/07/21 23:09:13 httpbin_validator.py [lines:80] DEBUG: HTTPConnectionPool(host='103.152.5.80', port=8080): Max retries exceeded with url: http://httpbin.org/get (Caused by ConnectTimeoutError(<urllib3.connection.HTTPConnection object at 0x0000013C26C9EE80>, 'Connection to 103.152.5.80 timed out. (connect timeout=5)'))
2021-09-03/07/21 23:09:13 httpbin_validator.py [lines:80] DEBUG: HTTPConnectionPool(host='106.104.148.208', port=80): Max retries exceeded with url: http://httpbin.org/get (Caused by ConnectTimeoutError(<urllib3.connection.HTTPConnection object at 0x0000013C26CC0760>, 'Connection to 106.104.148.208 timed out. (connect timeout=5)'))
2021-09-03/07/21 23:09:13 httpbin_validator.py [lines:80] DEBUG: HTTPConnectionPool(host='103.132.221.178', port=8080): Max retries exceeded with url: http://httpbin.org/get (Caused by ConnectTimeoutError(<urllib3.connection.HTTPConnection object at 0x0000013C26CCB0A0>, 'Connection to 103.132.221.178 timed out. (connect timeout=5)'))
2021-09-03/07/21 23:09:13 httpbin_validator.py [lines:80] DEBUG: HTTPConnectionPool(host='103.154.160.58', port=8080): Max retries exceeded with url: http://httpbin.org/get (Caused by ConnectTimeoutError(<urllib3.connection.HTTPConnection object at 0x0000013C26CC0D60>, 'Connection to 103.154.160.58 timed out. (connect timeout=5)'))
2021-09-03/07/21 23:09:13 connectionpool.py [lines:971] DEBUG: Starting new HTTPS connection (1): httpbin.org:443
2021-09-03/07/21 23:09:13 connectionpool.py [lines:971] DEBUG: Starting new HTTPS connection (1): httpbin.org:443
2021-09-03/07/21 23:09:13 connectionpool.py [lines:971] DEBUG: Starting new HTTPS connection (1): httpbin.org:443
2021-09-03/07/21 23:09:13 connectionpool.py [lines:971] DEBUG: Starting new HTTPS connection (1): httpbin.org:443
2021-09-03/07/21 23:09:13 connectionpool.py [lines:971] DEBUG: Starting new HTTPS connection (1): httpbin.org:443
2021-09-03/07/21 23:09:13 connectionpool.py [lines:971] DEBUG: Starting new HTTPS connection (1): httpbin.org:443
2021-09-03/07/21 23:09:13 connectionpool.py [lines:971] DEBUG: Starting new HTTPS connection (1): httpbin.org:443
2021-09-03/07/21 23:09:16 httpbin_validator.py [lines:80] DEBUG: HTTPSConnectionPool(host='httpbin.org', port=443): Max retries exceeded with url: /get (Caused by ProxyError('Cannot connect to proxy.', timeout('The handshake operation timed out')))
2021-09-03/07/21 23:09:18 httpbin_validator.py [lines:80] DEBUG: HTTPSConnectionPool(host='httpbin.org', port=443): Max retries exceeded with url: /get (Caused by ConnectTimeoutError(<urllib3.connection.HTTPSConnection object at 0x0000013C26D110A0>, 'Connection to 103.156.16.62 timed out. (connect timeout=5)'))
2021-09-03/07/21 23:09:18 httpbin_validator.py [lines:80] DEBUG: HTTPSConnectionPool(host='httpbin.org', port=443): Max retries exceeded with url: /get (Caused by ConnectTimeoutError(<urllib3.connection.HTTPSConnection object at 0x0000013C26D117F0>, 'Connection to 84.214.150.146 timed out. (connect timeout=5)'))
2021-09-03/07/21 23:09:18 httpbin_validator.py [lines:80] DEBUG: HTTPSConnectionPool(host='httpbin.org', port=443): Max retries exceeded with url: /get (Caused by ConnectTimeoutError(<urllib3.connection.HTTPSConnection object at 0x0000013C26D118B0>, 'Connection to 122.55.250.90 timed out. (connect timeout=5)'))
2021-09-03/07/21 23:09:18 httpbin_validator.py [lines:80] DEBUG: HTTPSConnectionPool(host='httpbin.org', port=443): Max retries exceeded with url: /get (Caused by ConnectTimeoutError(<urllib3.connection.HTTPSConnection object at 0x0000013C26D11970>, 'Connection to 103.152.5.80 timed out. (connect timeout=5)'))
2021-09-03/07/21 23:09:18 httpbin_validator.py [lines:80] DEBUG: HTTPSConnectionPool(host='httpbin.org', port=443): Max retries exceeded with url: /get (Caused by ConnectTimeoutError(<urllib3.connection.HTTPSConnection object at 0x0000013C26D11A30>, 'Connection to 106.104.148.208 timed out. (connect timeout=5)'))
2021-09-03/07/21 23:09:18 httpbin_validator.py [lines:80] DEBUG: HTTPSConnectionPool(host='httpbin.org', port=443): Max retries exceeded with url: /get (Caused by ConnectTimeoutError(<urllib3.connection.HTTPSConnection object at 0x0000013C26D11AF0>, 'Connection to 103.132.221.178 timed out. (connect timeout=5)'))
2021-09-03/07/21 23:09:18 httpbin_validator.py [lines:80] DEBUG: HTTPSConnectionPool(host='httpbin.org', port=443): Max retries exceeded with url: /get (Caused by ConnectTimeoutError(<urllib3.connection.HTTPSConnection object at 0x0000013C26D11BB0>, 'Connection to 103.154.160.58 timed out. (connect timeout=5)'))
2021-10-03/07/21 23:10:13 connectionpool.py [lines:227] DEBUG: Starting new HTTP connection (1): 103.156.16.62:8080
2021-10-03/07/21 23:10:13 connectionpool.py [lines:227] DEBUG: Starting new HTTP connection (1): 84.214.150.146:8080
2021-10-03/07/21 23:10:13 connectionpool.py [lines:227] DEBUG: Starting new HTTP connection (1): 122.55.250.90:8080
2021-10-03/07/21 23:10:13 connectionpool.py [lines:227] DEBUG: Starting new HTTP connection (1): 103.153.66.34:8080
2021-10-03/07/21 23:10:13 connectionpool.py [lines:227] DEBUG: Starting new HTTP connection (1): 103.152.5.80:8080
2021-10-03/07/21 23:10:13 connectionpool.py [lines:227] DEBUG: Starting new HTTP connection (1): 106.104.148.208:80
2021-10-03/07/21 23:10:13 connectionpool.py [lines:227] DEBUG: Starting new HTTP connection (1): 103.132.221.178:8080
2021-10-03/07/21 23:10:13 connectionpool.py [lines:227] DEBUG: Starting new HTTP connection (1): 103.154.160.58:8080
2021-10-03/07/21 23:10:15 connectionpool.py [lines:452] DEBUG: http://103.152.5.80:8080 "GET http://httpbin.org/get HTTP/1.1" 200 577
2021-10-03/07/21 23:10:15 connectionpool.py [lines:971] DEBUG: Starting new HTTPS connection (1): httpbin.org:443
2021-10-03/07/21 23:10:16 httpbin_validator.py [lines:80] DEBUG: HTTPSConnectionPool(host='httpbin.org', port=443): Max retries exceeded with url: /get (Caused by SSLError(SSLError(1, '[SSL: WRONG_VERSION_NUMBER] wrong version number (_ssl.c:1123)')))
2021-10-03/07/21 23:10:18 httpbin_validator.py [lines:80] DEBUG: HTTPConnectionPool(host='103.156.16.62', port=8080): Max retries exceeded with url: http://httpbin.org/get (Caused by ConnectTimeoutError(<urllib3.connection.HTTPConnection object at 0x00000203069FBCA0>, 'Connection to 103.156.16.62 timed out. (connect timeout=5)'))
2021-10-03/07/21 23:10:18 httpbin_validator.py [lines:80] DEBUG: HTTPConnectionPool(host='84.214.150.146', port=8080): Max retries exceeded with url: http://httpbin.org/get (Caused by ConnectTimeoutError(<urllib3.connection.HTTPConnection object at 0x00000203069FBEB0>, 'Connection to 84.214.150.146 timed out. (connect timeout=5)'))
2021-10-03/07/21 23:10:18 httpbin_validator.py [lines:80] DEBUG: HTTPConnectionPool(host='122.55.250.90', port=8080): Max retries exceeded with url: http://httpbin.org/get (Caused by ConnectTimeoutError(<urllib3.connection.HTTPConnection object at 0x0000020306A61D90>, 'Connection to 122.55.250.90 timed out. (connect timeout=5)'))
2021-10-03/07/21 23:10:18 httpbin_validator.py [lines:80] DEBUG: HTTPConnectionPool(host='106.104.148.208', port=80): Max retries exceeded with url: http://httpbin.org/get (Caused by ConnectTimeoutError(<urllib3.connection.HTTPConnection object at 0x00000203069FB790>, 'Connection to 106.104.148.208 timed out. (connect timeout=5)'))
2021-10-03/07/21 23:10:18 httpbin_validator.py [lines:80] DEBUG: HTTPConnectionPool(host='103.132.221.178', port=8080): Max retries exceeded with url: http://httpbin.org/get (Caused by ConnectTimeoutError(<urllib3.connection.HTTPConnection object at 0x0000020306A9C370>, 'Connection to 103.132.221.178 timed out. (connect timeout=5)'))
2021-10-03/07/21 23:10:18 httpbin_validator.py [lines:80] DEBUG: HTTPConnectionPool(host='103.154.160.58', port=8080): Max retries exceeded with url: http://httpbin.org/get (Caused by ConnectTimeoutError(<urllib3.connection.HTTPConnection object at 0x0000020306A9C070>, 'Connection to 103.154.160.58 timed out. (connect timeout=5)'))
2021-10-03/07/21 23:10:18 connectionpool.py [lines:971] DEBUG: Starting new HTTPS connection (1): httpbin.org:443
2021-10-03/07/21 23:10:18 connectionpool.py [lines:971] DEBUG: Starting new HTTPS connection (1): httpbin.org:443
2021-10-03/07/21 23:10:18 connectionpool.py [lines:971] DEBUG: Starting new HTTPS connection (1): httpbin.org:443
2021-10-03/07/21 23:10:18 connectionpool.py [lines:971] DEBUG: Starting new HTTPS connection (1): httpbin.org:443
2021-10-03/07/21 23:10:18 connectionpool.py [lines:971] DEBUG: Starting new HTTPS connection (1): httpbin.org:443
2021-10-03/07/21 23:10:18 connectionpool.py [lines:971] DEBUG: Starting new HTTPS connection (1): httpbin.org:443
2021-10-03/07/21 23:10:19 httpbin_validator.py [lines:80] DEBUG: HTTPConnectionPool(host='103.153.66.34', port=8080): Read timed out. (read timeout=5)
2021-10-03/07/21 23:10:19 connectionpool.py [lines:971] DEBUG: Starting new HTTPS connection (1): httpbin.org:443
2021-10-03/07/21 23:10:23 httpbin_validator.py [lines:80] DEBUG: HTTPSConnectionPool(host='httpbin.org', port=443): Max retries exceeded with url: /get (Caused by ConnectTimeoutError(<urllib3.connection.HTTPSConnection object at 0x0000020306ACE970>, 'Connection to 103.156.16.62 timed out. (connect timeout=5)'))
2021-10-03/07/21 23:10:23 httpbin_validator.py [lines:80] DEBUG: HTTPSConnectionPool(host='httpbin.org', port=443): Max retries exceeded with url: /get (Caused by ConnectTimeoutError(<urllib3.connection.HTTPSConnection object at 0x0000020306AD9A30>, 'Connection to 103.132.221.178 timed out. (connect timeout=5)'))
2021-10-03/07/21 23:10:23 httpbin_validator.py [lines:80] DEBUG: HTTPSConnectionPool(host='httpbin.org', port=443): Max retries exceeded with url: /get (Caused by ProxyError('Cannot connect to proxy.', timeout('The handshake operation timed out')))
2021-10-03/07/21 23:10:24 httpbin_validator.py [lines:80] DEBUG: HTTPSConnectionPool(host='httpbin.org', port=443): Max retries exceeded with url: /get (Caused by ProxyError('Cannot connect to proxy.', timeout('The handshake operation timed out')))
2021-10-03/07/21 23:10:24 httpbin_validator.py [lines:80] DEBUG: HTTPSConnectionPool(host='httpbin.org', port=443): Max retries exceeded with url: /get (Caused by ConnectTimeoutError(<urllib3.connection.HTTPSConnection object at 0x0000020306AA5490>, 'Connection to 103.153.66.34 timed out. (connect timeout=5)'))
2021-10-03/07/21 23:10:24 httpbin_validator.py [lines:80] DEBUG: HTTPSConnectionPool(host='httpbin.org', port=443): Max retries exceeded with url: /get (Caused by ProxyError('Cannot connect to proxy.', timeout('The handshake operation timed out')))
2021-10-03/07/21 23:10:26 httpbin_validator.py [lines:80] DEBUG: HTTPSConnectionPool(host='httpbin.org', port=443): Max retries exceeded with url: /get (Caused by ProxyError('Cannot connect to proxy.', timeout('The handshake operation timed out')))
2021-55-03/08/21 00:55:45 connectionpool.py [lines:227] DEBUG: Starting new HTTP connection (1): 103.156.16.62:8080
2021-55-03/08/21 00:55:45 connectionpool.py [lines:227] DEBUG: Starting new HTTP connection (1): 84.214.150.146:8080
2021-55-03/08/21 00:55:45 connectionpool.py [lines:227] DEBUG: Starting new HTTP connection (1): 122.55.250.90:8080
2021-55-03/08/21 00:55:45 connectionpool.py [lines:227] DEBUG: Starting new HTTP connection (1): 103.153.66.34:8080
2021-55-03/08/21 00:55:45 connectionpool.py [lines:227] DEBUG: Starting new HTTP connection (1): 103.152.5.80:8080
2021-55-03/08/21 00:55:45 connectionpool.py [lines:227] DEBUG: Starting new HTTP connection (1): 106.104.148.208:80
2021-55-03/08/21 00:55:45 connectionpool.py [lines:227] DEBUG: Starting new HTTP connection (1): 103.132.221.178:8080
2021-55-03/08/21 00:55:45 connectionpool.py [lines:227] DEBUG: Starting new HTTP connection (1): 103.154.160.58:8080
2021-55-03/08/21 00:55:46 connectionpool.py [lines:452] DEBUG: http://103.152.5.80:8080 "GET http://httpbin.org/get HTTP/1.1" 200 544
2021-55-03/08/21 00:55:46 connectionpool.py [lines:971] DEBUG: Starting new HTTPS connection (1): httpbin.org:443
2021-55-03/08/21 00:55:46 connectionpool.py [lines:452] DEBUG: http://106.104.148.208:80 "GET http://httpbin.org/get HTTP/1.1" 200 460
2021-55-03/08/21 00:55:46 connectionpool.py [lines:971] DEBUG: Starting new HTTPS connection (1): httpbin.org:443
2021-55-03/08/21 00:55:46 httpbin_validator.py [lines:80] DEBUG: HTTPSConnectionPool(host='httpbin.org', port=443): Max retries exceeded with url: /get (Caused by SSLError(SSLError(1, '[SSL: WRONG_VERSION_NUMBER] wrong version number (_ssl.c:1123)')))
2021-55-03/08/21 00:55:50 httpbin_validator.py [lines:80] DEBUG: HTTPConnectionPool(host='84.214.150.146', port=8080): Max retries exceeded with url: http://httpbin.org/get (Caused by ConnectTimeoutError(<urllib3.connection.HTTPConnection object at 0x0000023C47AF5D00>, 'Connection to 84.214.150.146 timed out. (connect timeout=5)'))
2021-55-03/08/21 00:55:50 httpbin_validator.py [lines:80] DEBUG: HTTPConnectionPool(host='122.55.250.90', port=8080): Max retries exceeded with url: http://httpbin.org/get (Caused by ConnectTimeoutError(<urllib3.connection.HTTPConnection object at 0x0000023C47B53850>, 'Connection to 122.55.250.90 timed out. (connect timeout=5)'))
2021-55-03/08/21 00:55:50 httpbin_validator.py [lines:80] DEBUG: HTTPConnectionPool(host='103.153.66.34', port=8080): Max retries exceeded with url: http://httpbin.org/get (Caused by ConnectTimeoutError(<urllib3.connection.HTTPConnection object at 0x0000023C47B60250>, 'Connection to 103.153.66.34 timed out. (connect timeout=5)'))
2021-55-03/08/21 00:55:50 httpbin_validator.py [lines:80] DEBUG: HTTPConnectionPool(host='103.132.221.178', port=8080): Max retries exceeded with url: http://httpbin.org/get (Caused by ConnectTimeoutError(<urllib3.connection.HTTPConnection object at 0x0000023C47B82E20>, 'Connection to 103.132.221.178 timed out. (connect timeout=5)'))
2021-55-03/08/21 00:55:50 httpbin_validator.py [lines:80] DEBUG: HTTPConnectionPool(host='103.154.160.58', port=8080): Max retries exceeded with url: http://httpbin.org/get (Caused by ConnectTimeoutError(<urllib3.connection.HTTPConnection object at 0x0000023C47B82AF0>, 'Connection to 103.154.160.58 timed out. (connect timeout=5)'))
2021-55-03/08/21 00:55:50 connectionpool.py [lines:971] DEBUG: Starting new HTTPS connection (1): httpbin.org:443
2021-55-03/08/21 00:55:50 connectionpool.py [lines:971] DEBUG: Starting new HTTPS connection (1): httpbin.org:443
2021-55-03/08/21 00:55:50 connectionpool.py [lines:971] DEBUG: Starting new HTTPS connection (1): httpbin.org:443
2021-55-03/08/21 00:55:50 connectionpool.py [lines:971] DEBUG: Starting new HTTPS connection (1): httpbin.org:443
2021-55-03/08/21 00:55:50 connectionpool.py [lines:971] DEBUG: Starting new HTTPS connection (1): httpbin.org:443
2021-55-03/08/21 00:55:51 httpbin_validator.py [lines:80] DEBUG: HTTPConnectionPool(host='103.156.16.62', port=8080): Read timed out. (read timeout=5)
2021-55-03/08/21 00:55:51 connectionpool.py [lines:971] DEBUG: Starting new HTTPS connection (1): httpbin.org:443
2021-55-03/08/21 00:55:51 httpbin_validator.py [lines:80] DEBUG: HTTPSConnectionPool(host='httpbin.org', port=443): Max retries exceeded with url: /get (Caused by ConnectTimeoutError(<urllib3.connection.HTTPSConnection object at 0x0000023C47B60B20>, 'Connection to 106.104.148.208 timed out. (connect timeout=5)'))
2021-55-03/08/21 00:55:55 httpbin_validator.py [lines:80] DEBUG: HTTPSConnectionPool(host='httpbin.org', port=443): Max retries exceeded with url: /get (Caused by ConnectTimeoutError(<urllib3.connection.HTTPSConnection object at 0x0000023C47B966D0>, 'Connection to 84.214.150.146 timed out. (connect timeout=5)'))
2021-55-03/08/21 00:55:55 httpbin_validator.py [lines:80] DEBUG: HTTPSConnectionPool(host='httpbin.org', port=443): Max retries exceeded with url: /get (Caused by ConnectTimeoutError(<urllib3.connection.HTTPSConnection object at 0x0000023C47BBAAF0>, 'Connection to 122.55.250.90 timed out. (connect timeout=5)'))
2021-55-03/08/21 00:55:55 httpbin_validator.py [lines:80] DEBUG: HTTPSConnectionPool(host='httpbin.org', port=443): Max retries exceeded with url: /get (Caused by ConnectTimeoutError(<urllib3.connection.HTTPSConnection object at 0x0000023C47BBAD60>, 'Connection to 103.154.160.58 timed out. (connect timeout=5)'))
2021-55-03/08/21 00:55:56 httpbin_validator.py [lines:80] DEBUG: HTTPSConnectionPool(host='httpbin.org', port=443): Max retries exceeded with url: /get (Caused by ConnectTimeoutError(<urllib3.connection.HTTPSConnection object at 0x0000023C47B90730>, 'Connection to 103.156.16.62 timed out. (connect timeout=5)'))
2021-55-03/08/21 00:55:56 httpbin_validator.py [lines:80] DEBUG: HTTPSConnectionPool(host='httpbin.org', port=443): Max retries exceeded with url: /get (Caused by ProxyError('Cannot connect to proxy.', timeout('The handshake operation timed out')))
2021-55-03/08/21 00:55:57 httpbin_validator.py [lines:80] DEBUG: HTTPSConnectionPool(host='httpbin.org', port=443): Max retries exceeded with url: /get (Caused by ProxyError('Cannot connect to proxy.', timeout('The handshake operation timed out')))
2021-57-03/08/21 00:57:29 _internal.py [lines:113] INFO:  * Running on http://0.0.0.0:8888/ (Press CTRL+C to quit)
2021-58-03/08/21 00:58:39 _internal.py [lines:113] INFO:  * Running on http://0.0.0.0:8888/ (Press CTRL+C to quit)
2021-58-03/08/21 00:58:43 _internal.py [lines:113] INFO: 127.0.0.1 - - [08/Mar/2021 00:58:43] "[33mGET / HTTP/1.1[0m" 404 -
2021-58-03/08/21 00:58:43 _internal.py [lines:113] INFO: 127.0.0.1 - - [08/Mar/2021 00:58:43] "[33mGET /favicon.ico HTTP/1.1[0m" 404 -
2021-59-03/08/21 00:59:13 _internal.py [lines:113] INFO: 127.0.0.1 - - [08/Mar/2021 00:59:13] "[37mGET /proxies HTTP/1.1[0m" 200 -
2021-01-03/08/21 01:01:08 app.py [lines:1891] ERROR: Exception on /random [GET]
Traceback (most recent call last):
  File "C:\Users\93057\AppData\Local\Programs\Python\Python39\lib\site-packages\flask\app.py", line 2447, in wsgi_app
    response = self.full_dispatch_request()
  File "C:\Users\93057\AppData\Local\Programs\Python\Python39\lib\site-packages\flask\app.py", line 1952, in full_dispatch_request
    rv = self.handle_user_exception(e)
  File "C:\Users\93057\AppData\Local\Programs\Python\Python39\lib\site-packages\flask\app.py", line 1821, in handle_user_exception
    reraise(exc_type, exc_value, tb)
  File "C:\Users\93057\AppData\Local\Programs\Python\Python39\lib\site-packages\flask\_compat.py", line 39, in reraise
    raise value
  File "C:\Users\93057\AppData\Local\Programs\Python\Python39\lib\site-packages\flask\app.py", line 1950, in full_dispatch_request
    rv = self.dispatch_request()
  File "C:\Users\93057\AppData\Local\Programs\Python\Python39\lib\site-packages\flask\app.py", line 1936, in dispatch_request
    return self.view_functions[rule.endpoint](**req.view_args)
  File "C:\Users\93057\PycharmProjects\IP_Proxy_Pool\core\proxy_api.py", line 24, in random
    proxy = self.mongo_pool.random_proxy(protocol, domain, count=PROXIES_MAX_COUNT)
  File "C:\Users\93057\PycharmProjects\IP_Proxy_Pool\core\db\mongo_pool.py", line 90, in random_proxy
    return random.choice(proxy_list)
  File "C:\Users\93057\AppData\Local\Programs\Python\Python39\lib\random.py", line 346, in choice
    return seq[self._randbelow(len(seq))]
IndexError: list index out of range
2021-01-03/08/21 01:01:08 _internal.py [lines:113] INFO: 127.0.0.1 - - [08/Mar/2021 01:01:08] "[35m[1mGET /random HTTP/1.1[0m" 500 -
2021-02-03/08/21 01:02:25 _internal.py [lines:113] INFO: 127.0.0.1 - - [08/Mar/2021 01:02:25] "[37mGET /random?protocol=http HTTP/1.1[0m" 200 -
2021-02-03/08/21 01:02:39 _internal.py [lines:113] INFO: 127.0.0.1 - - [08/Mar/2021 01:02:39] "[37mGET /proxies?protocol=http HTTP/1.1[0m" 200 -
2021-02-03/08/21 01:02:44 _internal.py [lines:113] INFO: 127.0.0.1 - - [08/Mar/2021 01:02:44] "[37mGET /proxies?protocol=https HTTP/1.1[0m" 200 -
2021-02-03/08/21 01:02:47 _internal.py [lines:113] INFO: 127.0.0.1 - - [08/Mar/2021 01:02:47] "[37mGET /proxies?protocol=http HTTP/1.1[0m" 200 -
2021-02-03/08/21 01:02:56 _internal.py [lines:113] INFO: 127.0.0.1 - - [08/Mar/2021 01:02:56] "[37mGET /proxies?protocol=https HTTP/1.1[0m" 200 -
2021-02-03/08/21 01:02:59 _internal.py [lines:113] INFO: 127.0.0.1 - - [08/Mar/2021 01:02:59] "[37mGET /proxies?protocol=http HTTP/1.1[0m" 200 -
2021-10-03/08/21 01:10:54 connectionpool.py [lines:227] DEBUG: Starting new HTTP connection (1): 103.156.16.62:8080
2021-10-03/08/21 01:10:54 connectionpool.py [lines:227] DEBUG: Starting new HTTP connection (1): 84.214.150.146:8080
2021-10-03/08/21 01:10:54 connectionpool.py [lines:227] DEBUG: Starting new HTTP connection (1): 122.55.250.90:8080
2021-10-03/08/21 01:10:54 connectionpool.py [lines:227] DEBUG: Starting new HTTP connection (1): 103.153.66.34:8080
2021-10-03/08/21 01:10:54 connectionpool.py [lines:227] DEBUG: Starting new HTTP connection (1): 103.152.5.80:8080
2021-10-03/08/21 01:10:54 connectionpool.py [lines:227] DEBUG: Starting new HTTP connection (1): 106.104.148.208:80
2021-10-03/08/21 01:10:54 connectionpool.py [lines:227] DEBUG: Starting new HTTP connection (1): 103.132.221.178:8080
2021-10-03/08/21 01:10:54 connectionpool.py [lines:227] DEBUG: Starting new HTTP connection (1): 103.154.160.58:8080
2021-10-03/08/21 01:10:55 connectionpool.py [lines:452] DEBUG: http://103.152.5.80:8080 "GET http://httpbin.org/get HTTP/1.1" 200 524
2021-10-03/08/21 01:10:55 connectionpool.py [lines:971] DEBUG: Starting new HTTPS connection (1): httpbin.org:443
2021-10-03/08/21 01:10:57 connectionpool.py [lines:452] DEBUG: http://103.153.66.34:8080 "GET http://httpbin.org/get HTTP/1.1" 200 559
2021-10-03/08/21 01:10:57 connectionpool.py [lines:971] DEBUG: Starting new HTTPS connection (1): httpbin.org:443
2021-10-03/08/21 01:10:58 connectionpool.py [lines:452] DEBUG: http://106.104.148.208:80 "GET http://httpbin.org/get HTTP/1.1" 200 522
2021-10-03/08/21 01:10:59 connectionpool.py [lines:971] DEBUG: Starting new HTTPS connection (1): httpbin.org:443
2021-10-03/08/21 01:10:59 httpbin_validator.py [lines:80] DEBUG: HTTPConnectionPool(host='84.214.150.146', port=8080): Max retries exceeded with url: http://httpbin.org/get (Caused by ConnectTimeoutError(<urllib3.connection.HTTPConnection object at 0x0000024C45A19CA0>, 'Connection to 84.214.150.146 timed out. (connect timeout=5)'))
2021-10-03/08/21 01:10:59 httpbin_validator.py [lines:80] DEBUG: HTTPConnectionPool(host='122.55.250.90', port=8080): Max retries exceeded with url: http://httpbin.org/get (Caused by ConnectTimeoutError(<urllib3.connection.HTTPConnection object at 0x0000024C45A737F0>, 'Connection to 122.55.250.90 timed out. (connect timeout=5)'))
2021-10-03/08/21 01:10:59 httpbin_validator.py [lines:80] DEBUG: HTTPConnectionPool(host='103.132.221.178', port=8080): Max retries exceeded with url: http://httpbin.org/get (Caused by ConnectTimeoutError(<urllib3.connection.HTTPConnection object at 0x0000024C45AA2E20>, 'Connection to 103.132.221.178 timed out. (connect timeout=5)'))
2021-10-03/08/21 01:10:59 httpbin_validator.py [lines:80] DEBUG: HTTPConnectionPool(host='103.154.160.58', port=8080): Max retries exceeded with url: http://httpbin.org/get (Caused by ConnectTimeoutError(<urllib3.connection.HTTPConnection object at 0x0000024C45AA2B20>, 'Connection to 103.154.160.58 timed out. (connect timeout=5)'))
2021-10-03/08/21 01:10:59 connectionpool.py [lines:971] DEBUG: Starting new HTTPS connection (1): httpbin.org:443
2021-10-03/08/21 01:10:59 connectionpool.py [lines:971] DEBUG: Starting new HTTPS connection (1): httpbin.org:443
2021-10-03/08/21 01:10:59 connectionpool.py [lines:971] DEBUG: Starting new HTTPS connection (1): httpbin.org:443
2021-10-03/08/21 01:10:59 connectionpool.py [lines:971] DEBUG: Starting new HTTPS connection (1): httpbin.org:443
2021-11-03/08/21 01:11:00 httpbin_validator.py [lines:80] DEBUG: HTTPSConnectionPool(host='httpbin.org', port=443): Max retries exceeded with url: /get (Caused by ConnectTimeoutError(<urllib3.connection.HTTPSConnection object at 0x0000024C45A06AC0>, 'Connection to 103.152.5.80 timed out. (connect timeout=5)'))
2021-11-03/08/21 01:11:02 httpbin_validator.py [lines:80] DEBUG: HTTPSConnectionPool(host='httpbin.org', port=443): Max retries exceeded with url: /get (Caused by ConnectTimeoutError(<urllib3.connection.HTTPSConnection object at 0x0000024C45A82130>, 'Connection to 103.153.66.34 timed out. (connect timeout=5)'))
2021-11-03/08/21 01:11:03 httpbin_validator.py [lines:80] DEBUG: HTTPConnectionPool(host='103.156.16.62', port=8080): Max retries exceeded with url: http://httpbin.org/get (Caused by ProxyError('Cannot connect to proxy.', RemoteDisconnected('Remote end closed connection without response')))
2021-11-03/08/21 01:11:03 connectionpool.py [lines:971] DEBUG: Starting new HTTPS connection (1): httpbin.org:443
2021-11-03/08/21 01:11:04 httpbin_validator.py [lines:80] DEBUG: HTTPSConnectionPool(host='httpbin.org', port=443): Max retries exceeded with url: /get (Caused by ConnectTimeoutError(<urllib3.connection.HTTPSConnection object at 0x0000024C45A82E50>, 'Connection to 106.104.148.208 timed out. (connect timeout=5)'))
2021-11-03/08/21 01:11:04 httpbin_validator.py [lines:80] DEBUG: HTTPSConnectionPool(host='httpbin.org', port=443): Max retries exceeded with url: /get (Caused by ConnectTimeoutError(<urllib3.connection.HTTPSConnection object at 0x0000024C45AB0BB0>, 'Connection to 84.214.150.146 timed out. (connect timeout=5)'))
2021-11-03/08/21 01:11:04 httpbin_validator.py [lines:80] DEBUG: HTTPSConnectionPool(host='httpbin.org', port=443): Max retries exceeded with url: /get (Caused by ConnectTimeoutError(<urllib3.connection.HTTPSConnection object at 0x0000024C45AD1E50>, 'Connection to 122.55.250.90 timed out. (connect timeout=5)'))
2021-11-03/08/21 01:11:04 httpbin_validator.py [lines:80] DEBUG: HTTPSConnectionPool(host='httpbin.org', port=443): Max retries exceeded with url: /get (Caused by ConnectTimeoutError(<urllib3.connection.HTTPSConnection object at 0x0000024C45AD1040>, 'Connection to 103.132.221.178 timed out. (connect timeout=5)'))
2021-11-03/08/21 01:11:04 httpbin_validator.py [lines:80] DEBUG: HTTPSConnectionPool(host='httpbin.org', port=443): Max retries exceeded with url: /get (Caused by ConnectTimeoutError(<urllib3.connection.HTTPSConnection object at 0x0000024C45AD8040>, 'Connection to 103.154.160.58 timed out. (connect timeout=5)'))
2021-11-03/08/21 01:11:08 httpbin_validator.py [lines:80] DEBUG: HTTPSConnectionPool(host='httpbin.org', port=443): Max retries exceeded with url: /get (Caused by ProxyError('Cannot connect to proxy.', timeout('The handshake operation timed out')))
2021-11-03/08/21 01:11:28 connectionpool.py [lines:227] DEBUG: Starting new HTTP connection (1): 103.156.16.62:8080
2021-11-03/08/21 01:11:28 connectionpool.py [lines:227] DEBUG: Starting new HTTP connection (1): 84.214.150.146:8080
2021-11-03/08/21 01:11:28 connectionpool.py [lines:227] DEBUG: Starting new HTTP connection (1): 122.55.250.90:8080
2021-11-03/08/21 01:11:28 connectionpool.py [lines:227] DEBUG: Starting new HTTP connection (1): 103.153.66.34:8080
2021-11-03/08/21 01:11:28 connectionpool.py [lines:227] DEBUG: Starting new HTTP connection (1): 103.152.5.80:8080
2021-11-03/08/21 01:11:28 connectionpool.py [lines:227] DEBUG: Starting new HTTP connection (1): 106.104.148.208:80
2021-11-03/08/21 01:11:28 connectionpool.py [lines:227] DEBUG: Starting new HTTP connection (1): 103.132.221.178:8080
2021-11-03/08/21 01:11:28 connectionpool.py [lines:227] DEBUG: Starting new HTTP connection (1): 103.154.160.58:8080
2021-11-03/08/21 01:11:33 httpbin_validator.py [lines:80] DEBUG: HTTPConnectionPool(host='103.152.5.80', port=8080): Max retries exceeded with url: http://httpbin.org/get (Caused by ConnectTimeoutError(<urllib3.connection.HTTPConnection object at 0x0000025BF81391C0>, 'Connection to 103.152.5.80 timed out. (connect timeout=5)'))
2021-11-03/08/21 01:11:33 httpbin_validator.py [lines:80] DEBUG: HTTPConnectionPool(host='106.104.148.208', port=80): Max retries exceeded with url: http://httpbin.org/get (Caused by ConnectTimeoutError(<urllib3.connection.HTTPConnection object at 0x0000025BF814EA60>, 'Connection to 106.104.148.208 timed out. (connect timeout=5)'))
2021-11-03/08/21 01:11:33 connectionpool.py [lines:971] DEBUG: Starting new HTTPS connection (1): httpbin.org:443
2021-11-03/08/21 01:11:33 connectionpool.py [lines:971] DEBUG: Starting new HTTPS connection (1): httpbin.org:443
2021-11-03/08/21 01:11:33 httpbin_validator.py [lines:80] DEBUG: HTTPConnectionPool(host='122.55.250.90', port=8080): Read timed out. (read timeout=5)
2021-11-03/08/21 01:11:33 connectionpool.py [lines:971] DEBUG: Starting new HTTPS connection (1): httpbin.org:443
2021-11-03/08/21 01:11:33 httpbin_validator.py [lines:80] DEBUG: HTTPConnectionPool(host='103.156.16.62', port=8080): Read timed out. (read timeout=5)
2021-11-03/08/21 01:11:33 connectionpool.py [lines:971] DEBUG: Starting new HTTPS connection (1): httpbin.org:443
2021-11-03/08/21 01:11:34 httpbin_validator.py [lines:80] DEBUG: HTTPConnectionPool(host='103.153.66.34', port=8080): Read timed out. (read timeout=5)
2021-11-03/08/21 01:11:34 connectionpool.py [lines:971] DEBUG: Starting new HTTPS connection (1): httpbin.org:443
2021-11-03/08/21 01:11:35 httpbin_validator.py [lines:80] DEBUG: HTTPConnectionPool(host='103.132.221.178', port=8080): Max retries exceeded with url: http://httpbin.org/get (Caused by ProxyError('Cannot connect to proxy.', RemoteDisconnected('Remote end closed connection without response')))
2021-11-03/08/21 01:11:35 connectionpool.py [lines:971] DEBUG: Starting new HTTPS connection (1): httpbin.org:443
2021-11-03/08/21 01:11:35 httpbin_validator.py [lines:80] DEBUG: HTTPConnectionPool(host='84.214.150.146', port=8080): Max retries exceeded with url: http://httpbin.org/get (Caused by ProxyError('Cannot connect to proxy.', RemoteDisconnected('Remote end closed connection without response')))
2021-11-03/08/21 01:11:35 connectionpool.py [lines:971] DEBUG: Starting new HTTPS connection (1): httpbin.org:443
2021-11-03/08/21 01:11:36 httpbin_validator.py [lines:80] DEBUG: HTTPConnectionPool(host='103.154.160.58', port=8080): Read timed out. (read timeout=5)
2021-11-03/08/21 01:11:36 connectionpool.py [lines:971] DEBUG: Starting new HTTPS connection (1): httpbin.org:443
2021-11-03/08/21 01:11:37 httpbin_validator.py [lines:80] DEBUG: HTTPSConnectionPool(host='httpbin.org', port=443): Max retries exceeded with url: /get (Caused by ProxyError('Cannot connect to proxy.', ConnectionResetError(10054, '远程主机强迫关闭了一个现有的连接。', None, 10054, None)))
2021-11-03/08/21 01:11:37 mongo_pool.py [lines:40] INFO: 删除代理:{'ip': '103.156.16.62', 'port': '8080', 'protocol': -1, 'nick_type': -1, 'speed': -1, 'area': '亚太地区', 'score': 0, 'disable_domains': []}
2021-11-03/08/21 01:11:38 httpbin_validator.py [lines:80] DEBUG: HTTPSConnectionPool(host='httpbin.org', port=443): Max retries exceeded with url: /get (Caused by ConnectTimeoutError(<urllib3.connection.HTTPSConnection object at 0x0000025BF816C8E0>, 'Connection to 103.152.5.80 timed out. (connect timeout=5)'))
2021-11-03/08/21 01:11:38 httpbin_validator.py [lines:80] DEBUG: HTTPSConnectionPool(host='httpbin.org', port=443): Max retries exceeded with url: /get (Caused by ProxyError('Cannot connect to proxy.', timeout('The handshake operation timed out')))
2021-11-03/08/21 01:11:38 httpbin_validator.py [lines:80] DEBUG: HTTPSConnectionPool(host='httpbin.org', port=443): Max retries exceeded with url: /get (Caused by ProxyError('Cannot connect to proxy.', timeout('The handshake operation timed out')))
2021-11-03/08/21 01:11:38 mongo_pool.py [lines:40] INFO: 删除代理:{'ip': '122.55.250.90', 'port': '8080', 'protocol': -1, 'nick_type': -1, 'speed': -1, 'area': '菲律宾', 'score': 0, 'disable_domains': []}
2021-11-03/08/21 01:11:39 httpbin_validator.py [lines:80] DEBUG: HTTPSConnectionPool(host='httpbin.org', port=443): Max retries exceeded with url: /get (Caused by ConnectTimeoutError(<urllib3.connection.HTTPSConnection object at 0x0000025BF8164460>, 'Connection to 103.153.66.34 timed out. (connect timeout=5)'))
2021-11-03/08/21 01:11:40 httpbin_validator.py [lines:80] DEBUG: HTTPSConnectionPool(host='httpbin.org', port=443): Max retries exceeded with url: /get (Caused by ConnectTimeoutError(<urllib3.connection.HTTPSConnection object at 0x0000025BF8139940>, 'Connection to 103.132.221.178 timed out. (connect timeout=5)'))
2021-11-03/08/21 01:11:41 httpbin_validator.py [lines:80] DEBUG: HTTPSConnectionPool(host='httpbin.org', port=443): Max retries exceeded with url: /get (Caused by ConnectTimeoutError(<urllib3.connection.HTTPSConnection object at 0x0000025BF8164E20>, 'Connection to 103.154.160.58 timed out. (connect timeout=5)'))
2021-11-03/08/21 01:11:44 httpbin_validator.py [lines:80] DEBUG: HTTPSConnectionPool(host='httpbin.org', port=443): Max retries exceeded with url: /get (Caused by ProxyError('Cannot connect to proxy.', timeout('The handshake operation timed out')))
2021-11-03/08/21 01:11:44 mongo_pool.py [lines:40] INFO: 删除代理:{'ip': '84.214.150.146', 'port': '8080', 'protocol': -1, 'nick_type': -1, 'speed': -1, 'area': '挪威', 'score': 0, 'disable_domains': []}
